Workbook

Sheet Cover
A1: Investment-Grade Company Analysis Engine
A2: All figures in USD millions unless stated. · v1.0
A4: Company | B4: ='Inputs'!$B$6
A5: Ticker / type | B5: ='Inputs'!$B$7&" · "&'Inputs'!$B$8
A7: Headline
A8: DCF value per share | B8: ='DCF'!$B$36 | C8: Current share price | D8: ='DCF'!$B$39 | E8: Valuation read | F8: ='DCF'!$B$41
A9: Upside / (downside) | B9: ='DCF'!$B$40 | C9: WACC | D9: ='WACC'!$B$24 | E9: Data health | F9: ='Checks'!$B$6
A11: Contents
A12: Inputs | B12: Data-entry layer — paste income statement, balance sheet, cash flow & market data
A13: Historical | B13: Ratios, margins, growth, returns & cash flow, each with a plain-English read
A14: Assumptions | B14: Driver-based DCF assumption engine + Base/Bull/Bear/Downside scenario selector
A15: WACC | B15: Discount rate built up step by step (CAPM cost of equity, after-tax cost of debt)
A16: Forecast | B16: Driver-based operating forecast & unlevered free cash flow (active scenario)
A17: DCF | B17: Discounted cash flow: discounting, terminal value, EV→equity bridge, value per share
A18: Sensitivity | B18: Two-way heat-maps: WACC×growth, WACC×exit multiple, growth×margin
A19: Scenario | B19: Four full DCF runs side by side — base, bull, bear and downside stress
A20: Checks | B20: Automated integrity, sanity and data-gap diagnostics (PASS / REVIEW / FAIL)
A21: Dashboard | B21: One-page investment tearsheet — the summary view
A22: Conclusion | B22: Written investment thesis: drivers, risks, swing assumptions and stance
A24: LEGEND
A25: 1,234 | B25: Input — type your data here (yellow fill, blue font)
A26: a / b | B26: Calculated on this sheet (black formula)
A27: → link | B27: Linked from another sheet (green font)
A28: 12.3x | B28: Key output (shaded)
A29: Strong | B29: Caution | C29: Weak / flag | D29: n/a = data missing · n/m = not meaningful
A31: How to Use
A32: 1. Go to the Inputs sheet and replace the yellow cells with the company's figures (at least revenue and equity; the more you fill, the deeper the analysis).
A33: 2. Enter market data (price, shares, beta, rates) for the WACC and per-share value — or leave blank to use clearly-labelled fallback defaults.
A34: 3. Review the Assumptions sheet; the base case is derived from history. Adjust if you have a different view, and pick a scenario (1–4) with the selector.
A35: 4. Read the Dashboard and Conclusion. Use Sensitivity and Scenario to stress the call. Check the Checks sheet for any data flags.
A37: Generated by Investment-Grade Company Analysis Engine v1.0 on 22 Jun 2026. Illustrative analytical tool — not investment advice.

Sheet Inputs
A1: INPUTS
A2: Standardised financial-statement input layer
A3: Investment-Grade Company Analysis Engine · v1.0
A5: Company & Reporting Profile
A6: Company name | B6: <Company name>
A7: Ticker / identifier | B7: <TICKER>
A8: Business type | B8: Industrial / Manufacturing
A9: Reporting currency | B9: USD
A10: Units | B10: millions
A11: Fiscal year end | B11: 31 December
A12: Business description | B12: <One-paragraph business description>
A15: Industry note | B15: <How revenue & margins are driven in this industry>
A18: LEGEND
A19: 1,234 | B19: Input — type your data here (yellow fill, blue font)
A20: a / b | B20: Calculated on this sheet (black formula)
A21: → link | B21: Linked from another sheet (green font)
A22: 12.3x | B22: Key output (shaded)
A23: Strong | B23: Caution | C23: Weak / flag | D23: n/a = data missing · n/m = not meaningful
A25: Conventions
A26: • COGS and SG&A are entered AS REPORTED (they already include their share of depreciation). Total D&A is entered ONCE in the Cash Flow block; EBITDA is built as EBIT + D&A so depreciation is never double-counted.
A27: • Capex, acquisitions, dividends paid and buybacks are entered as POSITIVE amounts (cash spent); the model applies the sign automatically.
A28: • Signed cash-flow lines (change in working capital, net debt issued/repaid, other lines) are entered as net cash impact: positive = inflow.
A29: • Leave any cell blank if the figure is unavailable — the model marks it missing and continues with the best partial output (it will not invent data).
A31: Income Statement
B32: FY—4 | C32: FY—3 | D32: FY—2 | E32: FY—1 | F32: FY—0 | G32: Source / note
A33: Revenue / Net sales
A34: Cost of goods sold (incl. D&A)
A35: Gross profit | B35: =$B$33-$B$34 | C35: =$C$33-$C$34 | D35: =$D$33-$D$34 | E35: =$E$33-$E$34 | F35: =$F$33-$F$34
A36: Selling, general & admin (SG&A)
A37: Research & development
A38: Other operating expense / (income)
A39: EBIT (operating income) | B39: =$B$35-$B$36-$B$37-$B$38 | C39: =$C$35-$C$36-$C$37-$C$38 | D39: =$D$35-$D$36-$D$37-$D$38 | E39: =$E$35-$E$36-$E$37-$E$38 | F39: =$F$35-$F$36-$F$37-$F$38
A40: (+) Depreciation & amortisation | B40: =$B$78 | C40: =$C$78 | D40: =$D$78 | E40: =$E$78 | F40: =$F$78 | G40: Linked from cash-flow block; added back to reach EBITDA.
A41: EBITDA | B41: =$B$39+$B$40 | C41: =$C$39+$C$40 | D41: =$D$39+$D$40 | E41: =$E$39+$E$40 | F41: =$F$39+$F$40
A42: Interest expense
A43: Interest & investment income
A44: Other non-operating income / (expense)
A45: Pre-tax income | B45: =$B$39-$B$42+$B$43+$B$44 | C45: =$C$39-$C$42+$C$43+$C$44 | D45: =$D$39-$D$42+$D$43+$D$44 | E45: =$E$39-$E$42+$E$43+$E$44 | F45: =$F$39-$F$42+$F$43+$F$44
A46: Income tax expense
A47: Minority interest / (income)
...

Sheet Historical
A1: HISTORICAL ANALYSIS
A2: Ratios, margins, growth, returns & cash flow — with plain-English read
A3: Investment-Grade Company Analysis Engine · v1.0
A4: All figures in USD millions unless stated. Balance-sheet ratios use period-end balances.
A6: Growth (year-on-year)
B7: FY—4 | C7: FY—3 | D7: FY—2 | E7: FY—1 | F7: FY—0 | G7: Latest read
A8: Revenue growth | C8: =IF(AND(ISNUMBER('Inputs'!$C$33),ISNUMBER('Inputs'!$B$33),'Inputs'!$B$33>0),'Inputs'!$C$33/'Inputs'!$B$33-1,"n/m") | D8: =IF(AND(ISNUMBER('Inputs'!$D$33),ISNUMBER('Inputs'!$C$33),'Inputs'!$C$33>0),'Inputs'!$D$33/'Inputs'!$C$33-1,"n/m") | E8: =IF(AND(ISNUMBER('Inputs'!$E$33),ISNUMBER('Inputs'!$D$33),'Inputs'!$D$33>0),'Inputs'!$E$33/'Inputs'!$D$33-1,"n/m") | F8: =IF(AND(ISNUMBER('Inputs'!$F$33),ISNUMBER('Inputs'!$E$33),'Inputs'!$E$33>0),'Inputs'!$F$33/'Inputs'!$E$33-1,"n/m") | G8: =IF(NOT(AND(ISNUMBER($F$8),ISNUMBER($E$8))),"n/a",IF($F$8>$E$8+0.02,"Accelerating",IF($F$8<$E$8-0.02,"Decelerating","Stable")))
A9: Gross profit growth | C9: =IF(AND(ISNUMBER('Inputs'!$C$35),ISNUMBER('Inputs'!$B$35),'Inputs'!$B$35>0),'Inputs'!$C$35/'Inputs'!$B$35-1,"n/m") | D9: =IF(AND(ISNUMBER('Inputs'!$D$35),ISNUMBER('Inputs'!$C$35),'Inputs'!$C$35>0),'Inputs'!$D$35/'Inputs'!$C$35-1,"n/m") | E9: =IF(AND(ISNUMBER('Inputs'!$E$35),ISNUMBER('Inputs'!$D$35),'Inputs'!$D$35>0),'Inputs'!$E$35/'Inputs'!$D$35-1,"n/m") | F9: =IF(AND(ISNUMBER('Inputs'!$F$35),ISNUMBER('Inputs'!$E$35),'Inputs'!$E$35>0),'Inputs'!$F$35/'Inputs'!$E$35-1,"n/m") | G9: =IF(NOT(AND(ISNUMBER($F$9),ISNUMBER($E$9))),"n/a",IF($F$9>$E$9+0.02,"Accelerating",IF($F$9<$E$9-0.02,"Decelerating","Stable")))
A10: EBITDA growth | C10: =IF(AND(ISNUMBER('Inputs'!$C$41),ISNUMBER('Inputs'!$B$41),'Inputs'!$B$41>0),'Inputs'!$C$41/'Inputs'!$B$41-1,"n/m") | D10: =IF(AND(ISNUMBER('Inputs'!$D$41),ISNUMBER('Inputs'!$C$41),'Inputs'!$C$41>0),'Inputs'!$D$41/'Inputs'!$C$41-1,"n/m") | E10: =IF(AND(ISNUMBER('Inputs'!$E$41),ISNUMBER('Inputs'!$D$41),'Inputs'!$D$41>0),'Inputs'!$E$41/'Inputs'!$D$41-1,"n/m") | F10: =IF(AND(ISNUMBER('Inputs'!$F$41),ISNUMBER('Inputs'!$E$41),'Inputs'!$E$41>0),'Inputs'!$F$41/'Inputs'!$E$41-1,"n/m") | G10: =IF(NOT(AND(ISNUMBER($F$10),ISNUMBER($E$10))),"n/a",IF($F$10>$E$10+0.02,"Accelerating",IF($F$10<$E$10-0.02,"Decelerating","Stable")))
A11: EBIT growth | C11: =IF(AND(ISNUMBER('Inputs'!$C$39),ISNUMBER('Inputs'!$B$39),'Inputs'!$B$39>0),'Inputs'!$C$39/'Inputs'!$B$39-1,"n/m") | D11: =IF(AND(ISNUMBER('Inputs'!$D$39),ISNUMBER('Inputs'!$C$39),'Inputs'!$C$39>0),'Inputs'!$D$39/'Inputs'!$C$39-1,"n/m") | E11: =IF(AND(ISNUMBER('Inputs'!$E$39),ISNUMBER('Inputs'!$D$39),'Inputs'!$D$39>0),'Inputs'!$E$39/'Inputs'!$D$39-1,"n/m") | F11: =IF(AND(ISNUMBER('Inputs'!$F$39),ISNUMBER('Inputs'!$E$39),'Inputs'!$E$39>0),'Inputs'!$F$39/'Inputs'!$E$39-1,"n/m") | G11: =IF(NOT(AND(ISNUMBER($F$11),ISNUMBER($E$11))),"n/a",IF($F$11>$E$11+0.02,"Accelerating",IF($F$11<$E$11-0.02,"Decelerating","Stable")))
A12: Net income growth | C12: =IF(AND(ISNUMBER('Inputs'!$C$48),ISNUMBER('Inputs'!$B$48),'Inputs'!$B$48>0),'Inputs'!$C$48/'Inputs'!$B$48-1,"n/m") | D12: =IF(AND(ISNUMBER('Inputs'!$D$48),ISNUMBER('Inputs'!$C$48),'Inputs'!$C$48>0),'Inputs'!$D$48/'Inputs'!$C$48-1,"n/m") | E12: =IF(AND(ISNUMBER('Inputs'!$E$48),ISNUMBER('Inputs'!$D$48),'Inputs'!$D$48>0),'Inputs'!$E$48/'Inputs'!$D$48-1,"n/m") | F12: =IF(AND(ISNUMBER('Inputs'!$F$48),ISNUMBER('Inputs'!$E$48),'Inputs'!$E$48>0),'Inputs'!$F$48/'Inputs'!$E$48-1,"n/m") | G12: =IF(NOT(AND(ISNUMBER($F$12),ISNUMBER($E$12))),"n/a",IF($F$12>$E$12+0.02,"Accelerating",IF($F$12<$E$12-0.02,"Decelerating","Stable")))
A13: Diluted EPS growth | C13: =IF(AND(ISNUMBER('Inputs'!$C$98),ISNUMBER('Inputs'!$B$98),'Inputs'!$B$98>0),'Inputs'!$C$98/'Inputs'!$B$98-1,"n/m") | D13: =IF(AND(ISNUMBER('Inputs'!$D$98),ISNUMBER('Inputs'!$C$98),'Inputs'!$C$98>0),'Inputs'!$D$98/'Inputs'!$C$98-1,"n/m") | E13: =IF(AND(ISNUMBER('Inputs'!$E$98),ISNUMBER('Inputs'!$D$98),'Inputs'!$D$98>0),'Inputs'!$E$98/'Inputs'!$D$98-1,"n/m") | F13: =IF(AND(ISNUMBER('Inputs'!$F$98),ISNUMBER('Inputs'!$E$98),'Inputs'!$E$98>0),'Inputs'!$F$98/'Inputs'!$E$98-1,"n/m") | G13: =IF(NOT(AND(ISNUMBER($F$13),ISNUMBER($E$13))),"n/a",IF($F$13>$E$13+0.02,"Accelerating",IF($F$13<$E$13-0.02,"Decelerating","Stable")))
A15: Profitability & Margins
B16: FY—4 | C16: FY—3 | D16: FY—2 | E16: FY—1 | F16: FY—0 | G16: Latest read
A17: Gross margin | B17: =IF(AND(ISNUMBER('Inputs'!$B$35),ISNUMBER('Inputs'!$B$33),'Inputs'!$B$33<>0),'Inputs'!$B$35/'Inputs'!$B$33,"n/m") | C17: =IF(AND(ISNUMBER('Inputs'!$C$35),ISNUMBER('Inputs'!$C$33),'Inputs'!$C$33<>0),'Inputs'!$C$35/'Inputs'!$C$33,"n/m") | D17: =IF(AND(ISNUMBER('Inputs'!$D$35),ISNUMBER('Inputs'!$D$33),'Inputs'!$D$33<>0),'Inputs'!$D$35/'Inputs'!$D$33,"n/m") | E17: =IF(AND(ISNUMBER('Inputs'!$E$35),ISNUMBER('Inputs'!$E$33),'Inputs'!$E$33<>0),'Inputs'!$E$35/'Inputs'!$E$33,"n/m") | F17: =IF(AND(ISNUMBER('Inputs'!$F$35),ISNUMBER('Inputs'!$F$33),'Inputs'!$F$33<>0),'Inputs'!$F$35/'Inputs'!$F$33,"n/m") | G17: =IF(NOT(AND(ISNUMBER($F$17),ISNUMBER(AVERAGE($B$17:$E$17)))),"n/a",IF($F$17>AVERAGE($B$17:$E$17)*(1+0.05),"Expanding",IF($F$17<AVERAGE($B$17:$E$17)*(1-0.05),"Compressing","Stable")))
A18: EBITDA margin | B18: =IF(AND(ISNUMBER('Inputs'!$B$41),ISNUMBER('Inputs'!$B$33),'Inputs'!$B$33<>0),'Inputs'!$B$41/'Inputs'!$B$33,"n/m") | C18: =IF(AND(ISNUMBER('Inputs'!$C$41),ISNUMBER('Inputs'!$C$33),'Inputs'!$C$33<>0),'Inputs'!$C$41/'Inputs'!$C$33,"n/m") | D18: =IF(AND(ISNUMBER('Inputs'!$D$41),ISNUMBER('Inputs'!$D$33),'Inputs'!$D$33<>0),'Inputs'!$D$41/'Inputs'!$D$33,"n/m") | E18: =IF(AND(ISNUMBER('Inputs'!$E$41),ISNUMBER('Inputs'!$E$33),'Inputs'!$E$33<>0),'Inputs'!$E$41/'Inputs'!$E$33,"n/m") | F18: =IF(AND(ISNUMBER('Inputs'!$F$41),ISNUMBER('Inputs'!$F$33),'Inputs'!$F$33<>0),'Inputs'!$F$41/'Inputs'!$F$33,"n/m") | G18: =IF(NOT(AND(ISNUMBER($F$18),ISNUMBER(AVERAGE($B$18:$E$18)))),"n/a",IF($F$18>AVERAGE($B$18:$E$18)*(1+0.05),"Expanding",IF($F$18<AVERAGE($B$18:$E$18)*(1-0.05),"Compressing","Stable")))
A19: EBIT (operating) margin | B19: =IF(AND(ISNUMBER('Inputs'!$B$39),ISNUMBER('Inputs'!$B$33),'Inputs'!$B$33<>0),'Inputs'!$B$39/'Inputs'!$B$33,"n/m") | C19: =IF(AND(ISNUMBER('Inputs'!$C$39),ISNUMBER('Inputs'!$C$33),'Inputs'!$C$33<>0),'Inputs'!$C$39/'Inputs'!$C$33,"n/m") | D19: =IF(AND(ISNUMBER('Inputs'!$D$39),ISNUMBER('Inputs'!$D$33),'Inputs'!$D$33<>0),'Inputs'!$D$39/'Inputs'!$D$33,"n/m") | E19: =IF(AND(ISNUMBER('Inputs'!$E$39),ISNUMBER('Inputs'!$E$33),'Inputs'!$E$33<>0),'Inputs'!$E$39/'Inputs'!$E$33,"n/m") | F19: =IF(AND(ISNUMBER('Inputs'!$F$39),ISNUMBER('Inputs'!$F$33),'Inputs'!$F$33<>0),'Inputs'!$F$39/'Inputs'!$F$33,"n/m") | G19: =IF(NOT(AND(ISNUMBER($F$19),ISNUMBER(AVERAGE($B$19:$E$19)))),"n/a",IF($F$19>AVERAGE($B$19:$E$19)*(1+0.05),"Expanding",IF($F$19<AVERAGE($B$19:$E$19)*(1-0.05),"Compressing","Stable")))
A20: Net margin | B20: =IF(AND(ISNUMBER('Inputs'!$B$48),ISNUMBER('Inputs'!$B$33),'Inputs'!$B$33<>0),'Inputs'!$B$48/'Inputs'!$B$33,"n/m") | C20: =IF(AND(ISNUMBER('Inputs'!$C$48),ISNUMBER('Inputs'!$C$33),'Inputs'!$C$33<>0),'Inputs'!$C$48/'Inputs'!$C$33,"n/m") | D20: =IF(AND(ISNUMBER('Inputs'!$D$48),ISNUMBER('Inputs'!$D$33),'Inputs'!$D$33<>0),'Inputs'!$D$48/'Inputs'!$D$33,"n/m") | E20: =IF(AND(ISNUMBER('Inputs'!$E$48),ISNUMBER('Inputs'!$E$33),'Inputs'!$E$33<>0),'Inputs'!$E$48/'Inputs'!$E$33,"n/m") | F20: =IF(AND(ISNUMBER('Inputs'!$F$48),ISNUMBER('Inputs'!$F$33),'Inputs'!$F$33<>0),'Inputs'!$F$48/'Inputs'!$F$33,"n/m") | G20: =IF(NOT(AND(ISNUMBER($F$20),ISNUMBER(AVERAGE($B$20:$E$20)))),"n/a",IF($F$20>AVERAGE($B$20:$E$20)*(1+0.05),"Expanding",IF($F$20<AVERAGE($B$20:$E$20)*(1-0.05),"Compressing","Stable")))
A21: SG&A % of revenue | B21: =IF(AND(ISNUMBER('Inputs'!$B$36),ISNUMBER('Inputs'!$B$33),'Inputs'!$B$33<>0),'Inputs'!$B$36/'Inputs'!$B$33,"n/m") | C21: =IF(AND(ISNUMBER('Inputs'!$C$36),ISNUMBER('Inputs'!$C$33),'Inputs'!$C$33<>0),'Inputs'!$C$36/'Inputs'!$C$33,"n/m") | D21: =IF(AND(ISNUMBER('Inputs'!$D$36),ISNUMBER('Inputs'!$D$33),'Inputs'!$D$33<>0),'Inputs'!$D$36/'Inputs'!$D$33,"n/m") | E21: =IF(AND(ISNUMBER('Inputs'!$E$36),ISNUMBER('Inputs'!$E$33),'Inputs'!$E$33<>0),'Inputs'!$E$36/'Inputs'!$E$33,"n/m") | F21: =IF(AND(ISNUMBER('Inputs'!$F$36),ISNUMBER('Inputs'!$F$33),'Inputs'!$F$33<>0),'Inputs'!$F$36/'Inputs'!$F$33,"n/m") | G21: =IF(NOT(AND(ISNUMBER($F$21),ISNUMBER(AVERAGE($B$21:$E$21)))),"n/a",IF($F$21>AVERAGE($B$21:$E$21)*(1+0.05),"Deteriorating",IF($F$21<AVERAGE($B$21:$E$21)*(1-0.05),"Improving","Stable")))
A22: R&D % of revenue | B22: =IF(AND(ISNUMBER('Inputs'!$B$37),ISNUMBER('Inputs'!$B$33),'Inputs'!$B$33<>0),'Inputs'!$B$37/'Inputs'!$B$33,"n/m") | C22: =IF(AND(ISNUMBER('Inputs'!$C$37),ISNUMBER('Inputs'!$C$33),'Inputs'!$C$33<>0),'Inputs'!$C$37/'Inputs'!$C$33,"n/m") | D22: =IF(AND(ISNUMBER('Inputs'!$D$37),ISNUMBER('Inputs'!$D$33),'Inputs'!$D$33<>0),'Inputs'!$D$37/'Inputs'!$D$33,"n/m") | E22: =IF(AND(ISNUMBER('Inputs'!$E$37),ISNUMBER('Inputs'!$E$33),'Inputs'!$E$33<>0),'Inputs'!$E$37/'Inputs'!$E$33,"n/m") | F22: =IF(AND(ISNUMBER('Inputs'!$F$37),ISNUMBER('Inputs'!$F$33),'Inputs'!$F$33<>0),'Inputs'!$F$37/'Inputs'!$F$33,"n/m") | G22: =IF(NOT(AND(ISNUMBER($F$22),ISNUMBER(AVERAGE($B$22:$E$22)))),"n/a",IF($F$22>AVERAGE($B$22:$E$22)*(1+0.05),"Deteriorating",IF($F$22<AVERAGE($B$22:$E$22)*(1-0.05),"Improving","Stable")))
A23: D&A % of revenue | B23: =IF(AND(ISNUMBER('Inputs'!$B$40),ISNUMBER('Inputs'!$B$33),'Inputs'!$B$33<>0),'Inputs'!$B$40/'Inputs'!$B$33,"n/m") | C23: =IF(AND(ISNUMBER('Inputs'!$C$40),ISNUMBER('Inputs'!$C$33),'Inputs'!$C$33<>0),'Inputs'!$C$40/'Inputs'!$C$33,"n/m") | D23: =IF(AND(ISNUMBER('Inputs'!$D$40),ISNUMBER('Inputs'!$D$33),'Inputs'!$D$33<>0),'Inputs'!$D$40/'Inputs'!$D$33,"n/m") | E23: =IF(AND(ISNUMBER('Inputs'!$E$40),ISNUMBER('Inputs'!$E$33),'Inputs'!$E$33<>0),'Inputs'!$E$40/'Inputs'!$E$33,"n/m") | F23: =IF(AND(ISNUMBER('Inputs'!$F$40),ISNUMBER('Inputs'!$F$33),'Inputs'!$F$33<>0),'Inputs'!$F$40/'Inputs'!$F$33,"n/m")
A24: Interest burden (EBT / EBIT) | B24: =IF(AND(ISNUMBER('Inputs'!$B$45),ISNUMBER('Inputs'!$B$39),'Inputs'!$B$39<>0),'Inputs'!$B$45/'Inputs'!$B$39,"n/m") | C24: =IF(AND(ISNUMBER('Inputs'!$C$45),ISNUMBER('Inputs'!$C$39),'Inputs'!$C$39<>0),'Inputs'!$C$45/'Inputs'!$C$39,"n/m") | D24: =IF(AND(ISNUMBER('Inputs'!$D$45),ISNUMBER('Inputs'!$D$39),'Inputs'!$D$39<>0),'Inputs'!$D$45/'Inputs'!$D$39,"n/m") | E24: =IF(AND(ISNUMBER('Inputs'!$E$45),ISNUMBER('Inputs'!$E$39),'Inputs'!$E$39<>0),'Inputs'!$E$45/'Inputs'!$E$39,"n/m") | F24: =IF(AND(ISNUMBER('Inputs'!$F$45),ISNUMBER('Inputs'!$F$39),'Inputs'!$F$39<>0),'Inputs'!$F$45/'Inputs'!$F$39,"n/m") | G24: =IF(NOT(AND(ISNUMBER($F$24),ISNUMBER(AVERAGE($B$24:$E$24)))),"n/a",IF($F$24>AVERAGE($B$24:$E$24)*(1+0.05),"Improving",IF($F$24<AVERAGE($B$24:$E$24)*(1-0.05),"Deteriorating","Stable")))
A25: Tax burden (NI / EBT) | B25: =IF(AND(ISNUMBER('Inputs'!$B$48),ISNUMBER('Inputs'!$B$45),'Inputs'!$B$45<>0),'Inputs'!$B$48/'Inputs'!$B$45,"n/m") | C25: =IF(AND(ISNUMBER('Inputs'!$C$48),ISNUMBER('Inputs'!$C$45),'Inputs'!$C$45<>0),'Inputs'!$C$48/'Inputs'!$C$45,"n/m") | D25: =IF(AND(ISNUMBER('Inputs'!$D$48),ISNUMBER('Inputs'!$D$45),'Inputs'!$D$45<>0),'Inputs'!$D$48/'Inputs'!$D$45,"n/m") | E25: =IF(AND(ISNUMBER('Inputs'!$E$48),ISNUMBER('Inputs'!$E$45),'Inputs'!$E$45<>0),'Inputs'!$E$48/'Inputs'!$E$45,"n/m") | F25: =IF(AND(ISNUMBER('Inputs'!$F$48),ISNUMBER('Inputs'!$F$45),'Inputs'!$F$45<>0),'Inputs'!$F$48/'Inputs'!$F$45,"n/m") | G25: =IF(NOT(AND(ISNUMBER($F$25),ISNUMBER(AVERAGE($B$25:$E$25)))),"n/a",IF($F$25>AVERAGE($B$25:$E$25)*(1+0.05),"Improving",IF($F$25<AVERAGE($B$25:$E$25)*(1-0.05),"Deteriorating","Stable")))
A26: Effective tax rate | B26: =IF(AND(ISNUMBER('Inputs'!$B$46),ISNUMBER('Inputs'!$B$45),'Inputs'!$B$45<>0),'Inputs'!$B$46/'Inputs'!$B$45,"n/m") | C26: =IF(AND(ISNUMBER('Inputs'!$C$46),ISNUMBER('Inputs'!$C$45),'Inputs'!$C$45<>0),'Inputs'!$C$46/'Inputs'!$C$45,"n/m") | D26: =IF(AND(ISNUMBER('Inputs'!$D$46),ISNUMBER('Inputs'!$D$45),'Inputs'!$D$45<>0),'Inputs'!$D$46/'Inputs'!$D$45,"n/m") | E26: =IF(AND(ISNUMBER('Inputs'!$E$46),ISNUMBER('Inputs'!$E$45),'Inputs'!$E$45<>0),'Inputs'!$E$46/'Inputs'!$E$45,"n/m") | F26: =IF(AND(ISNUMBER('Inputs'!$F$46),ISNUMBER('Inputs'!$F$45),'Inputs'!$F$45<>0),'Inputs'!$F$46/'Inputs'!$F$45,"n/m")
A28: Returns on Capital
B29: FY—4 | C29: FY—3 | D29: FY—2 | E29: FY—1 | F29: FY—0 | G29: Latest read
A30: NOPAT = EBIT × (1 − effective tax) | B30: =IF(AND(ISNUMBER('Inputs'!$B$39),ISNUMBER('Inputs'!$B$46),ISNUMBER('Inputs'!$B$45)),'Inputs'!$B$39*(1-'Inputs'!$B$46/'Inputs'!$B$45),"n/m") | C30: =IF(AND(ISNUMBER('Inputs'!$C$39),ISNUMBER('Inputs'!$C$46),ISNUMBER('Inputs'!$C$45)),'Inputs'!$C$39*(1-'Inputs'!$C$46/'Inputs'!$C$45),"n/m") | D30: =IF(AND(ISNUMBER('Inputs'!$D$39),ISNUMBER('Inputs'!$D$46),ISNUMBER('Inputs'!$D$45)),'Inputs'!$D$39*(1-'Inputs'!$D$46/'Inputs'!$D$45),"n/m") | E30: =IF(AND(ISNUMBER('Inputs'!$E$39),ISNUMBER('Inputs'!$E$46),ISNUMBER('Inputs'!$E$45)),'Inputs'!$E$39*(1-'Inputs'!$E$46/'Inputs'!$E$45),"n/m") | F30: =IF(AND(ISNUMBER('Inputs'!$F$39),ISNUMBER('Inputs'!$F$46),ISNUMBER('Inputs'!$F$45)),'Inputs'!$F$39*(1-'Inputs'!$F$46/'Inputs'!$F$45),"n/m")
A31: Invested capital (debt + equity − cash) | B31: ='Inputs'!$B$71+'Inputs'!$B$72+'Inputs'!$B$64+'Inputs'!$B$67-'Inputs'!$B$52-'Inputs'!$B$53 | C31: ='Inputs'!$C$71+'Inputs'!$C$72+'Inputs'!$C$64+'Inputs'!$C$67-'Inputs'!$C$52-'Inputs'!$C$53 | D31: ='Inputs'!$D$71+'Inputs'!$D$72+'Inputs'!$D$64+'Inputs'!$D$67-'Inputs'!$D$52-'Inputs'!$D$53 | E31: ='Inputs'!$E$71+'Inputs'!$E$72+'Inputs'!$E$64+'Inputs'!$E$67-'Inputs'!$E$52-'Inputs'!$E$53 | F31: ='Inputs'!$F$71+'Inputs'!$F$72+'Inputs'!$F$64+'Inputs'!$F$67-'Inputs'!$F$52-'Inputs'!$F$53
A32: Return on equity (ROE) | B32: =IF(AND(ISNUMBER('Inputs'!$B$48),ISNUMBER('Inputs'!$B$71),'Inputs'!$B$71<>0),'Inputs'!$B$48/'Inputs'!$B$71,"n/m") | C32: =IF(AND(ISNUMBER('Inputs'!$C$48),ISNUMBER('Inputs'!$C$71),'Inputs'!$C$71<>0),'Inputs'!$C$48/'Inputs'!$C$71,"n/m") | D32: =IF(AND(ISNUMBER('Inputs'!$D$48),ISNUMBER('Inputs'!$D$71),'Inputs'!$D$71<>0),'Inputs'!$D$48/'Inputs'!$D$71,"n/m") | E32: =IF(AND(ISNUMBER('Inputs'!$E$48),ISNUMBER('Inputs'!$E$71),'Inputs'!$E$71<>0),'Inputs'!$E$48/'Inputs'!$E$71,"n/m") | F32: =IF(AND(ISNUMBER('Inputs'!$F$48),ISNUMBER('Inputs'!$F$71),'Inputs'!$F$71<>0),'Inputs'!$F$48/'Inputs'!$F$71,"n/m") | G32: =IF(NOT(ISNUMBER($F$32)),"n/a",IF($F$32<0.08,"Weak",IF($F$32<0.15,"Moderate","Strong")))
A33: Return on assets (ROA) | B33: =IF(AND(ISNUMBER('Inputs'!$B$48),ISNUMBER('Inputs'!$B$62),'Inputs'!$B$62<>0),'Inputs'!$B$48/'Inputs'!$B$62,"n/m") | C33: =IF(AND(ISNUMBER('Inputs'!$C$48),ISNUMBER('Inputs'!$C$62),'Inputs'!$C$62<>0),'Inputs'!$C$48/'Inputs'!$C$62,"n/m") | D33: =IF(AND(ISNUMBER('Inputs'!$D$48),ISNUMBER('Inputs'!$D$62),'Inputs'!$D$62<>0),'Inputs'!$D$48/'Inputs'!$D$62,"n/m") | E33: =IF(AND(ISNUMBER('Inputs'!$E$48),ISNUMBER('Inputs'!$E$62),'Inputs'!$E$62<>0),'Inputs'!$E$48/'Inputs'!$E$62,"n/m") | F33: =IF(AND(ISNUMBER('Inputs'!$F$48),ISNUMBER('Inputs'!$F$62),'Inputs'!$F$62<>0),'Inputs'!$F$48/'Inputs'!$F$62,"n/m") | G33: =IF(NOT(ISNUMBER($F$33)),"n/a",IF($F$33<0.03,"Weak",IF($F$33<0.07,"Moderate","Strong")))
A34: Return on invested capital (ROIC) | B34: =IF(AND(ISNUMBER('Historical'!$B$30),ISNUMBER('Historical'!$B$31),'Historical'!$B$31<>0),'Historical'!$B$30/'Historical'!$B$31,"n/m") | C34: =IF(AND(ISNUMBER('Historical'!$C$30),ISNUMBER('Historical'!$C$31),'Historical'!$C$31<>0),'Historical'!$C$30/'Historical'!$C$31,"n/m") | D34: =IF(AND(ISNUMBER('Historical'!$D$30),ISNUMBER('Historical'!$D$31),'Historical'!$D$31<>0),'Historical'!$D$30/'Historical'!$D$31,"n/m") | E34: =IF(AND(ISNUMBER('Historical'!$E$30),ISNUMBER('Historical'!$E$31),'Historical'!$E$31<>0),'Historical'!$E$30/'Historical'!$E$31,"n/m") | F34: =IF(AND(ISNUMBER('Historical'!$F$30),ISNUMBER('Historical'!$F$31),'Historical'!$F$31<>0),'Historical'!$F$30/'Historical'!$F$31,"n/m") | G34: =IF(NOT(ISNUMBER($F$34)),"n/a",IF($F$34<0.08,"Weak",IF($F$34<0.12,"Moderate","Strong")))
A35: Return on capital employed (ROCE) | B35: =IF(AND(ISNUMBER('Inputs'!$B$39),ISNUMBER(('Inputs'!$B$62-'Inputs'!$B$66)),('Inputs'!$B$62-'Inputs'!$B$66)<>0),'Inputs'!$B$39/('Inputs'!$B$62-'Inputs'!$B$66),"n/m") | C35: =IF(AND(ISNUMBER('Inputs'!$C$39),ISNUMBER(('Inputs'!$C$62-'Inputs'!$C$66)),('Inputs'!$C$62-'Inputs'!$C$66)<>0),'Inputs'!$C$39/('Inputs'!$C$62-'Inputs'!$C$66),"n/m") | D35: =IF(AND(ISNUMBER('Inputs'!$D$39),ISNUMBER(('Inputs'!$D$62-'Inputs'!$D$66)),('Inputs'!$D$62-'Inputs'!$D$66)<>0),'Inputs'!$D$39/('Inputs'!$D$62-'Inputs'!$D$66),"n/m") | E35: =IF(AND(ISNUMBER('Inputs'!$E$39),ISNUMBER(('Inputs'!$E$62-'Inputs'!$E$66)),('Inputs'!$E$62-'Inputs'!$E$66)<>0),'Inputs'!$E$39/('Inputs'!$E$62-'Inputs'!$E$66),"n/m") | F35: =IF(AND(ISNUMBER('Inputs'!$F$39),ISNUMBER(('Inputs'!$F$62-'Inputs'!$F$66)),('Inputs'!$F$62-'Inputs'!$F$66)<>0),'Inputs'!$F$39/('Inputs'!$F$62-'Inputs'!$F$66),"n/m") | G35: =IF(NOT(ISNUMBER($F$35)),"n/a",IF($F$35<0.08,"Weak",IF($F$35<0.12,"Moderate","Strong")))
A37: Liquidity
B38: FY—4 | C38: FY—3 | D38: FY—2 | E38: FY—1 | F38: FY—0 | G38: Latest read
A39: Current ratio | B39: =IF(AND(ISNUMBER('Inputs'!$B$57),ISNUMBER('Inputs'!$B$66),'Inputs'!$B$66<>0),'Inputs'!$B$57/'Inputs'!$B$66,"n/m") | C39: =IF(AND(ISNUMBER('Inputs'!$C$57),ISNUMBER('Inputs'!$C$66),'Inputs'!$C$66<>0),'Inputs'!$C$57/'Inputs'!$C$66,"n/m") | D39: =IF(AND(ISNUMBER('Inputs'!$D$57),ISNUMBER('Inputs'!$D$66),'Inputs'!$D$66<>0),'Inputs'!$D$57/'Inputs'!$D$66,"n/m") | E39: =IF(AND(ISNUMBER('Inputs'!$E$57),ISNUMBER('Inputs'!$E$66),'Inputs'!$E$66<>0),'Inputs'!$E$57/'Inputs'!$E$66,"n/m") | F39: =IF(AND(ISNUMBER('Inputs'!$F$57),ISNUMBER('Inputs'!$F$66),'Inputs'!$F$66<>0),'Inputs'!$F$57/'Inputs'!$F$66,"n/m") | G39: =IF(NOT(ISNUMBER($F$39)),"n/a",IF($F$39<1.0,"Weak",IF($F$39<2.0,"Adequate","Strong")))
A40: Quick ratio (ex-inventory) | B40: =IF(AND(ISNUMBER(('Inputs'!$B$57-'Inputs'!$B$55)),ISNUMBER('Inputs'!$B$66),'Inputs'!$B$66<>0),('Inputs'!$B$57-'Inputs'!$B$55)/'Inputs'!$B$66,"n/m") | C40: =IF(AND(ISNUMBER(('Inputs'!$C$57-'Inputs'!$C$55)),ISNUMBER('Inputs'!$C$66),'Inputs'!$C$66<>0),('Inputs'!$C$57-'Inputs'!$C$55)/'Inputs'!$C$66,"n/m") | D40: =IF(AND(ISNUMBER(('Inputs'!$D$57-'Inputs'!$D$55)),ISNUMBER('Inputs'!$D$66),'Inputs'!$D$66<>0),('Inputs'!$D$57-'Inputs'!$D$55)/'Inputs'!$D$66,"n/m") | E40: =IF(AND(ISNUMBER(('Inputs'!$E$57-'Inputs'!$E$55)),ISNUMBER('Inputs'!$E$66),'Inputs'!$E$66<>0),('Inputs'!$E$57-'Inputs'!$E$55)/'Inputs'!$E$66,"n/m") | F40: =IF(AND(ISNUMBER(('Inputs'!$F$57-'Inputs'!$F$55)),ISNUMBER('Inputs'!$F$66),'Inputs'!$F$66<>0),('Inputs'!$F$57-'Inputs'!$F$55)/'Inputs'!$F$66,"n/m") | G40: =IF(NOT(ISNUMBER($F$40)),"n/a",IF($F$40<0.8,"Weak",IF($F$40<1.2,"Adequate","Strong")))
A41: Cash ratio | B41: =IF(AND(ISNUMBER(('Inputs'!$B$52+'Inputs'!$B$53)),ISNUMBER('Inputs'!$B$66),'Inputs'!$B$66<>0),('Inputs'!$B$52+'Inputs'!$B$53)/'Inputs'!$B$66,"n/m") | C41: =IF(AND(ISNUMBER(('Inputs'!$C$52+'Inputs'!$C$53)),ISNUMBER('Inputs'!$C$66),'Inputs'!$C$66<>0),('Inputs'!$C$52+'Inputs'!$C$53)/'Inputs'!$C$66,"n/m") | D41: =IF(AND(ISNUMBER(('Inputs'!$D$52+'Inputs'!$D$53)),ISNUMBER('Inputs'!$D$66),'Inputs'!$D$66<>0),('Inputs'!$D$52+'Inputs'!$D$53)/'Inputs'!$D$66,"n/m") | E41: =IF(AND(ISNUMBER(('Inputs'!$E$52+'Inputs'!$E$53)),ISNUMBER('Inputs'!$E$66),'Inputs'!$E$66<>0),('Inputs'!$E$52+'Inputs'!$E$53)/'Inputs'!$E$66,"n/m") | F41: =IF(AND(ISNUMBER(('Inputs'!$F$52+'Inputs'!$F$53)),ISNUMBER('Inputs'!$F$66),'Inputs'!$F$66<>0),('Inputs'!$F$52+'Inputs'!$F$53)/'Inputs'!$F$66,"n/m") | G41: =IF(NOT(ISNUMBER($F$41)),"n/a",IF($F$41<0.2,"Weak",IF($F$41<0.5,"Adequate","Strong")))
A43: Leverage & Solvency
B44: FY—4 | C44: FY—3 | D44: FY—2 | E44: FY—1 | F44: FY—0 | G44: Latest read
A45: Total debt | B45: ='Inputs'!$B$64+'Inputs'!$B$67 | C45: ='Inputs'!$C$64+'Inputs'!$C$67 | D45: ='Inputs'!$D$64+'Inputs'!$D$67 | E45: ='Inputs'!$E$64+'Inputs'!$E$67 | F45: ='Inputs'!$F$64+'Inputs'!$F$67
...

Sheet Assumptions
A1: ASSUMPTIONS
A2: DCF assumption engine — driver-based, scenario-aware, fully sourced
A3: Investment-Grade Company Analysis Engine · v1.0
A5: Scenario Selector
A6: Active scenario (1=Base, 2=Bull, 3=Bear, 4=Downside) | B6: 1 | E6: ← active scenario: | F6: input | G6: =CHOOSE('Assumptions'!$B$6,"Base","Bull","Bear","Downside")
A8: Derived Historical Anchors (read-only)
A9: These are computed from the Historical sheet and feed the base case.
A10: Historical revenue CAGR (full window) | B10: =IF(AND(ISNUMBER('Inputs'!$F$33),ISNUMBER('Inputs'!$B$33),'Inputs'!$B$33>0,'Inputs'!$F$33>0,4>0),('Inputs'!$F$33/'Inputs'!$B$33)^(1/4)-1,"n/m") | F10: model-derived | G10: Compound annual revenue growth across all reported years.
A11: Latest-year revenue growth | B11: ='Historical'!$F$8 | F11: model-derived | G11: Most recent year-on-year growth.
A12: Avg EBIT margin (last 3y) | B12: =IFERROR(AVERAGE('Historical'!$D$19,'Historical'!$E$19,'Historical'!$F$19),"n/a") | F12: model-derived | G12: Anchor for the sustainable operating margin.
A13: Avg D&A % of revenue (last 3y) | B13: =IFERROR(AVERAGE('Historical'!$D$23,'Historical'!$E$23,'Historical'!$F$23),"n/a") | F13: model-derived | G13: Drives forecast depreciation & amortisation.
A14: Avg capex intensity (last 3y) | B14: =IFERROR(AVERAGE('Historical'!$D$68,'Historical'!$E$68,'Historical'!$F$68),"n/a") | F14: model-derived | G14: Drives forecast capital expenditure.
A15: Net working capital % of revenue | B15: =IF(AND(ISNUMBER(('Inputs'!$F$54+'Inputs'!$F$55-'Inputs'!$F$63)),ISNUMBER('Inputs'!$F$33),'Inputs'!$F$33<>0),('Inputs'!$F$54+'Inputs'!$F$55-'Inputs'!$F$63)/'Inputs'!$F$33,"n/m") | F15: model-derived | G15: Working capital scales with sales at this ratio.
A17: Forecast Drivers by Scenario
A18: Driver | B18: Base | C18: Bull | D18: Bear | E18: Downside | F18: Source | G18: Rationale
A19: Blended raw start growth | B19: =IF(AND(ISNUMBER('Assumptions'!$B$10),ISNUMBER('Assumptions'!$B$11)),('Assumptions'!$B$10+'Assumptions'!$B$11)/2,IF(ISNUMBER('Assumptions'!$B$10),'Assumptions'!$B$10,IF(ISNUMBER('Assumptions'!$B$11),'Assumptions'!$B$11,0.03))) | G19: Average of historical CAGR and latest growth (fallback to long-run).
A20: Revenue growth — year 1 (start) | B20: =MAX(-0.05,MIN(0.20,'Assumptions'!$B$19)) | C20: =MAX(-0.3,MIN(0.3,'Assumptions'!$B$20+0.03)) | D20: =MAX(-0.3,MIN(0.3,'Assumptions'!$B$20+-0.03)) | E20: =MAX(-0.3,MIN(0.3,'Assumptions'!$B$20+-0.06)) | F20: model-derived | G20: Start of the revenue path; clamped to a sane band. Bull/Bear/Downside add ±tilts.
A21: Terminal / perpetuity growth (g) | B21: =MIN(0.025,'WACC'!$B$24-0.01) | C21: =MAX(-0.02,MIN('WACC'!$B$24-0.01,'Assumptions'!$B$21+0.005)) | D21: =MAX(-0.02,MIN('WACC'!$B$24-0.01,'Assumptions'!$B$21+-0.005)) | E21: =MAX(-0.02,MIN('WACC'!$B$24-0.01,'Assumptions'!$B$21+-0.01)) | F21: assumption | G21: Long-run growth into perpetuity; capped at WACC−1% so TV stays finite.
A22: Terminal EBIT margin | B22: =IF(ISNUMBER('Assumptions'!$B$12),MAX(0,MIN(0.60,'Assumptions'!$B$12)),0.12) | C22: =MAX(0.0,MIN(0.6,'Assumptions'!$B$22+0.02)) | D22: =MAX(0.0,MIN(0.6,'Assumptions'!$B$22+-0.02)) | E22: =MAX(0.0,MIN(0.6,'Assumptions'!$B$22+-0.05)) | F22: model-derived | G22: Operating margin the business converges to by the terminal year.
A24: Scenario-Invariant Drivers
A25: D&A as % of revenue | B25: =IF(ISNUMBER('Assumptions'!$B$13),'Assumptions'!$B$13,0.05) | F25: derived/fallback | G25: Historical average; conservative fallback if no history.
A26: Capex as % of revenue | B26: =IF(ISNUMBER('Assumptions'!$B$14),'Assumptions'!$B$14,0.05) | F26: derived/fallback | G26: Historical average; in steady state ≈ D&A.
A27: Net working capital % of revenue | B27: =IF(ISNUMBER('Assumptions'!$B$15),'Assumptions'!$B$15,0.1) | F27: derived/fallback | G27: ΔWC each year = this % × the change in revenue.
A28: Tax rate (from WACC sheet) | B28: ='WACC'!$B$13 | F28: linked | G28: Marginal tax rate applied to EBIT to get NOPAT.
A29: Exit EBITDA multiple (TV cross-check) | B29: 8.0 | F29: fallback | G29: Generic multiple for the exit-multiple terminal-value cross-check only.
A30: Forecast horizon (years) | B30: 5 | F30: setting | G30: Number of explicitly forecast years before terminal value.
A32: Active Assumptions (resolved by selector)
A33: These are the values the Forecast & DCF actually use.
A34: Active start revenue growth | B34: =CHOOSE('Assumptions'!$B$6,'Assumptions'!$B$20,'Assumptions'!$C$20,'Assumptions'!$D$20,'Assumptions'!$E$20) | F34: active | G34: Year-1 revenue growth for the selected scenario.
A35: Active terminal growth (g) | B35: =CHOOSE('Assumptions'!$B$6,'Assumptions'!$B$21,'Assumptions'!$C$21,'Assumptions'!$D$21,'Assumptions'!$E$21) | F35: active | G35: Perpetuity growth; also the year-N revenue growth (smooth hand-off to TV).
A36: Active terminal EBIT margin | B36: =CHOOSE('Assumptions'!$B$6,'Assumptions'!$B$22,'Assumptions'!$C$22,'Assumptions'!$D$22,'Assumptions'!$E$22) | F36: active | G36: EBIT margin the forecast converges to.
A38: Methodology Notes
A39: • Revenue is forecast by fading the year-1 growth rate linearly to the terminal growth rate over the horizon — a transparent mean-reversion that avoids an arbitrary flat growth assumption.
A40: • Operating margin fades linearly from the last reported EBIT margin to the terminal target margin, reflecting gradual normalisation rather than a step change.
A41: • Capex, D&A and working capital are tied to revenue via historical intensity ratios, so they scale with the business instead of being guessed.
A42: • Scenarios change only a few economically meaningful levers (growth and margin); this keeps the bull/bear/downside cases comparable and interpretable.
A43: • Where a needed figure is missing, the model falls back to a clearly-labelled conservative default rather than inventing a number.

Sheet WACC
A1: WACC
A2: Weighted average cost of capital — built up step by step
A3: Investment-Grade Company Analysis Engine · v1.0
A5: 1 · Cost of Equity — CAPM
A6: Risk-free rate (Rf) | B6: =IF(ISNUMBER('Inputs'!$B$115),'Inputs'!$B$115,0.04) | C6: =IF(ISNUMBER('Inputs'!$B$115),"input","fallback") | D6: Long-dated government bond yield in the reporting currency.
A7: Equity risk premium (ERP) | B7: =IF(ISNUMBER('Inputs'!$B$116),'Inputs'!$B$116,0.05) | C7: =IF(ISNUMBER('Inputs'!$B$116),"input","fallback") | D7: Expected return of equities over the risk-free rate.
A8: Beta (β) | B8: =IF(ISNUMBER('Inputs'!$B$114),'Inputs'!$B$114,1.0) | C8: =IF(ISNUMBER('Inputs'!$B$114),"input","fallback") | D8: Levered equity beta vs the market; fallback 1.00 (market risk).
A9: Cost of equity Ke = Rf + β × ERP | B9: ='WACC'!$B$6+'WACC'!$B$8*'WACC'!$B$7 | C9: computed | D9: CAPM. Ke is the return equity holders require.
A11: 2 · Cost of Debt
A12: Pre-tax cost of debt (Kd) | B12: =IF(ISNUMBER('Inputs'!$B$117),'Inputs'!$B$117,0.06) | C12: =IF(ISNUMBER('Inputs'!$B$117),"input","fallback") | D12: Marginal borrowing rate. Cross-check vs implied rate below.
A13: Marginal tax rate (t) | B13: =IF(ISNUMBER('Inputs'!$B$118),'Inputs'!$B$118,0.25) | C13: =IF(ISNUMBER('Inputs'!$B$118),"input","fallback") | D13: Used to tax-shield debt and for NOPAT in the DCF.
A14: After-tax cost of debt Kd × (1 − t) | B14: ='WACC'!$B$12*(1-'WACC'!$B$13) | C14: computed | D14: Interest is tax-deductible, lowering its effective cost.
A15: Implied rate cross-check (int. exp / debt) | B15: =IFERROR('Inputs'!$F$42/'Historical'!$F$45,"n/a") | C15: computed | D15: Sanity check on the assumed pre-tax cost of debt.
A17: 3 · Capital Structure (market weights)
A18: Equity value (E) | B18: =IF(ISNUMBER('Inputs'!$B$119),'Inputs'!$B$119,'Inputs'!$F$71) | C18: =IF(ISNUMBER('Inputs'!$B$119),"market","book (fallback)") | D18: Market capitalisation; falls back to book equity if price/shares missing.
A19: Debt value (D) | B19: ='Historical'!$F$45 | C19: book | D19: Total interest-bearing debt (book value as a proxy for market value).
A20: Equity weight We = E / (E + D) | B20: =IFERROR('WACC'!$B$18/('WACC'!$B$18+'WACC'!$B$19),1) | C20: computed | D20: Share of capital funded by equity.
A21: Debt weight Wd = D / (E + D) | B21: =IFERROR('WACC'!$B$19/('WACC'!$B$18+'WACC'!$B$19),0) | C21: computed | D21: Share of capital funded by debt.
A23: 4 · Weighted Average Cost of Capital
A24: WACC = We × Ke + Wd × Kd(1−t) | B24: ='WACC'!$B$20*'WACC'!$B$9+'WACC'!$B$21*'WACC'!$B$14 | D24: The blended required return used to discount the forecast cash flows.
A25: Plausibility | D25: =IF(AND('WACC'!$B$24>=0.035,'WACC'!$B$24>=0.04,'WACC'!$B$24<=0.18),"Within a reasonable range","Outside typical 4–18% range — review inputs")
A27: How to read this
A28: • WACC rises with beta, the equity risk premium and leverage cost, and falls with the tax shield on debt. It is the single most important valuation input.
A29: • If you have no market data, the fallback defaults give a defensible starting point; replace them with company-specific figures for a real valuation.
A30: • Equity value uses market cap where available — the market's own view of equity — rather than book value, which can be stale.

Sheet Forecast
A1: FORECAST
A2: Driver-based operating forecast & unlevered free cash flow
A3: Investment-Grade Company Analysis Engine · v1.0
A4: Active scenario: | B4: ='Assumptions'!$G$6 | H4: All figures in USD millions unless stated.
A6: Forecast line item | B6: ="FY—0 (base)" | C6: Year +1 | D6: Year +2 | E6: Year +3 | F6: Year +4 | G6: Year +5 | H6: Driver / logic
A7: Revenue growth | B7: ='Historical'!$F$8 | C7: ='Assumptions'!$B$34+('Assumptions'!$B$35-'Assumptions'!$B$34)*0.000000 | D7: ='Assumptions'!$B$34+('Assumptions'!$B$35-'Assumptions'!$B$34)*0.250000 | E7: ='Assumptions'!$B$34+('Assumptions'!$B$35-'Assumptions'!$B$34)*0.500000 | F7: ='Assumptions'!$B$34+('Assumptions'!$B$35-'Assumptions'!$B$34)*0.750000 | G7: ='Assumptions'!$B$34+('Assumptions'!$B$35-'Assumptions'!$B$34)*1.000000 | H7: Linear fade from start growth to terminal growth.
A8: Revenue | B8: ='Inputs'!$F$33 | C8: ='Forecast'!$B$8*(1+'Forecast'!$C$7) | D8: ='Forecast'!$C$8*(1+'Forecast'!$D$7) | E8: ='Forecast'!$D$8*(1+'Forecast'!$E$7) | F8: ='Forecast'!$E$8*(1+'Forecast'!$F$7) | G8: ='Forecast'!$F$8*(1+'Forecast'!$G$7) | H8: Compounds off the last actual by the growth path.
A9: EBIT margin | B9: =IF(ISNUMBER('Historical'!$F$19),'Historical'!$F$19,'Assumptions'!$B$36) | C9: ='Forecast'!$B$9+('Assumptions'!$B$36-'Forecast'!$B$9)*0.200000 | D9: ='Forecast'!$B$9+('Assumptions'!$B$36-'Forecast'!$B$9)*0.400000 | E9: ='Forecast'!$B$9+('Assumptions'!$B$36-'Forecast'!$B$9)*0.600000 | F9: ='Forecast'!$B$9+('Assumptions'!$B$36-'Forecast'!$B$9)*0.800000 | G9: ='Forecast'!$B$9+('Assumptions'!$B$36-'Forecast'!$B$9)*1.000000 | H9: Linear fade from last-actual margin to terminal target.
A10: EBIT (operating profit) | B10: ='Inputs'!$F$39 | C10: ='Forecast'!$C$8*'Forecast'!$C$9 | D10: ='Forecast'!$D$8*'Forecast'!$D$9 | E10: ='Forecast'!$E$8*'Forecast'!$E$9 | F10: ='Forecast'!$F$8*'Forecast'!$F$9 | G10: ='Forecast'!$G$8*'Forecast'!$G$9 | H10: Revenue × EBIT margin.
A11: (+) Depreciation & amortisation | B11: ='Inputs'!$F$40 | C11: ='Forecast'!$C$8*'Assumptions'!$B$25 | D11: ='Forecast'!$D$8*'Assumptions'!$B$25 | E11: ='Forecast'!$E$8*'Assumptions'!$B$25 | F11: ='Forecast'!$F$8*'Assumptions'!$B$25 | G11: ='Forecast'!$G$8*'Assumptions'!$B$25 | H11: Revenue × D&A intensity (historical average).
A12: EBITDA | B12: ='Inputs'!$F$41 | C12: ='Forecast'!$C$10+'Forecast'!$C$11 | D12: ='Forecast'!$D$10+'Forecast'!$D$11 | E12: ='Forecast'!$E$10+'Forecast'!$E$11 | F12: ='Forecast'!$F$10+'Forecast'!$F$11 | G12: ='Forecast'!$G$10+'Forecast'!$G$11 | H12: EBIT + D&A.
A14: Unlevered Free Cash Flow
A15: EBIT (operating profit) | C15: ='Forecast'!$C$10 | D15: ='Forecast'!$D$10 | E15: ='Forecast'!$E$10 | F15: ='Forecast'!$F$10 | G15: ='Forecast'!$G$10
A16: (−) Cash tax on EBIT | C16: =-'Forecast'!$C$10*'Assumptions'!$B$28 | D16: =-'Forecast'!$D$10*'Assumptions'!$B$28 | E16: =-'Forecast'!$E$10*'Assumptions'!$B$28 | F16: =-'Forecast'!$F$10*'Assumptions'!$B$28 | G16: =-'Forecast'!$G$10*'Assumptions'!$B$28 | H16: EBIT × marginal tax rate (unlevered, so no interest tax shield here).
A17: NOPAT | C17: ='Forecast'!$C$10*(1-'Assumptions'!$B$28) | D17: ='Forecast'!$D$10*(1-'Assumptions'!$B$28) | E17: ='Forecast'!$E$10*(1-'Assumptions'!$B$28) | F17: ='Forecast'!$F$10*(1-'Assumptions'!$B$28) | G17: ='Forecast'!$G$10*(1-'Assumptions'!$B$28) | H17: Net operating profit after tax = EBIT × (1 − tax).
A18: (+) Depreciation & amortisation | C18: ='Forecast'!$C$11 | D18: ='Forecast'!$D$11 | E18: ='Forecast'!$E$11 | F18: ='Forecast'!$F$11 | G18: ='Forecast'!$G$11 | H18: Non-cash; added back.
A19: (−) Capital expenditure | C19: =-'Forecast'!$C$8*'Assumptions'!$B$26 | D19: =-'Forecast'!$D$8*'Assumptions'!$B$26 | E19: =-'Forecast'!$E$8*'Assumptions'!$B$26 | F19: =-'Forecast'!$F$8*'Assumptions'!$B$26 | G19: =-'Forecast'!$G$8*'Assumptions'!$B$26 | H19: Revenue × capex intensity (historical average).
A20: (−) Increase in net working capital | C20: =-'Assumptions'!$B$27*('Forecast'!$C$8-'Forecast'!$B$8) | D20: =-'Assumptions'!$B$27*('Forecast'!$D$8-'Forecast'!$C$8) | E20: =-'Assumptions'!$B$27*('Forecast'!$E$8-'Forecast'!$D$8) | F20: =-'Assumptions'!$B$27*('Forecast'!$F$8-'Forecast'!$E$8) | G20: =-'Assumptions'!$B$27*('Forecast'!$G$8-'Forecast'!$F$8) | H20: WC % × change in revenue; cash use when revenue grows.
A21: Unlevered free cash flow (FCFF) | C21: ='Forecast'!$C$17+'Forecast'!$C$18+'Forecast'!$C$19+'Forecast'!$C$20 | D21: ='Forecast'!$D$17+'Forecast'!$D$18+'Forecast'!$D$19+'Forecast'!$D$20 | E21: ='Forecast'!$E$17+'Forecast'!$E$18+'Forecast'!$E$19+'Forecast'!$E$20 | F21: ='Forecast'!$F$17+'Forecast'!$F$18+'Forecast'!$F$19+'Forecast'!$F$20 | G21: ='Forecast'!$G$17+'Forecast'!$G$18+'Forecast'!$G$19+'Forecast'!$G$20 | H21: NOPAT + D&A − Capex − ΔWC. Discounted on the DCF sheet.
A23: Forecast Method
A24: Revenue method: trend + mean-reversion (growth fades from FY—0 drivers to the long-run rate). If unit volume and price are entered on Inputs, a bottom-up volume × price override can be used instead. Operating costs, capex, D&A and working capital are tied to revenue, so the forecast is driver-based rather than a flat assumption.

Sheet DCF
A1: DCF VALUATION
A2: Discounted unlevered free cash flow — every step shown
A3: Investment-Grade Company Analysis Engine · v1.0
A4: Active scenario: | B4: ='Assumptions'!$G$6 | H4: All figures in USD millions unless stated.
A6: 1 · Present Value of Explicit Free Cash Flows
A7: Forecast year | B7: Year +1 | C7: Year +2 | D7: Year +3 | E7: Year +4 | F7: Year +5 | G7: Total
A8: Unlevered FCF (FCFF) | B8: ='Forecast'!$C$21 | C8: ='Forecast'!$D$21 | D8: ='Forecast'!$E$21 | E8: ='Forecast'!$F$21 | F8: ='Forecast'!$G$21
A9: Discount period (years) | B9: 1 | C9: 2 | D9: 3 | E9: 4 | F9: 5 | H9: End-of-year discounting convention.
A10: Discount factor = 1/(1+WACC)^t | B10: =1/(1+'WACC'!$B$24)^'DCF'!$B$9 | C10: =1/(1+'WACC'!$B$24)^'DCF'!$C$9 | D10: =1/(1+'WACC'!$B$24)^'DCF'!$D$9 | E10: =1/(1+'WACC'!$B$24)^'DCF'!$E$9 | F10: =1/(1+'WACC'!$B$24)^'DCF'!$F$9
A11: PV of FCFF | B11: ='Forecast'!$C$21*'DCF'!$B$10 | C11: ='Forecast'!$D$21*'DCF'!$C$10 | D11: ='Forecast'!$E$21*'DCF'!$D$10 | E11: ='Forecast'!$F$21*'DCF'!$E$10 | F11: ='Forecast'!$G$21*'DCF'!$F$10 | G11: =SUM($B$11:$F$11) | H11: Sum of discounted explicit-period cash flows.
A13: 2 · Terminal Value
A14: — Method A: Perpetuity growth (Gordon) —
A15: Terminal-year FCFF (year N) | B15: ='Forecast'!$G$21 | H15: Last explicit-year unlevered cash flow.
A16: Terminal growth (g) | B16: ='Assumptions'!$B$35 | H16: Perpetuity growth, from active assumptions.
A17: WACC | B17: ='WACC'!$B$24 | H17: From the WACC sheet.
A18: Terminal value at year N = FCFF×(1+g)/(WACC−g) | B18: =IFERROR('DCF'!$B$15*(1+'DCF'!$B$16)/('DCF'!$B$17-'DCF'!$B$16),"n/m") | H18: Gordon growth perpetuity, valued as of year N.
A19: PV of terminal value | B19: ='DCF'!$B$18*'DCF'!$F$10 | H19: Terminal value discounted to today.
A21: — Method B: Exit multiple (cross-check only) —
A22: Terminal-year EBITDA | B22: ='Forecast'!$G$12 | H22: Year-N EBITDA from the forecast.
A23: Exit EBITDA multiple | B23: ='Assumptions'!$B$29 | H23: Generic assumption; not used in the headline value.
A24: TV (exit multiple) at year N | B24: ='DCF'!$B$22*'DCF'!$B$23 | H24: Sanity check against the perpetuity TV.
A25: PV of TV (exit multiple) | B25: ='DCF'!$B$24*'DCF'!$F$10 | H25: For comparison with the perpetuity PV of TV.
A28: 3 · Enterprise Value → Equity Value → Per Share
A29: Σ PV of explicit FCFF | B29: ='DCF'!$G$11 | H29: From section 1.
A30: (+) PV of terminal value | B30: ='DCF'!$B$19 | H30: Perpetuity method (section 2A).
A31: Enterprise value (EV) | B31: ='DCF'!$B$29+'DCF'!$B$30 | H31: Value of the operating business to all capital providers.
A32: (−) Net debt | B32: =-'Historical'!$F$46 | H32: Total debt less cash & investments (latest balance sheet).
A33: (−) Minority interest | B33: =-'Inputs'!$F$72 | H33: Equity not attributable to shareholders.
A34: Equity value | B34: ='DCF'!$B$31+'DCF'!$B$32+'DCF'!$B$33 | H34: Intrinsic value attributable to shareholders.
A35: Shares outstanding | B35: =IF(ISNUMBER('Inputs'!$B$113),'Inputs'!$B$113,'Inputs'!$F$96) | H35: Current shares; falls back to diluted weighted-average.
A36: Implied value per share | B36: =IF(AND(ISNUMBER('DCF'!$B$34),ISNUMBER('DCF'!$B$35),'DCF'!$B$35<>0),'DCF'!$B$34/'DCF'!$B$35,"n/m") | H36: Headline DCF output.
A38: 4 · Cross-Checks & Valuation Read
A39: Current share price | B39: ='Inputs'!$B$112 | H39: Market reference input (blank if unknown).
A40: Upside / (downside) to DCF value | B40: =IFERROR('DCF'!$B$36/'DCF'!$B$39-1,"n/a") | H40: How far the price sits from intrinsic value.
A41: Valuation read | B41: =IF(NOT(AND(ISNUMBER('DCF'!$B$36),ISNUMBER('DCF'!$B$39),'DCF'!$B$39>0)),"n/a",IF('DCF'!$B$36>'DCF'!$B$39*(1+0.15),"Undervalued",IF('DCF'!$B$36<'DCF'!$B$39*(1-0.15),"Overvalued","Fairly valued"))) | H41: ±15% band around the price defines 'fairly valued'.
A43: Terminal value as % of EV | B43: =IF(AND(ISNUMBER('DCF'!$B$30),ISNUMBER('DCF'!$B$31),'DCF'!$B$31<>0),'DCF'!$B$30/'DCF'!$B$31,"n/m") | H43: =IF('DCF'!$B$43>0.8,"TV-heavy — scrutinise terminal assumptions","Reasonable split between explicit and terminal value")
A44: Implied exit multiple (from perpetuity TV) | B44: =IF(AND(ISNUMBER('DCF'!$B$18),ISNUMBER('DCF'!$B$22),'DCF'!$B$22<>0),'DCF'!$B$18/'DCF'!$B$22,"n/m") | H44: Cross-check: compare with the assumed exit multiple above.
A45: EV / next-year EBITDA | B45: =IF(AND(ISNUMBER('DCF'!$B$31),ISNUMBER('Forecast'!$C$12),'Forecast'!$C$12<>0),'DCF'!$B$31/'Forecast'!$C$12,"n/m") | H45: Forward valuation multiple implied by the DCF.

Sheet Sensitivity
A1: SENSITIVITY ANALYSIS
A2: Implied value per share across key assumptions
A3: Investment-Grade Company Analysis Engine · v1.0
A4: Each cell recomputes the full valuation for its row/column pair. Centre cell (boxed) = active base case.
A6: Table 1 · WACC (down) × Terminal growth g (across)
A7: Value / share | C7: ='Assumptions'!$B$35-0.01 | D7: ='Assumptions'!$B$35-0.005 | E7: ='Assumptions'!$B$35+0 | F7: ='Assumptions'!$B$35+0.005 | G7: ='Assumptions'!$B$35+0.01
B8: ='WACC'!$B$24-0.015 | C8: =IF($B$8-$C$7<=0.005,"n/m",IFERROR(((('Forecast'!$C$21/(1+$B$8)^1+'Forecast'!$D$21/(1+$B$8)^2+'Forecast'!$E$21/(1+$B$8)^3+'Forecast'!$F$21/(1+$B$8)^4+'Forecast'!$G$21/(1+$B$8)^5)+('Forecast'!$G$21*(1+$C$7)/($B$8-$C$7))/(1+$B$8)^5)-'Historical'!$F$46-'Inputs'!$F$72)/'DCF'!$B$35,"n/m")) | D8: =IF($B$8-$D$7<=0.005,"n/m",IFERROR(((('Forecast'!$C$21/(1+$B$8)^1+'Forecast'!$D$21/(1+$B$8)^2+'Forecast'!$E$21/(1+$B$8)^3+'Forecast'!$F$21/(1+$B$8)^4+'Forecast'!$G$21/(1+$B$8)^5)+('Forecast'!$G$21*(1+$D$7)/($B$8-$D$7))/(1+$B$8)^5)-'Historical'!$F$46-'Inputs'!$F$72)/'DCF'!$B$35,"n/m")) | E8: =IF($B$8-$E$7<=0.005,"n/m",IFERROR(((('Forecast'!$C$21/(1+$B$8)^1+'Forecast'!$D$21/(1+$B$8)^2+'Forecast'!$E$21/(1+$B$8)^3+'Forecast'!$F$21/(1+$B$8)^4+'Forecast'!$G$21/(1+$B$8)^5)+('Forecast'!$G$21*(1+$E$7)/($B$8-$E$7))/(1+$B$8)^5)-'Historical'!$F$46-'Inputs'!$F$72)/'DCF'!$B$35,"n/m")) | F8: =IF($B$8-$F$7<=0.005,"n/m",IFERROR(((('Forecast'!$C$21/(1+$B$8)^1+'Forecast'!$D$21/(1+$B$8)^2+'Forecast'!$E$21/(1+$B$8)^3+'Forecast'!$F$21/(1+$B$8)^4+'Forecast'!$G$21/(1+$B$8)^5)+('Forecast'!$G$21*(1+$F$7)/($B$8-$F$7))/(1+$B$8)^5)-'Historical'!$F$46-'Inputs'!$F$72)/'DCF'!$B$35,"n/m")) | G8: =IF($B$8-$G$7<=0.005,"n/m",IFERROR(((('Forecast'!$C$21/(1+$B$8)^1+'Forecast'!$D$21/(1+$B$8)^2+'Forecast'!$E$21/(1+$B$8)^3+'Forecast'!$F$21/(1+$B$8)^4+'Forecast'!$G$21/(1+$B$8)^5)+('Forecast'!$G$21*(1+$G$7)/($B$8-$G$7))/(1+$B$8)^5)-'Historical'!$F$46-'Inputs'!$F$72)/'DCF'!$B$35,"n/m"))
B9: ='WACC'!$B$24-0.0075 | C9: =IF($B$9-$C$7<=0.005,"n/m",IFERROR(((('Forecast'!$C$21/(1+$B$9)^1+'Forecast'!$D$21/(1+$B$9)^2+'Forecast'!$E$21/(1+$B$9)^3+'Forecast'!$F$21/(1+$B$9)^4+'Forecast'!$G$21/(1+$B$9)^5)+('Forecast'!$G$21*(1+$C$7)/($B$9-$C$7))/(1+$B$9)^5)-'Historical'!$F$46-'Inputs'!$F$72)/'DCF'!$B$35,"n/m")) | D9: =IF($B$9-$D$7<=0.005,"n/m",IFERROR(((('Forecast'!$C$21/(1+$B$9)^1+'Forecast'!$D$21/(1+$B$9)^2+'Forecast'!$E$21/(1+$B$9)^3+'Forecast'!$F$21/(1+$B$9)^4+'Forecast'!$G$21/(1+$B$9)^5)+('Forecast'!$G$21*(1+$D$7)/($B$9-$D$7))/(1+$B$9)^5)-'Historical'!$F$46-'Inputs'!$F$72)/'DCF'!$B$35,"n/m")) | E9: =IF($B$9-$E$7<=0.005,"n/m",IFERROR(((('Forecast'!$C$21/(1+$B$9)^1+'Forecast'!$D$21/(1+$B$9)^2+'Forecast'!$E$21/(1+$B$9)^3+'Forecast'!$F$21/(1+$B$9)^4+'Forecast'!$G$21/(1+$B$9)^5)+('Forecast'!$G$21*(1+$E$7)/($B$9-$E$7))/(1+$B$9)^5)-'Historical'!$F$46-'Inputs'!$F$72)/'DCF'!$B$35,"n/m")) | F9: =IF($B$9-$F$7<=0.005,"n/m",IFERROR(((('Forecast'!$C$21/(1+$B$9)^1+'Forecast'!$D$21/(1+$B$9)^2+'Forecast'!$E$21/(1+$B$9)^3+'Forecast'!$F$21/(1+$B$9)^4+'Forecast'!$G$21/(1+$B$9)^5)+('Forecast'!$G$21*(1+$F$7)/($B$9-$F$7))/(1+$B$9)^5)-'Historical'!$F$46-'Inputs'!$F$72)/'DCF'!$B$35,"n/m")) | G9: =IF($B$9-$G$7<=0.005,"n/m",IFERROR(((('Forecast'!$C$21/(1+$B$9)^1+'Forecast'!$D$21/(1+$B$9)^2+'Forecast'!$E$21/(1+$B$9)^3+'Forecast'!$F$21/(1+$B$9)^4+'Forecast'!$G$21/(1+$B$9)^5)+('Forecast'!$G$21*(1+$G$7)/($B$9-$G$7))/(1+$B$9)^5)-'Historical'!$F$46-'Inputs'!$F$72)/'DCF'!$B$35,"n/m"))
B10: ='WACC'!$B$24+0 | C10: =IF($B$10-$C$7<=0.005,"n/m",IFERROR(((('Forecast'!$C$21/(1+$B$10)^1+'Forecast'!$D$21/(1+$B$10)^2+'Forecast'!$E$21/(1+$B$10)^3+'Forecast'!$F$21/(1+$B$10)^4+'Forecast'!$G$21/(1+$B$10)^5)+('Forecast'!$G$21*(1+$C$7)/($B$10-$C$7))/(1+$B$10)^5)-'Historical'!$F$46-'Inputs'!$F$72)/'DCF'!$B$35,"n/m")) | D10: =IF($B$10-$D$7<=0.005,"n/m",IFERROR(((('Forecast'!$C$21/(1+$B$10)^1+'Forecast'!$D$21/(1+$B$10)^2+'Forecast'!$E$21/(1+$B$10)^3+'Forecast'!$F$21/(1+$B$10)^4+'Forecast'!$G$21/(1+$B$10)^5)+('Forecast'!$G$21*(1+$D$7)/($B$10-$D$7))/(1+$B$10)^5)-'Historical'!$F$46-'Inputs'!$F$72)/'DCF'!$B$35,"n/m")) | E10: =IF($B$10-$E$7<=0.005,"n/m",IFERROR(((('Forecast'!$C$21/(1+$B$10)^1+'Forecast'!$D$21/(1+$B$10)^2+'Forecast'!$E$21/(1+$B$10)^3+'Forecast'!$F$21/(1+$B$10)^4+'Forecast'!$G$21/(1+$B$10)^5)+('Forecast'!$G$21*(1+$E$7)/($B$10-$E$7))/(1+$B$10)^5)-'Historical'!$F$46-'Inputs'!$F$72)/'DCF'!$B$35,"n/m")) | F10: =IF($B$10-$F$7<=0.005,"n/m",IFERROR(((('Forecast'!$C$21/(1+$B$10)^1+'Forecast'!$D$21/(1+$B$10)^2+'Forecast'!$E$21/(1+$B$10)^3+'Forecast'!$F$21/(1+$B$10)^4+'Forecast'!$G$21/(1+$B$10)^5)+('Forecast'!$G$21*(1+$F$7)/($B$10-$F$7))/(1+$B$10)^5)-'Historical'!$F$46-'Inputs'!$F$72)/'DCF'!$B$35,"n/m")) | G10: =IF($B$10-$G$7<=0.005,"n/m",IFERROR(((('Forecast'!$C$21/(1+$B$10)^1+'Forecast'!$D$21/(1+$B$10)^2+'Forecast'!$E$21/(1+$B$10)^3+'Forecast'!$F$21/(1+$B$10)^4+'Forecast'!$G$21/(1+$B$10)^5)+('Forecast'!$G$21*(1+$G$7)/($B$10-$G$7))/(1+$B$10)^5)-'Historical'!$F$46-'Inputs'!$F$72)/'DCF'!$B$35,"n/m"))
B11: ='WACC'!$B$24+0.0075 | C11: =IF($B$11-$C$7<=0.005,"n/m",IFERROR(((('Forecast'!$C$21/(1+$B$11)^1+'Forecast'!$D$21/(1+$B$11)^2+'Forecast'!$E$21/(1+$B$11)^3+'Forecast'!$F$21/(1+$B$11)^4+'Forecast'!$G$21/(1+$B$11)^5)+('Forecast'!$G$21*(1+$C$7)/($B$11-$C$7))/(1+$B$11)^5)-'Historical'!$F$46-'Inputs'!$F$72)/'DCF'!$B$35,"n/m")) | D11: =IF($B$11-$D$7<=0.005,"n/m",IFERROR(((('Forecast'!$C$21/(1+$B$11)^1+'Forecast'!$D$21/(1+$B$11)^2+'Forecast'!$E$21/(1+$B$11)^3+'Forecast'!$F$21/(1+$B$11)^4+'Forecast'!$G$21/(1+$B$11)^5)+('Forecast'!$G$21*(1+$D$7)/($B$11-$D$7))/(1+$B$11)^5)-'Historical'!$F$46-'Inputs'!$F$72)/'DCF'!$B$35,"n/m")) | E11: =IF($B$11-$E$7<=0.005,"n/m",IFERROR(((('Forecast'!$C$21/(1+$B$11)^1+'Forecast'!$D$21/(1+$B$11)^2+'Forecast'!$E$21/(1+$B$11)^3+'Forecast'!$F$21/(1+$B$11)^4+'Forecast'!$G$21/(1+$B$11)^5)+('Forecast'!$G$21*(1+$E$7)/($B$11-$E$7))/(1+$B$11)^5)-'Historical'!$F$46-'Inputs'!$F$72)/'DCF'!$B$35,"n/m")) | F11: =IF($B$11-$F$7<=0.005,"n/m",IFERROR(((('Forecast'!$C$21/(1+$B$11)^1+'Forecast'!$D$21/(1+$B$11)^2+'Forecast'!$E$21/(1+$B$11)^3+'Forecast'!$F$21/(1+$B$11)^4+'Forecast'!$G$21/(1+$B$11)^5)+('Forecast'!$G$21*(1+$F$7)/($B$11-$F$7))/(1+$B$11)^5)-'Historical'!$F$46-'Inputs'!$F$72)/'DCF'!$B$35,"n/m")) | G11: =IF($B$11-$G$7<=0.005,"n/m",IFERROR(((('Forecast'!$C$21/(1+$B$11)^1+'Forecast'!$D$21/(1+$B$11)^2+'Forecast'!$E$21/(1+$B$11)^3+'Forecast'!$F$21/(1+$B$11)^4+'Forecast'!$G$21/(1+$B$11)^5)+('Forecast'!$G$21*(1+$G$7)/($B$11-$G$7))/(1+$B$11)^5)-'Historical'!$F$46-'Inputs'!$F$72)/'DCF'!$B$35,"n/m"))
B12: ='WACC'!$B$24+0.015 | C12: =IF($B$12-$C$7<=0.005,"n/m",IFERROR(((('Forecast'!$C$21/(1+$B$12)^1+'Forecast'!$D$21/(1+$B$12)^2+'Forecast'!$E$21/(1+$B$12)^3+'Forecast'!$F$21/(1+$B$12)^4+'Forecast'!$G$21/(1+$B$12)^5)+('Forecast'!$G$21*(1+$C$7)/($B$12-$C$7))/(1+$B$12)^5)-'Historical'!$F$46-'Inputs'!$F$72)/'DCF'!$B$35,"n/m")) | D12: =IF($B$12-$D$7<=0.005,"n/m",IFERROR(((('Forecast'!$C$21/(1+$B$12)^1+'Forecast'!$D$21/(1+$B$12)^2+'Forecast'!$E$21/(1+$B$12)^3+'Forecast'!$F$21/(1+$B$12)^4+'Forecast'!$G$21/(1+$B$12)^5)+('Forecast'!$G$21*(1+$D$7)/($B$12-$D$7))/(1+$B$12)^5)-'Historical'!$F$46-'Inputs'!$F$72)/'DCF'!$B$35,"n/m")) | E12: =IF($B$12-$E$7<=0.005,"n/m",IFERROR(((('Forecast'!$C$21/(1+$B$12)^1+'Forecast'!$D$21/(1+$B$12)^2+'Forecast'!$E$21/(1+$B$12)^3+'Forecast'!$F$21/(1+$B$12)^4+'Forecast'!$G$21/(1+$B$12)^5)+('Forecast'!$G$21*(1+$E$7)/($B$12-$E$7))/(1+$B$12)^5)-'Historical'!$F$46-'Inputs'!$F$72)/'DCF'!$B$35,"n/m")) | F12: =IF($B$12-$F$7<=0.005,"n/m",IFERROR(((('Forecast'!$C$21/(1+$B$12)^1+'Forecast'!$D$21/(1+$B$12)^2+'Forecast'!$E$21/(1+$B$12)^3+'Forecast'!$F$21/(1+$B$12)^4+'Forecast'!$G$21/(1+$B$12)^5)+('Forecast'!$G$21*(1+$F$7)/($B$12-$F$7))/(1+$B$12)^5)-'Historical'!$F$46-'Inputs'!$F$72)/'DCF'!$B$35,"n/m")) | G12: =IF($B$12-$G$7<=0.005,"n/m",IFERROR(((('Forecast'!$C$21/(1+$B$12)^1+'Forecast'!$D$21/(1+$B$12)^2+'Forecast'!$E$21/(1+$B$12)^3+'Forecast'!$F$21/(1+$B$12)^4+'Forecast'!$G$21/(1+$B$12)^5)+('Forecast'!$G$21*(1+$G$7)/($B$12-$G$7))/(1+$B$12)^5)-'Historical'!$F$46-'Inputs'!$F$72)/'DCF'!$B$35,"n/m"))
A15: Table 2 · WACC (down) × Exit EBITDA multiple (across)
A16: Value / share | C16: ='Assumptions'!$B$29-2 | D16: ='Assumptions'!$B$29-1 | E16: ='Assumptions'!$B$29+0 | F16: ='Assumptions'!$B$29+1 | G16: ='Assumptions'!$B$29+2
B17: ='WACC'!$B$24-0.015 | C17: =IFERROR(((('Forecast'!$C$21/(1+$B$17)^1+'Forecast'!$D$21/(1+$B$17)^2+'Forecast'!$E$21/(1+$B$17)^3+'Forecast'!$F$21/(1+$B$17)^4+'Forecast'!$G$21/(1+$B$17)^5)+('Forecast'!$G$12*$C$16)/(1+$B$17)^5)-'Historical'!$F$46-'Inputs'!$F$72)/'DCF'!$B$35,"n/m") | D17: =IFERROR(((('Forecast'!$C$21/(1+$B$17)^1+'Forecast'!$D$21/(1+$B$17)^2+'Forecast'!$E$21/(1+$B$17)^3+'Forecast'!$F$21/(1+$B$17)^4+'Forecast'!$G$21/(1+$B$17)^5)+('Forecast'!$G$12*$D$16)/(1+$B$17)^5)-'Historical'!$F$46-'Inputs'!$F$72)/'DCF'!$B$35,"n/m") | E17: =IFERROR(((('Forecast'!$C$21/(1+$B$17)^1+'Forecast'!$D$21/(1+$B$17)^2+'Forecast'!$E$21/(1+$B$17)^3+'Forecast'!$F$21/(1+$B$17)^4+'Forecast'!$G$21/(1+$B$17)^5)+('Forecast'!$G$12*$E$16)/(1+$B$17)^5)-'Historical'!$F$46-'Inputs'!$F$72)/'DCF'!$B$35,"n/m") | F17: =IFERROR(((('Forecast'!$C$21/(1+$B$17)^1+'Forecast'!$D$21/(1+$B$17)^2+'Forecast'!$E$21/(1+$B$17)^3+'Forecast'!$F$21/(1+$B$17)^4+'Forecast'!$G$21/(1+$B$17)^5)+('Forecast'!$G$12*$F$16)/(1+$B$17)^5)-'Historical'!$F$46-'Inputs'!$F$72)/'DCF'!$B$35,"n/m") | G17: =IFERROR(((('Forecast'!$C$21/(1+$B$17)^1+'Forecast'!$D$21/(1+$B$17)^2+'Forecast'!$E$21/(1+$B$17)^3+'Forecast'!$F$21/(1+$B$17)^4+'Forecast'!$G$21/(1+$B$17)^5)+('Forecast'!$G$12*$G$16)/(1+$B$17)^5)-'Historical'!$F$46-'Inputs'!$F$72)/'DCF'!$B$35,"n/m")
B18: ='WACC'!$B$24-0.0075 | C18: =IFERROR(((('Forecast'!$C$21/(1+$B$18)^1+'Forecast'!$D$21/(1+$B$18)^2+'Forecast'!$E$21/(1+$B$18)^3+'Forecast'!$F$21/(1+$B$18)^4+'Forecast'!$G$21/(1+$B$18)^5)+('Forecast'!$G$12*$C$16)/(1+$B$18)^5)-'Historical'!$F$46-'Inputs'!$F$72)/'DCF'!$B$35,"n/m") | D18: =IFERROR(((('Forecast'!$C$21/(1+$B$18)^1+'Forecast'!$D$21/(1+$B$18)^2+'Forecast'!$E$21/(1+$B$18)^3+'Forecast'!$F$21/(1+$B$18)^4+'Forecast'!$G$21/(1+$B$18)^5)+('Forecast'!$G$12*$D$16)/(1+$B$18)^5)-'Historical'!$F$46-'Inputs'!$F$72)/'DCF'!$B$35,"n/m") | E18: =IFERROR(((('Forecast'!$C$21/(1+$B$18)^1+'Forecast'!$D$21/(1+$B$18)^2+'Forecast'!$E$21/(1+$B$18)^3+'Forecast'!$F$21/(1+$B$18)^4+'Forecast'!$G$21/(1+$B$18)^5)+('Forecast'!$G$12*$E$16)/(1+$B$18)^5)-'Historical'!$F$46-'Inputs'!$F$72)/'DCF'!$B$35,"n/m") | F18: =IFERROR(((('Forecast'!$C$21/(1+$B$18)^1+'Forecast'!$D$21/(1+$B$18)^2+'Forecast'!$E$21/(1+$B$18)^3+'Forecast'!$F$21/(1+$B$18)^4+'Forecast'!$G$21/(1+$B$18)^5)+('Forecast'!$G$12*$F$16)/(1+$B$18)^5)-'Historical'!$F$46-'Inputs'!$F$72)/'DCF'!$B$35,"n/m") | G18: =IFERROR(((('Forecast'!$C$21/(1+$B$18)^1+'Forecast'!$D$21/(1+$B$18)^2+'Forecast'!$E$21/(1+$B$18)^3+'Forecast'!$F$21/(1+$B$18)^4+'Forecast'!$G$21/(1+$B$18)^5)+('Forecast'!$G$12*$G$16)/(1+$B$18)^5)-'Historical'!$F$46-'Inputs'!$F$72)/'DCF'!$B$35,"n/m")
B19: ='WACC'!$B$24+0 | C19: =IFERROR(((('Forecast'!$C$21/(1+$B$19)^1+'Forecast'!$D$21/(1+$B$19)^2+'Forecast'!$E$21/(1+$B$19)^3+'Forecast'!$F$21/(1+$B$19)^4+'Forecast'!$G$21/(1+$B$19)^5)+('Forecast'!$G$12*$C$16)/(1+$B$19)^5)-'Historical'!$F$46-'Inputs'!$F$72)/'DCF'!$B$35,"n/m") | D19: =IFERROR(((('Forecast'!$C$21/(1+$B$19)^1+'Forecast'!$D$21/(1+$B$19)^2+'Forecast'!$E$21/(1+$B$19)^3+'Forecast'!$F$21/(1+$B$19)^4+'Forecast'!$G$21/(1+$B$19)^5)+('Forecast'!$G$12*$D$16)/(1+$B$19)^5)-'Historical'!$F$46-'Inputs'!$F$72)/'DCF'!$B$35,"n/m") | E19: =IFERROR(((('Forecast'!$C$21/(1+$B$19)^1+'Forecast'!$D$21/(1+$B$19)^2+'Forecast'!$E$21/(1+$B$19)^3+'Forecast'!$F$21/(1+$B$19)^4+'Forecast'!$G$21/(1+$B$19)^5)+('Forecast'!$G$12*$E$16)/(1+$B$19)^5)-'Historical'!$F$46-'Inputs'!$F$72)/'DCF'!$B$35,"n/m") | F19: =IFERROR(((('Forecast'!$C$21/(1+$B$19)^1+'Forecast'!$D$21/(1+$B$19)^2+'Forecast'!$E$21/(1+$B$19)^3+'Forecast'!$F$21/(1+$B$19)^4+'Forecast'!$G$21/(1+$B$19)^5)+('Forecast'!$G$12*$F$16)/(1+$B$19)^5)-'Historical'!$F$46-'Inputs'!$F$72)/'DCF'!$B$35,"n/m") | G19: =IFERROR(((('Forecast'!$C$21/(1+$B$19)^1+'Forecast'!$D$21/(1+$B$19)^2+'Forecast'!$E$21/(1+$B$19)^3+'Forecast'!$F$21/(1+$B$19)^4+'Forecast'!$G$21/(1+$B$19)^5)+('Forecast'!$G$12*$G$16)/(1+$B$19)^5)-'Historical'!$F$46-'Inputs'!$F$72)/'DCF'!$B$35,"n/m")
B20: ='WACC'!$B$24+0.0075 | C20: =IFERROR(((('Forecast'!$C$21/(1+$B$20)^1+'Forecast'!$D$21/(1+$B$20)^2+'Forecast'!$E$21/(1+$B$20)^3+'Forecast'!$F$21/(1+$B$20)^4+'Forecast'!$G$21/(1+$B$20)^5)+('Forecast'!$G$12*$C$16)/(1+$B$20)^5)-'Historical'!$F$46-'Inputs'!$F$72)/'DCF'!$B$35,"n/m") | D20: =IFERROR(((('Forecast'!$C$21/(1+$B$20)^1+'Forecast'!$D$21/(1+$B$20)^2+'Forecast'!$E$21/(1+$B$20)^3+'Forecast'!$F$21/(1+$B$20)^4+'Forecast'!$G$21/(1+$B$20)^5)+('Forecast'!$G$12*$D$16)/(1+$B$20)^5)-'Historical'!$F$46-'Inputs'!$F$72)/'DCF'!$B$35,"n/m") | E20: =IFERROR(((('Forecast'!$C$21/(1+$B$20)^1+'Forecast'!$D$21/(1+$B$20)^2+'Forecast'!$E$21/(1+$B$20)^3+'Forecast'!$F$21/(1+$B$20)^4+'Forecast'!$G$21/(1+$B$20)^5)+('Forecast'!$G$12*$E$16)/(1+$B$20)^5)-'Historical'!$F$46-'Inputs'!$F$72)/'DCF'!$B$35,"n/m") | F20: =IFERROR(((('Forecast'!$C$21/(1+$B$20)^1+'Forecast'!$D$21/(1+$B$20)^2+'Forecast'!$E$21/(1+$B$20)^3+'Forecast'!$F$21/(1+$B$20)^4+'Forecast'!$G$21/(1+$B$20)^5)+('Forecast'!$G$12*$F$16)/(1+$B$20)^5)-'Historical'!$F$46-'Inputs'!$F$72)/'DCF'!$B$35,"n/m") | G20: =IFERROR(((('Forecast'!$C$21/(1+$B$20)^1+'Forecast'!$D$21/(1+$B$20)^2+'Forecast'!$E$21/(1+$B$20)^3+'Forecast'!$F$21/(1+$B$20)^4+'Forecast'!$G$21/(1+$B$20)^5)+('Forecast'!$G$12*$G$16)/(1+$B$20)^5)-'Historical'!$F$46-'Inputs'!$F$72)/'DCF'!$B$35,"n/m")
B21: ='WACC'!$B$24+0.015 | C21: =IFERROR(((('Forecast'!$C$21/(1+$B$21)^1+'Forecast'!$D$21/(1+$B$21)^2+'Forecast'!$E$21/(1+$B$21)^3+'Forecast'!$F$21/(1+$B$21)^4+'Forecast'!$G$21/(1+$B$21)^5)+('Forecast'!$G$12*$C$16)/(1+$B$21)^5)-'Historical'!$F$46-'Inputs'!$F$72)/'DCF'!$B$35,"n/m") | D21: =IFERROR(((('Forecast'!$C$21/(1+$B$21)^1+'Forecast'!$D$21/(1+$B$21)^2+'Forecast'!$E$21/(1+$B$21)^3+'Forecast'!$F$21/(1+$B$21)^4+'Forecast'!$G$21/(1+$B$21)^5)+('Forecast'!$G$12*$D$16)/(1+$B$21)^5)-'Historical'!$F$46-'Inputs'!$F$72)/'DCF'!$B$35,"n/m") | E21: =IFERROR(((('Forecast'!$C$21/(1+$B$21)^1+'Forecast'!$D$21/(1+$B$21)^2+'Forecast'!$E$21/(1+$B$21)^3+'Forecast'!$F$21/(1+$B$21)^4+'Forecast'!$G$21/(1+$B$21)^5)+('Forecast'!$G$12*$E$16)/(1+$B$21)^5)-'Historical'!$F$46-'Inputs'!$F$72)/'DCF'!$B$35,"n/m") | F21: =IFERROR(((('Forecast'!$C$21/(1+$B$21)^1+'Forecast'!$D$21/(1+$B$21)^2+'Forecast'!$E$21/(1+$B$21)^3+'Forecast'!$F$21/(1+$B$21)^4+'Forecast'!$G$21/(1+$B$21)^5)+('Forecast'!$G$12*$F$16)/(1+$B$21)^5)-'Historical'!$F$46-'Inputs'!$F$72)/'DCF'!$B$35,"n/m") | G21: =IFERROR(((('Forecast'!$C$21/(1+$B$21)^1+'Forecast'!$D$21/(1+$B$21)^2+'Forecast'!$E$21/(1+$B$21)^3+'Forecast'!$F$21/(1+$B$21)^4+'Forecast'!$G$21/(1+$B$21)^5)+('Forecast'!$G$12*$G$16)/(1+$B$21)^5)-'Historical'!$F$46-'Inputs'!$F$72)/'DCF'!$B$35,"n/m")
A23: Exit-multiple TV is a cross-check; the headline uses the perpetuity method.
A25: Table 3 · Start revenue growth (down) × Terminal EBIT margin (across)
A26: Value / share | C26: ='Assumptions'!$B$36-0.03 | D26: ='Assumptions'!$B$36-0.015 | E26: ='Assumptions'!$B$36+0 | F26: ='Assumptions'!$B$36+0.015 | G26: ='Assumptions'!$B$36+0.03
