Workbook
Name Fed_Weights: 'Settings'!$B$14:$B$20
Name Lib_Name: 'Impact Library'!$B$9:$B$29
Name Lib_Cat: 'Impact Library'!$G$9:$G$29
Name Lib_Interp_Higher: 'Impact Library'!$E$9:$E$29
Name Lib_Interp_Lower: 'Impact Library'!$F$9:$F$29
Name Lib_PolInfl: 'Impact Library'!$P$9:$P$29
Name Lib_PolGrow: 'Impact Library'!$Q$9:$Q$29
Name Lib_Importance: 'Impact Library'!$R$9:$R$29
Name Lib_Scale: 'Impact Library'!$S$9:$S$29
Name SUR_CAT: 'Surprise Engine'!$D$9:$D$48
Name SUR_INFLIMP: 'Surprise Engine'!$K$9:$K$48
Name SUR_GROWIMP: 'Surprise Engine'!$L$9:$L$48
Name Fed_SubScores: 'Fed Tracker'!$C$36:$C$42
Name Score_Fed: 'Fed Tracker'!$C$43
Name Fed_Bias_Label: 'Fed Tracker'!$C$44

Sheet Cover
A1: MACRO MARKET INTELLIGENCE SYSTEM
A2: Core engine (Phase 1-2) - read this first
A3: Macro Market Intelligence System - v0.9 (core)
A5: What this is
A6: This workbook helps you monitor the macro environment and translate it into market and portfolio implications. This is the CORE build: the input log and the first two scoring engines (data surprise and Fed bias). The market modules, scenario tools and executive dashboard follow in the next phase.
A7: You maintain just two sheets: the Data Tracker (releases) and the Fed Tracker (policy). Everything else calculates. Tune all weights and lists on the Settings sheet.
A10: Colour legend
A11: Input - you type here | C11: example
A12: Formula / derived | C12: example
A13: Linked from another sheet | C13: example
A14: Key output / score | C14: example
A16: How it flows (3 layers)
A17: INPUT -> Data Tracker, Fed Tracker, Settings (you maintain these)
A18: ENGINE -> Surprise Engine, Fed bias score (formulas score the inputs)
A19: OUTPUT -> signals and arrows you read, and - in the next phase - a one-page dashboard
A21: Contents (click to jump)
A22: Cover | C22: This page - guide, legend and contents.
A23: Settings | C23: Control panel: dropdown lists, Fed score weights, thresholds.
A24: Impact Library | C24: How each of 21 macro indicators usually moves markets.
A25: Data Tracker | C25: Log every release here (an input sheet).
A26: Surprise Engine | C26: Scores each release: surprise vs forecast -> signals -> asset arrows.
A27: Fed Tracker | C27: Fed policy state, speeches, and the hawkish/dovish score.
A29: Coming in the next build phase
A30: Executive Dashboard · USD Dashboard · Bond Module · Geopolitical Risk · Oil & Commodity · Cross-Asset Matrix · Scenario Engine · Regime Classifier · Portfolio Link · Market Note Generator · Watchlist · Executive Snapshot · Glossary
A32: How to update
A33: Daily/on release: add a row to the Data Tracker (pick the indicator from the dropdown), enter Actual / Forecast / Previous. The Surprise Engine scores it instantly.
A34: Weekly: update the Fed Tracker (speeches, implied path, yield moves) and re-read the Fed bias score.
A35: As needed: adjust weights, lists or indicator polarity on Settings / Impact Library.
A37: Disclaimer
A38: Intelligence and decision-support tool for monitoring macro and geopolitical risk. Its scores are transparent, weighted heuristics - a structured way to organise judgement, not a guaranteed predictor of market moves.

Sheet Settings
A1: SETTINGS & LISTS
A2: One control panel: every dropdown list, weight and threshold
A3: Macro Market Intelligence System - v0.9 (core)
A5: Cover | B5: Settings | C5: Impact Library | D5: Data Tracker | E5: Surprise Engine | F5: Fed Tracker
A8: What this sheet does
A9: Nothing analytical is hidden. Tune the model here: change a weight or a list and every sheet that uses it updates. The Fed weights below are the only numbers that change how the Fed bias score is calculated.
A12: Fed bias score - sub-score weights (must sum to 1.00)
A13: Sub-score | B13: Weight | C13: What it captures
A14: Inflation surprises | B14: 0.25 | C14: CPI / Core CPI / PCE surprises (from the Surprise Engine)
A15: Labor-market strength | B15: 0.2 | C15: payrolls / unemployment / wages / claims / JOLTS surprises
A16: Growth strength | B16: 0.15 | C16: GDP / ISM / PMI / retail growth surprises
A17: Fed-speech tone | B17: 0.15 | C17: your read of recent Fed speeches (-2..+2)
A18: Market-implied rate change | B18: 0.1 | C18: change in the market-implied policy path (bps)
A19: Yield-curve move (2Y) | B19: 0.1 | C19: 2Y Treasury yield move since the last meeting (bps)
A20: Real-yield move (10Y) | B20: 0.05 | C20: 10Y real-yield move (bps)
A21: Total | B21: =SUM(B14:B20) | C21: =IF(ABS(B21-1)<0.001,"OK - weights sum to 1.00","WARNING: weights must sum to 1.00")
A23: Fed bias bands (applied to the composite score)
A24: score >= +1.00 -> Hawkish · score >= +0.33 -> Mildly hawkish · score >= -0.33 -> Neutral · score >= -1.00 -> Mildly dovish · below -1.00 -> Dovish
A25: Surprise Engine z-score bands: |z| < 0.5 = Neutral · z >= 0.5 = Hot (above forecast) · z <= -0.5 = Cold (below forecast).
A27: Dropdown lists (reference)
A28: Country/Region | D28: Frequency | G28: Importance
A29: US | D29: Monthly | G29: 1
A30: Eurozone | D30: Weekly | G30: 2
A31: UK | D31: Quarterly | G31: 3
A32: Japan | D32: Daily | G32: 4
A33: China | D33: Ad hoc | G33: 5
A34: Global
A35: Kuwait | D35: Fed / CB bias | G35: Direction
A36: GCC | D36: Hawkish | G36: Up
A37: EM | D37: Mildly hawkish | G37: Flat
D38: Neutral | G38: Down
A39: Confidence | D39: Mildly dovish
A40: Low | D40: Dovish | G40: Decision
A41: Medium | G41: Hike
A42: High | D42: Dot-plot | G42: Hold
D43: More hikes | G43: Cut
A44: Speech tone (-2..+2) | D44: Fewer cuts
A45: -2 | D45: On hold
A46: -1 | D46: More cuts
A47: 0 | D47: Cutting
...

Sheet Impact Library
A1: INDICATOR IMPACT LIBRARY
A2: How each macro indicator usually affects markets (the reference the engines look up)
A3: Macro Market Intelligence System - v0.9 (core)
A5: Cover | B5: Settings | C5: Impact Library | D5: Data Tracker | E5: Surprise Engine | F5: Fed Tracker
A6: One row per indicator. The Surprise Engine and Fed Tracker look up the polarity, importance and scale columns from here. Edit the text and numbers to fit your own playbook.
B8: Indicator | C8: What it measures | D8: Why it matters | E8: Higher-than-expected read | F8: Lower-than-expected read | G8: Category | H8: Fed impact | I8: USD | J8: UST yld | K8: UST px | L8: Equities | M8: Gold | N8: Oil | O8: GCC | P8: Pol.Infl | Q8: Pol.Grow | R8: Imp | S8: Scale | T8: Exceptions / context
B9: CPI y/y | C9: consumer price inflation, headline | D9: the main inflation gauge; drives Fed expectations and real yields | E9: Hotter -> hawkish; supports USD & yields, pressures bonds, gold and equities | F9: Cooler -> dovish; supports bonds, gold and risk assets | G9: Inflation | H9: Higher -> fewer / later cuts | I9: ↑ | J9: ↑ | K9: ↓ | L9: ↓ | M9: ↓ | N9: ↔ | O9: ↔ (USD peg) | P9: 1 | Q9: 0 | R9: 5 | S9: 0.2 | T9: Watch core vs headline; energy and base effects can distort.
B10: Core CPI y/y | C10: CPI excluding food and energy | D10: cleaner inflation trend the Fed focuses on | E10: Sticky core -> hawkish; bond- and gold-negative | F10: Cooling core -> dovish; bond- and gold-positive | G10: Inflation | H10: Higher -> hawkish | I10: ↑ | J10: ↑ | K10: ↓ | L10: ↓ | M10: ↓ | N10: ↔ | O10: ↔ | P10: 1 | Q10: 0 | R10: 5 | S10: 0.2 | T10: Shelter lags; core services (ex-housing) is the stickiest part.
B11: PCE y/y | C11: personal consumption price index | D11: a broad inflation measure across a wide basket | E11: Hotter -> hawkish | F11: Cooler -> dovish | G11: Inflation | H11: Higher -> hawkish | I11: ↑ | J11: ↑ | K11: ↓ | L11: ↓ | M11: ↓ | N11: ↔ | O11: ↔ | P11: 1 | Q11: 0 | R11: 4 | S11: 0.2 | T11: Broader basket than CPI.
B12: Core PCE y/y | C12: PCE excluding food and energy | D12: the Fed's PREFERRED inflation gauge (2% target) | E12: Above target -> hawkish | F12: Toward target -> dovish | G12: Inflation | H12: Higher -> hawkish | I12: ↑ | J12: ↑ | K12: ↓ | L12: ↓ | M12: ↓ | N12: ↔ | O12: ↔ | P12: 1 | Q12: 0 | R12: 5 | S12: 0.2 | T12: This is the Fed's target metric.
B13: GDP q/q ann | C13: real output growth, annualized | D13: headline growth; expansion vs recession | E13: Strong -> risk-on, mildly hawkish (delays cuts) | F13: Weak -> recession fear, dovish | G13: Growth | H13: Higher -> mildly hawkish | I13: ↑ | J13: ↑ | K13: ↑* | L13: ↑ | M13: ↔ | N13: ↑ | O13: ↔ | P13: 0 | Q13: 1 | R13: 4 | S13: 0.5 | T13: Backward-looking; watch composition (inventories, net exports).
B14: Nonfarm payrolls | C14: net new jobs excluding farming | D14: the top labor print; jobs = income = demand | E14: Strong jobs -> hawkish; USD & yields up, bonds down | F14: Weak jobs -> dovish, but recession fear can hit equities | G14: Labor | H14: Higher -> hawkish | I14: ↑ | J14: ↑ | K14: ↓ | L14: Mixed | M14: ↓ | N14: ↑ | O14: ↔ | P14: 1 | Q14: 1 | R14: 5 | S14: 50 | T14: Revisions and the household survey can flip the read.
B15: Unemployment rate | C15: share of the labor force unemployed | D15: the Fed's employment mandate; a recession trigger (Sahm rule) | E15: Higher -> dovish, growth-negative | F15: Lower -> hawkish, tight labor | G15: Labor | H15: Higher -> dovish (cuts) | I15: ↓ | J15: ↓ | K15: ↑ | L15: Mixed | M15: ↑ | N15: ↓ | O15: ↔ | P15: -1 | Q15: -1 | R15: 4 | S15: 0.1 | T15: Participation swings distort it; read with payrolls.
B16: Avg hourly earnings y/y | C16: wage growth | D16: wages feed the services inflation the Fed fears most | E16: Hot wages -> hawkish | F16: Cooling wages -> dovish | G16: Labor | H16: Higher -> hawkish | I16: ↑ | J16: ↑ | K16: ↓ | L16: ↓ | M16: ↓ | N16: ↔ | O16: ↔ | P16: 1 | Q16: 1 | R16: 4 | S16: 0.2 | T16: Job-mix (composition) effects can mislead month to month.
B17: Initial jobless claims | C17: new unemployment filings (weekly) | D17: the most timely labor signal | E17: Rising claims -> dovish, labor weakening | F17: Falling claims -> hawkish, labor strong | G17: Labor | H17: Higher -> dovish | I17: ↓ | J17: ↓ | K17: ↑ | L17: Mixed | M17: ↑ | N17: ↓ | O17: ↔ | P17: -1 | Q17: -1 | R17: 3 | S17: 15 | T17: Noisy weekly; watch the 4-week moving average.
B18: JOLTS job openings | C18: unfilled job vacancies | D18: labor demand and tightness | E18: More openings -> hawkish (tight labor) | F18: Fewer -> dovish (loosening) | G18: Labor | H18: Higher -> hawkish | I18: ↑ | J18: ↑ | K18: ↓ | L18: Mixed | M18: ↓ | N18: ↔ | O18: ↔ | P18: 1 | Q18: 1 | R18: 3 | S18: 0.2 | T18: Reported with an extra month lag vs payrolls.
B19: ISM Manufacturing | C19: factory activity (>50 = expansion) | D19: a leading cyclical gauge | E19: Expansion -> risk-on, mildly hawkish | F19: Contraction -> growth fear, dovish | G19: Growth | H19: Higher -> mildly hawkish | I19: ↑ | J19: ↑ | K19: ↓ | L19: ↑ | M19: ↔ | N19: ↑ | O19: ↔ | P19: 1 | Q19: 1 | R19: 4 | S19: 1 | T19: The prices-paid sub-index is the inflation tell.
B20: ISM Services | C20: services activity (>50 = expansion) | D20: services are ~70% of the US economy | E20: Firm services -> hawkish, risk-on | F20: Soft -> dovish, growth fear | G20: Growth | H20: Higher -> hawkish | I20: ↑ | J20: ↑ | K20: ↓ | L20: ↑ | M20: ↔ | N20: ↑ | O20: ↔ | P20: 1 | Q20: 1 | R20: 4 | S20: 1 | T20: More important than manufacturing for the US cycle.
... B29: Global/China PMI | C29: ex-US global activity (e.g. China) | D29: global demand, commodities, EM and GCC | E29: Global expansion -> risk-on, oil+ | F29: Global slowdown -> risk-off, oil- | G29: Growth | H29: Indirect | I29: ↓ | J29: ↑ | K29: ↓ | L29: ↑ | M29: ↔ | N29: ↑ | O29: ↑ (oil demand) | P29: 0 | Q29: 1 | R29: 3 | S29: 1 | T29: China property and policy dominate the swings.

Sheet Data Tracker
A1: MACRO DATA TRACKER
A2: Log every release here - this and the Fed sheet are your inputs
A3: Macro Market Intelligence System - v0.9 (core)
A5: Cover | B5: Settings | C5: Impact Library | D5: Data Tracker | E5: Surprise Engine | F5: Fed Tracker
A6: Type releases in the yellow cells. Surprise, Hot/Cold and Importance fill in automatically. Pick the indicator from the dropdown so it matches the Impact Library. Blank rows are yours to fill.
B8: Date | C8: Country | D8: Indicator | E8: Actual | F8: Forecast | G8: Previous | H8: Unit | I8: Frequency | J8: Surprise | K8: Hot/Cold | L8: Imp | M8: Source | N8: Notes
J9: =IF($D9="","",$E9-$F9) | K9: =IF($D9="","",IF(ABS(IFERROR(($E9-$F9)/INDEX(Lib_Scale,MATCH($D9,Lib_Name,0)),0))<0.5,"Neutral",IF($E9>$F9,"Hot","Cold"))) | L9: =IF($D9="","",IFERROR(INDEX(Lib_Importance,MATCH($D9,Lib_Name,0)),""))
J10: =IF($D10="","",$E10-$F10) | K10: =IF($D10="","",IF(ABS(IFERROR(($E10-$F10)/INDEX(Lib_Scale,MATCH($D10,Lib_Name,0)),0))<0.5,"Neutral",IF($E10>$F10,"Hot","Cold"))) | L10: =IF($D10="","",IFERROR(INDEX(Lib_Importance,MATCH($D10,Lib_Name,0)),""))
J11: =IF($D11="","",$E11-$F11) | K11: =IF($D11="","",IF(ABS(IFERROR(($E11-$F11)/INDEX(Lib_Scale,MATCH($D11,Lib_Name,0)),0))<0.5,"Neutral",IF($E11>$F11,"Hot","Cold"))) | L11: =IF($D11="","",IFERROR(INDEX(Lib_Importance,MATCH($D11,Lib_Name,0)),""))
J12: =IF($D12="","",$E12-$F12) | K12: =IF($D12="","",IF(ABS(IFERROR(($E12-$F12)/INDEX(Lib_Scale,MATCH($D12,Lib_Name,0)),0))<0.5,"Neutral",IF($E12>$F12,"Hot","Cold"))) | L12: =IF($D12="","",IFERROR(INDEX(Lib_Importance,MATCH($D12,Lib_Name,0)),""))
J13: =IF($D13="","",$E13-$F13) | K13: =IF($D13="","",IF(ABS(IFERROR(($E13-$F13)/INDEX(Lib_Scale,MATCH($D13,Lib_Name,0)),0))<0.5,"Neutral",IF($E13>$F13,"Hot","Cold"))) | L13: =IF($D13="","",IFERROR(INDEX(Lib_Importance,MATCH($D13,Lib_Name,0)),""))
J14: =IF($D14="","",$E14-$F14) | K14: =IF($D14="","",IF(ABS(IFERROR(($E14-$F14)/INDEX(Lib_Scale,MATCH($D14,Lib_Name,0)),0))<0.5,"Neutral",IF($E14>$F14,"Hot","Cold"))) | L14: =IF($D14="","",IFERROR(INDEX(Lib_Importance,MATCH($D14,Lib_Name,0)),""))
J15: =IF($D15="","",$E15-$F15) | K15: =IF($D15="","",IF(ABS(IFERROR(($E15-$F15)/INDEX(Lib_Scale,MATCH($D15,Lib_Name,0)),0))<0.5,"Neutral",IF($E15>$F15,"Hot","Cold"))) | L15: =IF($D15="","",IFERROR(INDEX(Lib_Importance,MATCH($D15,Lib_Name,0)),""))
J16: =IF($D16="","",$E16-$F16) | K16: =IF($D16="","",IF(ABS(IFERROR(($E16-$F16)/INDEX(Lib_Scale,MATCH($D16,Lib_Name,0)),0))<0.5,"Neutral",IF($E16>$F16,"Hot","Cold"))) | L16: =IF($D16="","",IFERROR(INDEX(Lib_Importance,MATCH($D16,Lib_Name,0)),""))
J17: =IF($D17="","",$E17-$F17) | K17: =IF($D17="","",IF(ABS(IFERROR(($E17-$F17)/INDEX(Lib_Scale,MATCH($D17,Lib_Name,0)),0))<0.5,"Neutral",IF($E17>$F17,"Hot","Cold"))) | L17: =IF($D17="","",IFERROR(INDEX(Lib_Importance,MATCH($D17,Lib_Name,0)),""))
J18: =IF($D18="","",$E18-$F18) | K18: =IF($D18="","",IF(ABS(IFERROR(($E18-$F18)/INDEX(Lib_Scale,MATCH($D18,Lib_Name,0)),0))<0.5,"Neutral",IF($E18>$F18,"Hot","Cold"))) | L18: =IF($D18="","",IFERROR(INDEX(Lib_Importance,MATCH($D18,Lib_Name,0)),""))
J19: =IF($D19="","",$E19-$F19) | K19: =IF($D19="","",IF(ABS(IFERROR(($E19-$F19)/INDEX(Lib_Scale,MATCH($D19,Lib_Name,0)),0))<0.5,"Neutral",IF($E19>$F19,"Hot","Cold"))) | L19: =IF($D19="","",IFERROR(INDEX(Lib_Importance,MATCH($D19,Lib_Name,0)),""))
J20: =IF($D20="","",$E20-$F20) | K20: =IF($D20="","",IF(ABS(IFERROR(($E20-$F20)/INDEX(Lib_Scale,MATCH($D20,Lib_Name,0)),0))<0.5,"Neutral",IF($E20>$F20,"Hot","Cold"))) | L20: =IF($D20="","",IFERROR(INDEX(Lib_Importance,MATCH($D20,Lib_Name,0)),""))
... J48: =IF($D48="","",$E48-$F48) | K48: =IF($D48="","",IF(ABS(IFERROR(($E48-$F48)/INDEX(Lib_Scale,MATCH($D48,Lib_Name,0)),0))<0.5,"Neutral",IF($E48>$F48,"Hot","Cold"))) | L48: =IF($D48="","",IFERROR(INDEX(Lib_Importance,MATCH($D48,Lib_Name,0)),""))

Sheet Surprise Engine
A1: DATA SURPRISE ENGINE
A2: Markets trade the surprise vs forecast - this scores it into signals and asset impacts
A3: Macro Market Intelligence System - v0.9 (core)
A5: Cover | B5: Settings | C5: Impact Library | D5: Data Tracker | E5: Surprise Engine | F5: Fed Tracker
A6: Everything here is calculated from the Data Tracker (same rows). z = surprise / typical surprise. Infl.imp = z x inflation-polarity x importance (this is the hawkish impulse that feeds the Fed score). Arrows are the usual first-order reaction, not a prediction.
B8: Date | C8: Indicator | D8: Category | E8: Actual | F8: Fcst | G8: Prev | H8: Surprise | I8: z | J8: Hot/Cold | K8: Infl.imp | L8: Grow.imp | M8: Inflation | N8: Growth | O8: USD | P8: UST yld | Q8: UST px | R8: Gold | S8: Oil | T8: S&P | U8: EM | V8: GCC | W8: Risk tone | X8: Conf
B9: =IF('Data Tracker'!$D9="","",'Data Tracker'!$B9) | C9: =IF('Data Tracker'!$D9="","",'Data Tracker'!$D9) | D9: =IF($Z9="","",IFERROR(INDEX(Lib_Cat,$Z9),"")) | E9: =IF('Data Tracker'!$D9="","",'Data Tracker'!$E9) | F9: =IF('Data Tracker'!$D9="","",'Data Tracker'!$F9) | G9: =IF('Data Tracker'!$D9="","",'Data Tracker'!$G9) | H9: =IF($E9="","",$E9-$F9) | I9: =IF($E9="","",IFERROR($H9/INDEX(Lib_Scale,$Z9),0)) | J9: =IF($E9="","",IF(ABS($I9)<0.5,"Neutral",IF($I9>0,"Hot","Cold"))) | K9: =IF($E9="","",$I9*INDEX(Lib_PolInfl,$Z9)*INDEX(Lib_Importance,$Z9)/5) | L9: =IF($E9="","",$I9*INDEX(Lib_PolGrow,$Z9)*INDEX(Lib_Importance,$Z9)/5) | M9: =IF($E9="","",IF($K9>0.5,"Inflationary",IF($K9<-0.5,"Disinflationary","Neutral"))) | N9: =IF($E9="","",IF($L9>0.5,"Growth+",IF($L9<-0.5,"Growth-","Neutral"))) | O9: =IF($E9="","",IF(0.6*$K9+0.4*$L9>=1.5,"⇈",IF(0.6*$K9+0.4*$L9>=0.5,"↑",IF(0.6*$K9+0.4*$L9>-0.5,"↔",IF(0.6*$K9+0.4*$L9>-1.5,"↓","⇊"))))) | P9: =IF($E9="","",IF(0.7*$K9+0.3*$L9>=1.5,"⇈",IF(0.7*$K9+0.3*$L9>=0.5,"↑",IF(0.7*$K9+0.3*$L9>-0.5,"↔",IF(0.7*$K9+0.3*$L9>-1.5,"↓","⇊"))))) | Q9: =IF($E9="","",IF(-(0.7*$K9+0.3*$L9)>=1.5,"⇈",IF(-(0.7*$K9+0.3*$L9)>=0.5,"↑",IF(-(0.7*$K9+0.3*$L9)>-0.5,"↔",IF(-(0.7*$K9+0.3*$L9)>-1.5,"↓","⇊"))))) | R9: =IF($E9="","",IF(-0.8*$K9>=1.5,"⇈",IF(-0.8*$K9>=0.5,"↑",IF(-0.8*$K9>-0.5,"↔",IF(-0.8*$K9>-1.5,"↓","⇊"))))) | S9: =IF($E9="","",IF(0.5*$L9>=1.5,"⇈",IF(0.5*$L9>=0.5,"↑",IF(0.5*$L9>-0.5,"↔",IF(0.5*$L9>-1.5,"↓","⇊"))))) | T9: =IF($E9="","",IF(0.5*$L9-0.5*$K9>=1.5,"⇈",IF(0.5*$L9-0.5*$K9>=0.5,"↑",IF(0.5*$L9-0.5*$K9>-0.5,"↔",IF(0.5*$L9-0.5*$K9>-1.5,"↓","⇊"))))) | U9: =IF($E9="","",IF(0.4*$L9-0.6*$K9>=1.5,"⇈",IF(0.4*$L9-0.6*$K9>=0.5,"↑",IF(0.4*$L9-0.6*$K9>-0.5,"↔",IF(0.4*$L9-0.6*$K9>-1.5,"↓","⇊"))))) | V9: =IF($E9="","",IF(0.5*$L9>=1.5,"⇈",IF(0.5*$L9>=0.5,"↑",IF(0.5*$L9>-0.5,"↔",IF(0.5*$L9>-1.5,"↓","⇊"))))) | W9: =IF($E9="","",IF(AND($L9>=0.5,$K9<=0.5),"Risk-on",IF(OR($L9<=-0.5,$K9>=1),"Risk-off","Neutral"))) | X9: =IF($E9="","",IF(AND(IFERROR(INDEX(Lib_Importance,$Z9),0)>=4,ABS($I9)>=1),"High",IF(ABS($I9)<0.5,"Low","Medium"))) | Z9: =IF('Data Tracker'!$D9="","",IFERROR(MATCH('Data Tracker'!$D9,Lib_Name,0),""))
B10: =IF('Data Tracker'!$D10="","",'Data Tracker'!$B10) | C10: =IF('Data Tracker'!$D10="","",'Data Tracker'!$D10) | D10: =IF($Z10="","",IFERROR(INDEX(Lib_Cat,$Z10),"")) | E10: =IF('Data Tracker'!$D10="","",'Data Tracker'!$E10) | F10: =IF('Data Tracker'!$D10="","",'Data Tracker'!$F10) | G10: =IF('Data Tracker'!$D10="","",'Data Tracker'!$G10) | H10: =IF($E10="","",$E10-$F10) | I10: =IF($E10="","",IFERROR($H10/INDEX(Lib_Scale,$Z10),0)) | J10: =IF($E10="","",IF(ABS($I10)<0.5,"Neutral",IF($I10>0,"Hot","Cold"))) | K10: =IF($E10="","",$I10*INDEX(Lib_PolInfl,$Z10)*INDEX(Lib_Importance,$Z10)/5) | L10: =IF($E10="","",$I10*INDEX(Lib_PolGrow,$Z10)*INDEX(Lib_Importance,$Z10)/5) | M10: =IF($E10="","",IF($K10>0.5,"Inflationary",IF($K10<-0.5,"Disinflationary","Neutral"))) | N10: =IF($E10="","",IF($L10>0.5,"Growth+",IF($L10<-0.5,"Growth-","Neutral"))) | O10: =IF($E10="","",IF(0.6*$K10+0.4*$L10>=1.5,"⇈",IF(0.6*$K10+0.4*$L10>=0.5,"↑",IF(0.6*$K10+0.4*$L10>-0.5,"↔",IF(0.6*$K10+0.4*$L10>-1.5,"↓","⇊"))))) | P10: =IF($E10="","",IF(0.7*$K10+0.3*$L10>=1.5,"⇈",IF(0.7*$K10+0.3*$L10>=0.5,"↑",IF(0.7*$K10+0.3*$L10>-0.5,"↔",IF(0.7*$K10+0.3*$L10>-1.5,"↓","⇊"))))) | Q10: =IF($E10="","",IF(-(0.7*$K10+0.3*$L10)>=1.5,"⇈",IF(-(0.7*$K10+0.3*$L10)>=0.5,"↑",IF(-(0.7*$K10+0.3*$L10)>-0.5,"↔",IF(-(0.7*$K10+0.3*$L10)>-1.5,"↓","⇊"))))) | R10: =IF($E10="","",IF(-0.8*$K10>=1.5,"⇈",IF(-0.8*$K10>=0.5,"↑",IF(-0.8*$K10>-0.5,"↔",IF(-0.8*$K10>-1.5,"↓","⇊"))))) | S10: =IF($E10="","",IF(0.5*$L10>=1.5,"⇈",IF(0.5*$L10>=0.5,"↑",IF(0.5*$L10>-0.5,"↔",IF(0.5*$L10>-1.5,"↓","⇊"))))) | T10: =IF($E10="","",IF(0.5*$L10-0.5*$K10>=1.5,"⇈",IF(0.5*$L10-0.5*$K10>=0.5,"↑",IF(0.5*$L10-0.5*$K10>-0.5,"↔",IF(0.5*$L10-0.5*$K10>-1.5,"↓","⇊"))))) | U10: =IF($E10="","",IF(0.4*$L10-0.6*$K10>=1.5,"⇈",IF(0.4*$L10-0.6*$K10>=0.5,"↑",IF(0.4*$L10-0.6*$K10>-0.5,"↔",IF(0.4*$L10-0.6*$K10>-1.5,"↓","⇊"))))) | V10: =IF($E10="","",IF(0.5*$L10>=1.5,"⇈",IF(0.5*$L10>=0.5,"↑",IF(0.5*$L10>-0.5,"↔",IF(0.5*$L10>-1.5,"↓","⇊"))))) | W10: =IF($E10="","",IF(AND($L10>=0.5,$K10<=0.5),"Risk-on",IF(OR($L10<=-0.5,$K10>=1),"Risk-off","Neutral"))) | X10: =IF($E10="","",IF(AND(IFERROR(INDEX(Lib_Importance,$Z10),0)>=4,ABS($I10)>=1),"High",IF(ABS($I10)<0.5,"Low","Medium"))) | Z10: =IF('Data Tracker'!$D10="","",IFERROR(MATCH('Data Tracker'!$D10,Lib_Name,0),""))
B11: =IF('Data Tracker'!$D11="","",'Data Tracker'!$B11) | C11: =IF('Data Tracker'!$D11="","",'Data Tracker'!$D11) | D11: =IF($Z11="","",IFERROR(INDEX(Lib_Cat,$Z11),"")) | E11: =IF('Data Tracker'!$D11="","",'Data Tracker'!$E11) | F11: =IF('Data Tracker'!$D11="","",'Data Tracker'!$F11) | G11: =IF('Data Tracker'!$D11="","",'Data Tracker'!$G11) | H11: =IF($E11="","",$E11-$F11) | I11: =IF($E11="","",IFERROR($H11/INDEX(Lib_Scale,$Z11),0)) | J11: =IF($E11="","",IF(ABS($I11)<0.5,"Neutral",IF($I11>0,"Hot","Cold"))) | K11: =IF($E11="","",$I11*INDEX(Lib_PolInfl,$Z11)*INDEX(Lib_Importance,$Z11)/5) | L11: =IF($E11="","",$I11*INDEX(Lib_PolGrow,$Z11)*INDEX(Lib_Importance,$Z11)/5) | M11: =IF($E11="","",IF($K11>0.5,"Inflationary",IF($K11<-0.5,"Disinflationary","Neutral"))) | N11: =IF($E11="","",IF($L11>0.5,"Growth+",IF($L11<-0.5,"Growth-","Neutral"))) | O11: =IF($E11="","",IF(0.6*$K11+0.4*$L11>=1.5,"⇈",IF(0.6*$K11+0.4*$L11>=0.5,"↑",IF(0.6*$K11+0.4*$L11>-0.5,"↔",IF(0.6*$K11+0.4*$L11>-1.5,"↓","⇊"))))) | P11: =IF($E11="","",IF(0.7*$K11+0.3*$L11>=1.5,"⇈",IF(0.7*$K11+0.3*$L11>=0.5,"↑",IF(0.7*$K11+0.3*$L11>-0.5,"↔",IF(0.7*$K11+0.3*$L11>-1.5,"↓","⇊"))))) | Q11: =IF($E11="","",IF(-(0.7*$K11+0.3*$L11)>=1.5,"⇈",IF(-(0.7*$K11+0.3*$L11)>=0.5,"↑",IF(-(0.7*$K11+0.3*$L11)>-0.5,"↔",IF(-(0.7*$K11+0.3*$L11)>-1.5,"↓","⇊"))))) | R11: =IF($E11="","",IF(-0.8*$K11>=1.5,"⇈",IF(-0.8*$K11>=0.5,"↑",IF(-0.8*$K11>-0.5,"↔",IF(-0.8*$K11>-1.5,"↓","⇊"))))) | S11: =IF($E11="","",IF(0.5*$L11>=1.5,"⇈",IF(0.5*$L11>=0.5,"↑",IF(0.5*$L11>-0.5,"↔",IF(0.5*$L11>-1.5,"↓","⇊"))))) | T11: =IF($E11="","",IF(0.5*$L11-0.5*$K11>=1.5,"⇈",IF(0.5*$L11-0.5*$K11>=0.5,"↑",IF(0.5*$L11-0.5*$K11>-0.5,"↔",IF(0.5*$L11-0.5*$K11>-1.5,"↓","⇊"))))) | U11: =IF($E11="","",IF(0.4*$L11-0.6*$K11>=1.5,"⇈",IF(0.4*$L11-0.6*$K11>=0.5,"↑",IF(0.4*$L11-0.6*$K11>-0.5,"↔",IF(0.4*$L11-0.6*$K11>-1.5,"↓","⇊"))))) | V11: =IF($E11="","",IF(0.5*$L11>=1.5,"⇈",IF(0.5*$L11>=0.5,"↑",IF(0.5*$L11>-0.5,"↔",IF(0.5*$L11>-1.5,"↓","⇊"))))) | W11: =IF($E11="","",IF(AND($L11>=0.5,$K11<=0.5),"Risk-on",IF(OR($L11<=-0.5,$K11>=1),"Risk-off","Neutral"))) | X11: =IF($E11="","",IF(AND(IFERROR(INDEX(Lib_Importance,$Z11),0)>=4,ABS($I11)>=1),"High",IF(ABS($I11)<0.5,"Low","Medium"))) | Z11: =IF('Data Tracker'!$D11="","",IFERROR(MATCH('Data Tracker'!$D11,Lib_Name,0),""))
B12: =IF('Data Tracker'!$D12="","",'Data Tracker'!$B12) | C12: =IF('Data Tracker'!$D12="","",'Data Tracker'!$D12) | D12: =IF($Z12="","",IFERROR(INDEX(Lib_Cat,$Z12),"")) | E12: =IF('Data Tracker'!$D12="","",'Data Tracker'!$E12) | F12: =IF('Data Tracker'!$D12="","",'Data Tracker'!$F12) | G12: =IF('Data Tracker'!$D12="","",'Data Tracker'!$G12) | H12: =IF($E12="","",$E12-$F12) | I12: =IF($E12="","",IFERROR($H12/INDEX(Lib_Scale,$Z12),0)) | J12: =IF($E12="","",IF(ABS($I12)<0.5,"Neutral",IF($I12>0,"Hot","Cold"))) | K12: =IF($E12="","",$I12*INDEX(Lib_PolInfl,$Z12)*INDEX(Lib_Importance,$Z12)/5) | L12: =IF($E12="","",$I12*INDEX(Lib_PolGrow,$Z12)*INDEX(Lib_Importance,$Z12)/5) | M12: =IF($E12="","",IF($K12>0.5,"Inflationary",IF($K12<-0.5,"Disinflationary","Neutral"))) | N12: =IF($E12="","",IF($L12>0.5,"Growth+",IF($L12<-0.5,"Growth-","Neutral"))) | O12: =IF($E12="","",IF(0.6*$K12+0.4*$L12>=1.5,"⇈",IF(0.6*$K12+0.4*$L12>=0.5,"↑",IF(0.6*$K12+0.4*$L12>-0.5,"↔",IF(0.6*$K12+0.4*$L12>-1.5,"↓","⇊"))))) | P12: =IF($E12="","",IF(0.7*$K12+0.3*$L12>=1.5,"⇈",IF(0.7*$K12+0.3*$L12>=0.5,"↑",IF(0.7*$K12+0.3*$L12>-0.5,"↔",IF(0.7*$K12+0.3*$L12>-1.5,"↓","⇊"))))) | Q12: =IF($E12="","",IF(-(0.7*$K12+0.3*$L12)>=1.5,"⇈",IF(-(0.7*$K12+0.3*$L12)>=0.5,"↑",IF(-(0.7*$K12+0.3*$L12)>-0.5,"↔",IF(-(0.7*$K12+0.3*$L12)>-1.5,"↓","⇊"))))) | R12: =IF($E12="","",IF(-0.8*$K12>=1.5,"⇈",IF(-0.8*$K12>=0.5,"↑",IF(-0.8*$K12>-0.5,"↔",IF(-0.8*$K12>-1.5,"↓","⇊"))))) | S12: =IF($E12="","",IF(0.5*$L12>=1.5,"⇈",IF(0.5*$L12>=0.5,"↑",IF(0.5*$L12>-0.5,"↔",IF(0.5*$L12>-1.5,"↓","⇊"))))) | T12: =IF($E12="","",IF(0.5*$L12-0.5*$K12>=1.5,"⇈",IF(0.5*$L12-0.5*$K12>=0.5,"↑",IF(0.5*$L12-0.5*$K12>-0.5,"↔",IF(0.5*$L12-0.5*$K12>-1.5,"↓","⇊"))))) | U12: =IF($E12="","",IF(0.4*$L12-0.6*$K12>=1.5,"⇈",IF(0.4*$L12-0.6*$K12>=0.5,"↑",IF(0.4*$L12-0.6*$K12>-0.5,"↔",IF(0.4*$L12-0.6*$K12>-1.5,"↓","⇊"))))) | V12: =IF($E12="","",IF(0.5*$L12>=1.5,"⇈",IF(0.5*$L12>=0.5,"↑",IF(0.5*$L12>-0.5,"↔",IF(0.5*$L12>-1.5,"↓","⇊"))))) | W12: =IF($E12="","",IF(AND($L12>=0.5,$K12<=0.5),"Risk-on",IF(OR($L12<=-0.5,$K12>=1),"Risk-off","Neutral"))) | X12: =IF($E12="","",IF(AND(IFERROR(INDEX(Lib_Importance,$Z12),0)>=4,ABS($I12)>=1),"High",IF(ABS($I12)<0.5,"Low","Medium"))) | Z12: =IF('Data Tracker'!$D12="","",IFERROR(MATCH('Data Tracker'!$D12,Lib_Name,0),""))
B13: =IF('Data Tracker'!$D13="","",'Data Tracker'!$B13) | C13: =IF('Data Tracker'!$D13="","",'Data Tracker'!$D13) | D13: =IF($Z13="","",IFERROR(INDEX(Lib_Cat,$Z13),"")) | E13: =IF('Data Tracker'!$D13="","",'Data Tracker'!$E13) | F13: =IF('Data Tracker'!$D13="","",'Data Tracker'!$F13) | G13: =IF('Data Tracker'!$D13="","",'Data Tracker'!$G13) | H13: =IF($E13="","",$E13-$F13) | I13: =IF($E13="","",IFERROR($H13/INDEX(Lib_Scale,$Z13),0)) | J13: =IF($E13="","",IF(ABS($I13)<0.5,"Neutral",IF($I13>0,"Hot","Cold"))) | K13: =IF($E13="","",$I13*INDEX(Lib_PolInfl,$Z13)*INDEX(Lib_Importance,$Z13)/5) | L13: =IF($E13="","",$I13*INDEX(Lib_PolGrow,$Z13)*INDEX(Lib_Importance,$Z13)/5) | M13: =IF($E13="","",IF($K13>0.5,"Inflationary",IF($K13<-0.5,"Disinflationary","Neutral"))) | N13: =IF($E13="","",IF($L13>0.5,"Growth+",IF($L13<-0.5,"Growth-","Neutral"))) | O13: =IF($E13="","",IF(0.6*$K13+0.4*$L13>=1.5,"⇈",IF(0.6*$K13+0.4*$L13>=0.5,"↑",IF(0.6*$K13+0.4*$L13>-0.5,"↔",IF(0.6*$K13+0.4*$L13>-1.5,"↓","⇊"))))) | P13: =IF($E13="","",IF(0.7*$K13+0.3*$L13>=1.5,"⇈",IF(0.7*$K13+0.3*$L13>=0.5,"↑",IF(0.7*$K13+0.3*$L13>-0.5,"↔",IF(0.7*$K13+0.3*$L13>-1.5,"↓","⇊"))))) | Q13: =IF($E13="","",IF(-(0.7*$K13+0.3*$L13)>=1.5,"⇈",IF(-(0.7*$K13+0.3*$L13)>=0.5,"↑",IF(-(0.7*$K13+0.3*$L13)>-0.5,"↔",IF(-(0.7*$K13+0.3*$L13)>-1.5,"↓","⇊"))))) | R13: =IF($E13="","",IF(-0.8*$K13>=1.5,"⇈",IF(-0.8*$K13>=0.5,"↑",IF(-0.8*$K13>-0.5,"↔",IF(-0.8*$K13>-1.5,"↓","⇊"))))) | S13: =IF($E13="","",IF(0.5*$L13>=1.5,"⇈",IF(0.5*$L13>=0.5,"↑",IF(0.5*$L13>-0.5,"↔",IF(0.5*$L13>-1.5,"↓","⇊"))))) | T13: =IF($E13="","",IF(0.5*$L13-0.5*$K13>=1.5,"⇈",IF(0.5*$L13-0.5*$K13>=0.5,"↑",IF(0.5*$L13-0.5*$K13>-0.5,"↔",IF(0.5*$L13-0.5*$K13>-1.5,"↓","⇊"))))) | U13: =IF($E13="","",IF(0.4*$L13-0.6*$K13>=1.5,"⇈",IF(0.4*$L13-0.6*$K13>=0.5,"↑",IF(0.4*$L13-0.6*$K13>-0.5,"↔",IF(0.4*$L13-0.6*$K13>-1.5,"↓","⇊"))))) | V13: =IF($E13="","",IF(0.5*$L13>=1.5,"⇈",IF(0.5*$L13>=0.5,"↑",IF(0.5*$L13>-0.5,"↔",IF(0.5*$L13>-1.5,"↓","⇊"))))) | W13: =IF($E13="","",IF(AND($L13>=0.5,$K13<=0.5),"Risk-on",IF(OR($L13<=-0.5,$K13>=1),"Risk-off","Neutral"))) | X13: =IF($E13="","",IF(AND(IFERROR(INDEX(Lib_Importance,$Z13),0)>=4,ABS($I13)>=1),"High",IF(ABS($I13)<0.5,"Low","Medium"))) | Z13: =IF('Data Tracker'!$D13="","",IFERROR(MATCH('Data Tracker'!$D13,Lib_Name,0),""))
B14: =IF('Data Tracker'!$D14="","",'Data Tracker'!$B14) | C14: =IF('Data Tracker'!$D14="","",'Data Tracker'!$D14) | D14: =IF($Z14="","",IFERROR(INDEX(Lib_Cat,$Z14),"")) | E14: =IF('Data Tracker'!$D14="","",'Data Tracker'!$E14) | F14: =IF('Data Tracker'!$D14="","",'Data Tracker'!$F14) | G14: =IF('Data Tracker'!$D14="","",'Data Tracker'!$G14) | H14: =IF($E14="","",$E14-$F14) | I14: =IF($E14="","",IFERROR($H14/INDEX(Lib_Scale,$Z14),0)) | J14: =IF($E14="","",IF(ABS($I14)<0.5,"Neutral",IF($I14>0,"Hot","Cold"))) | K14: =IF($E14="","",$I14*INDEX(Lib_PolInfl,$Z14)*INDEX(Lib_Importance,$Z14)/5) | L14: =IF($E14="","",$I14*INDEX(Lib_PolGrow,$Z14)*INDEX(Lib_Importance,$Z14)/5) | M14: =IF($E14="","",IF($K14>0.5,"Inflationary",IF($K14<-0.5,"Disinflationary","Neutral"))) | N14: =IF($E14="","",IF($L14>0.5,"Growth+",IF($L14<-0.5,"Growth-","Neutral"))) | O14: =IF($E14="","",IF(0.6*$K14+0.4*$L14>=1.5,"⇈",IF(0.6*$K14+0.4*$L14>=0.5,"↑",IF(0.6*$K14+0.4*$L14>-0.5,"↔",IF(0.6*$K14+0.4*$L14>-1.5,"↓","⇊"))))) | P14: =IF($E14="","",IF(0.7*$K14+0.3*$L14>=1.5,"⇈",IF(0.7*$K14+0.3*$L14>=0.5,"↑",IF(0.7*$K14+0.3*$L14>-0.5,"↔",IF(0.7*$K14+0.3*$L14>-1.5,"↓","⇊"))))) | Q14: =IF($E14="","",IF(-(0.7*$K14+0.3*$L14)>=1.5,"⇈",IF(-(0.7*$K14+0.3*$L14)>=0.5,"↑",IF(-(0.7*$K14+0.3*$L14)>-0.5,"↔",IF(-(0.7*$K14+0.3*$L14)>-1.5,"↓","⇊"))))) | R14: =IF($E14="","",IF(-0.8*$K14>=1.5,"⇈",IF(-0.8*$K14>=0.5,"↑",IF(-0.8*$K14>-0.5,"↔",IF(-0.8*$K14>-1.5,"↓","⇊"))))) | S14: =IF($E14="","",IF(0.5*$L14>=1.5,"⇈",IF(0.5*$L14>=0.5,"↑",IF(0.5*$L14>-0.5,"↔",IF(0.5*$L14>-1.5,"↓","⇊"))))) | T14: =IF($E14="","",IF(0.5*$L14-0.5*$K14>=1.5,"⇈",IF(0.5*$L14-0.5*$K14>=0.5,"↑",IF(0.5*$L14-0.5*$K14>-0.5,"↔",IF(0.5*$L14-0.5*$K14>-1.5,"↓","⇊"))))) | U14: =IF($E14="","",IF(0.4*$L14-0.6*$K14>=1.5,"⇈",IF(0.4*$L14-0.6*$K14>=0.5,"↑",IF(0.4*$L14-0.6*$K14>-0.5,"↔",IF(0.4*$L14-0.6*$K14>-1.5,"↓","⇊"))))) | V14: =IF($E14="","",IF(0.5*$L14>=1.5,"⇈",IF(0.5*$L14>=0.5,"↑",IF(0.5*$L14>-0.5,"↔",IF(0.5*$L14>-1.5,"↓","⇊"))))) | W14: =IF($E14="","",IF(AND($L14>=0.5,$K14<=0.5),"Risk-on",IF(OR($L14<=-0.5,$K14>=1),"Risk-off","Neutral"))) | X14: =IF($E14="","",IF(AND(IFERROR(INDEX(Lib_Importance,$Z14),0)>=4,ABS($I14)>=1),"High",IF(ABS($I14)<0.5,"Low","Medium"))) | Z14: =IF('Data Tracker'!$D14="","",IFERROR(MATCH('Data Tracker'!$D14,Lib_Name,0),""))
B15: =IF('Data Tracker'!$D15="","",'Data Tracker'!$B15) | C15: =IF('Data Tracker'!$D15="","",'Data Tracker'!$D15) | D15: =IF($Z15="","",IFERROR(INDEX(Lib_Cat,$Z15),"")) | E15: =IF('Data Tracker'!$D15="","",'Data Tracker'!$E15) | F15: =IF('Data Tracker'!$D15="","",'Data Tracker'!$F15) | G15: =IF('Data Tracker'!$D15="","",'Data Tracker'!$G15) | H15: =IF($E15="","",$E15-$F15) | I15: =IF($E15="","",IFERROR($H15/INDEX(Lib_Scale,$Z15),0)) | J15: =IF($E15="","",IF(ABS($I15)<0.5,"Neutral",IF($I15>0,"Hot","Cold"))) | K15: =IF($E15="","",$I15*INDEX(Lib_PolInfl,$Z15)*INDEX(Lib_Importance,$Z15)/5) | L15: =IF($E15="","",$I15*INDEX(Lib_PolGrow,$Z15)*INDEX(Lib_Importance,$Z15)/5) | M15: =IF($E15="","",IF($K15>0.5,"Inflationary",IF($K15<-0.5,"Disinflationary","Neutral"))) | N15: =IF($E15="","",IF($L15>0.5,"Growth+",IF($L15<-0.5,"Growth-","Neutral"))) | O15: =IF($E15="","",IF(0.6*$K15+0.4*$L15>=1.5,"⇈",IF(0.6*$K15+0.4*$L15>=0.5,"↑",IF(0.6*$K15+0.4*$L15>-0.5,"↔",IF(0.6*$K15+0.4*$L15>-1.5,"↓","⇊"))))) | P15: =IF($E15="","",IF(0.7*$K15+0.3*$L15>=1.5,"⇈",IF(0.7*$K15+0.3*$L15>=0.5,"↑",IF(0.7*$K15+0.3*$L15>-0.5,"↔",IF(0.7*$K15+0.3*$L15>-1.5,"↓","⇊"))))) | Q15: =IF($E15="","",IF(-(0.7*$K15+0.3*$L15)>=1.5,"⇈",IF(-(0.7*$K15+0.3*$L15)>=0.5,"↑",IF(-(0.7*$K15+0.3*$L15)>-0.5,"↔",IF(-(0.7*$K15+0.3*$L15)>-1.5,"↓","⇊"))))) | R15: =IF($E15="","",IF(-0.8*$K15>=1.5,"⇈",IF(-0.8*$K15>=0.5,"↑",IF(-0.8*$K15>-0.5,"↔",IF(-0.8*$K15>-1.5,"↓","⇊"))))) | S15: =IF($E15="","",IF(0.5*$L15>=1.5,"⇈",IF(0.5*$L15>=0.5,"↑",IF(0.5*$L15>-0.5,"↔",IF(0.5*$L15>-1.5,"↓","⇊"))))) | T15: =IF($E15="","",IF(0.5*$L15-0.5*$K15>=1.5,"⇈",IF(0.5*$L15-0.5*$K15>=0.5,"↑",IF(0.5*$L15-0.5*$K15>-0.5,"↔",IF(0.5*$L15-0.5*$K15>-1.5,"↓","⇊"))))) | U15: =IF($E15="","",IF(0.4*$L15-0.6*$K15>=1.5,"⇈",IF(0.4*$L15-0.6*$K15>=0.5,"↑",IF(0.4*$L15-0.6*$K15>-0.5,"↔",IF(0.4*$L15-0.6*$K15>-1.5,"↓","⇊"))))) | V15: =IF($E15="","",IF(0.5*$L15>=1.5,"⇈",IF(0.5*$L15>=0.5,"↑",IF(0.5*$L15>-0.5,"↔",IF(0.5*$L15>-1.5,"↓","⇊"))))) | W15: =IF($E15="","",IF(AND($L15>=0.5,$K15<=0.5),"Risk-on",IF(OR($L15<=-0.5,$K15>=1),"Risk-off","Neutral"))) | X15: =IF($E15="","",IF(AND(IFERROR(INDEX(Lib_Importance,$Z15),0)>=4,ABS($I15)>=1),"High",IF(ABS($I15)<0.5,"Low","Medium"))) | Z15: =IF('Data Tracker'!$D15="","",IFERROR(MATCH('Data Tracker'!$D15,Lib_Name,0),""))
B16: =IF('Data Tracker'!$D16="","",'Data Tracker'!$B16) | C16: =IF('Data Tracker'!$D16="","",'Data Tracker'!$D16) | D16: =IF($Z16="","",IFERROR(INDEX(Lib_Cat,$Z16),"")) | E16: =IF('Data Tracker'!$D16="","",'Data Tracker'!$E16) | F16: =IF('Data Tracker'!$D16="","",'Data Tracker'!$F16) | G16: =IF('Data Tracker'!$D16="","",'Data Tracker'!$G16) | H16: =IF($E16="","",$E16-$F16) | I16: =IF($E16="","",IFERROR($H16/INDEX(Lib_Scale,$Z16),0)) | J16: =IF($E16="","",IF(ABS($I16)<0.5,"Neutral",IF($I16>0,"Hot","Cold"))) | K16: =IF($E16="","",$I16*INDEX(Lib_PolInfl,$Z16)*INDEX(Lib_Importance,$Z16)/5) | L16: =IF($E16="","",$I16*INDEX(Lib_PolGrow,$Z16)*INDEX(Lib_Importance,$Z16)/5) | M16: =IF($E16="","",IF($K16>0.5,"Inflationary",IF($K16<-0.5,"Disinflationary","Neutral"))) | N16: =IF($E16="","",IF($L16>0.5,"Growth+",IF($L16<-0.5,"Growth-","Neutral"))) | O16: =IF($E16="","",IF(0.6*$K16+0.4*$L16>=1.5,"⇈",IF(0.6*$K16+0.4*$L16>=0.5,"↑",IF(0.6*$K16+0.4*$L16>-0.5,"↔",IF(0.6*$K16+0.4*$L16>-1.5,"↓","⇊"))))) | P16: =IF($E16="","",IF(0.7*$K16+0.3*$L16>=1.5,"⇈",IF(0.7*$K16+0.3*$L16>=0.5,"↑",IF(0.7*$K16+0.3*$L16>-0.5,"↔",IF(0.7*$K16+0.3*$L16>-1.5,"↓","⇊"))))) | Q16: =IF($E16="","",IF(-(0.7*$K16+0.3*$L16)>=1.5,"⇈",IF(-(0.7*$K16+0.3*$L16)>=0.5,"↑",IF(-(0.7*$K16+0.3*$L16)>-0.5,"↔",IF(-(0.7*$K16+0.3*$L16)>-1.5,"↓","⇊"))))) | R16: =IF($E16="","",IF(-0.8*$K16>=1.5,"⇈",IF(-0.8*$K16>=0.5,"↑",IF(-0.8*$K16>-0.5,"↔",IF(-0.8*$K16>-1.5,"↓","⇊"))))) | S16: =IF($E16="","",IF(0.5*$L16>=1.5,"⇈",IF(0.5*$L16>=0.5,"↑",IF(0.5*$L16>-0.5,"↔",IF(0.5*$L16>-1.5,"↓","⇊"))))) | T16: =IF($E16="","",IF(0.5*$L16-0.5*$K16>=1.5,"⇈",IF(0.5*$L16-0.5*$K16>=0.5,"↑",IF(0.5*$L16-0.5*$K16>-0.5,"↔",IF(0.5*$L16-0.5*$K16>-1.5,"↓","⇊"))))) | U16: =IF($E16="","",IF(0.4*$L16-0.6*$K16>=1.5,"⇈",IF(0.4*$L16-0.6*$K16>=0.5,"↑",IF(0.4*$L16-0.6*$K16>-0.5,"↔",IF(0.4*$L16-0.6*$K16>-1.5,"↓","⇊"))))) | V16: =IF($E16="","",IF(0.5*$L16>=1.5,"⇈",IF(0.5*$L16>=0.5,"↑",IF(0.5*$L16>-0.5,"↔",IF(0.5*$L16>-1.5,"↓","⇊"))))) | W16: =IF($E16="","",IF(AND($L16>=0.5,$K16<=0.5),"Risk-on",IF(OR($L16<=-0.5,$K16>=1),"Risk-off","Neutral"))) | X16: =IF($E16="","",IF(AND(IFERROR(INDEX(Lib_Importance,$Z16),0)>=4,ABS($I16)>=1),"High",IF(ABS($I16)<0.5,"Low","Medium"))) | Z16: =IF('Data Tracker'!$D16="","",IFERROR(MATCH('Data Tracker'!$D16,Lib_Name,0),""))
B17: =IF('Data Tracker'!$D17="","",'Data Tracker'!$B17) | C17: =IF('Data Tracker'!$D17="","",'Data Tracker'!$D17) | D17: =IF($Z17="","",IFERROR(INDEX(Lib_Cat,$Z17),"")) | E17: =IF('Data Tracker'!$D17="","",'Data Tracker'!$E17) | F17: =IF('Data Tracker'!$D17="","",'Data Tracker'!$F17) | G17: =IF('Data Tracker'!$D17="","",'Data Tracker'!$G17) | H17: =IF($E17="","",$E17-$F17) | I17: =IF($E17="","",IFERROR($H17/INDEX(Lib_Scale,$Z17),0)) | J17: =IF($E17="","",IF(ABS($I17)<0.5,"Neutral",IF($I17>0,"Hot","Cold"))) | K17: =IF($E17="","",$I17*INDEX(Lib_PolInfl,$Z17)*INDEX(Lib_Importance,$Z17)/5) | L17: =IF($E17="","",$I17*INDEX(Lib_PolGrow,$Z17)*INDEX(Lib_Importance,$Z17)/5) | M17: =IF($E17="","",IF($K17>0.5,"Inflationary",IF($K17<-0.5,"Disinflationary","Neutral"))) | N17: =IF($E17="","",IF($L17>0.5,"Growth+",IF($L17<-0.5,"Growth-","Neutral"))) | O17: =IF($E17="","",IF(0.6*$K17+0.4*$L17>=1.5,"⇈",IF(0.6*$K17+0.4*$L17>=0.5,"↑",IF(0.6*$K17+0.4*$L17>-0.5,"↔",IF(0.6*$K17+0.4*$L17>-1.5,"↓","⇊"))))) | P17: =IF($E17="","",IF(0.7*$K17+0.3*$L17>=1.5,"⇈",IF(0.7*$K17+0.3*$L17>=0.5,"↑",IF(0.7*$K17+0.3*$L17>-0.5,"↔",IF(0.7*$K17+0.3*$L17>-1.5,"↓","⇊"))))) | Q17: =IF($E17="","",IF(-(0.7*$K17+0.3*$L17)>=1.5,"⇈",IF(-(0.7*$K17+0.3*$L17)>=0.5,"↑",IF(-(0.7*$K17+0.3*$L17)>-0.5,"↔",IF(-(0.7*$K17+0.3*$L17)>-1.5,"↓","⇊"))))) | R17: =IF($E17="","",IF(-0.8*$K17>=1.5,"⇈",IF(-0.8*$K17>=0.5,"↑",IF(-0.8*$K17>-0.5,"↔",IF(-0.8*$K17>-1.5,"↓","⇊"))))) | S17: =IF($E17="","",IF(0.5*$L17>=1.5,"⇈",IF(0.5*$L17>=0.5,"↑",IF(0.5*$L17>-0.5,"↔",IF(0.5*$L17>-1.5,"↓","⇊"))))) | T17: =IF($E17="","",IF(0.5*$L17-0.5*$K17>=1.5,"⇈",IF(0.5*$L17-0.5*$K17>=0.5,"↑",IF(0.5*$L17-0.5*$K17>-0.5,"↔",IF(0.5*$L17-0.5*$K17>-1.5,"↓","⇊"))))) | U17: =IF($E17="","",IF(0.4*$L17-0.6*$K17>=1.5,"⇈",IF(0.4*$L17-0.6*$K17>=0.5,"↑",IF(0.4*$L17-0.6*$K17>-0.5,"↔",IF(0.4*$L17-0.6*$K17>-1.5,"↓","⇊"))))) | V17: =IF($E17="","",IF(0.5*$L17>=1.5,"⇈",IF(0.5*$L17>=0.5,"↑",IF(0.5*$L17>-0.5,"↔",IF(0.5*$L17>-1.5,"↓","⇊"))))) | W17: =IF($E17="","",IF(AND($L17>=0.5,$K17<=0.5),"Risk-on",IF(OR($L17<=-0.5,$K17>=1),"Risk-off","Neutral"))) | X17: =IF($E17="","",IF(AND(IFERROR(INDEX(Lib_Importance,$Z17),0)>=4,ABS($I17)>=1),"High",IF(ABS($I17)<0.5,"Low","Medium"))) | Z17: =IF('Data Tracker'!$D17="","",IFERROR(MATCH('Data Tracker'!$D17,Lib_Name,0),""))
B18: =IF('Data Tracker'!$D18="","",'Data Tracker'!$B18) | C18: =IF('Data Tracker'!$D18="","",'Data Tracker'!$D18) | D18: =IF($Z18="","",IFERROR(INDEX(Lib_Cat,$Z18),"")) | E18: =IF('Data Tracker'!$D18="","",'Data Tracker'!$E18) | F18: =IF('Data Tracker'!$D18="","",'Data Tracker'!$F18) | G18: =IF('Data Tracker'!$D18="","",'Data Tracker'!$G18) | H18: =IF($E18="","",$E18-$F18) | I18: =IF($E18="","",IFERROR($H18/INDEX(Lib_Scale,$Z18),0)) | J18: =IF($E18="","",IF(ABS($I18)<0.5,"Neutral",IF($I18>0,"Hot","Cold"))) | K18: =IF($E18="","",$I18*INDEX(Lib_PolInfl,$Z18)*INDEX(Lib_Importance,$Z18)/5) | L18: =IF($E18="","",$I18*INDEX(Lib_PolGrow,$Z18)*INDEX(Lib_Importance,$Z18)/5) | M18: =IF($E18="","",IF($K18>0.5,"Inflationary",IF($K18<-0.5,"Disinflationary","Neutral"))) | N18: =IF($E18="","",IF($L18>0.5,"Growth+",IF($L18<-0.5,"Growth-","Neutral"))) | O18: =IF($E18="","",IF(0.6*$K18+0.4*$L18>=1.5,"⇈",IF(0.6*$K18+0.4*$L18>=0.5,"↑",IF(0.6*$K18+0.4*$L18>-0.5,"↔",IF(0.6*$K18+0.4*$L18>-1.5,"↓","⇊"))))) | P18: =IF($E18="","",IF(0.7*$K18+0.3*$L18>=1.5,"⇈",IF(0.7*$K18+0.3*$L18>=0.5,"↑",IF(0.7*$K18+0.3*$L18>-0.5,"↔",IF(0.7*$K18+0.3*$L18>-1.5,"↓","⇊"))))) | Q18: =IF($E18="","",IF(-(0.7*$K18+0.3*$L18)>=1.5,"⇈",IF(-(0.7*$K18+0.3*$L18)>=0.5,"↑",IF(-(0.7*$K18+0.3*$L18)>-0.5,"↔",IF(-(0.7*$K18+0.3*$L18)>-1.5,"↓","⇊"))))) | R18: =IF($E18="","",IF(-0.8*$K18>=1.5,"⇈",IF(-0.8*$K18>=0.5,"↑",IF(-0.8*$K18>-0.5,"↔",IF(-0.8*$K18>-1.5,"↓","⇊"))))) | S18: =IF($E18="","",IF(0.5*$L18>=1.5,"⇈",IF(0.5*$L18>=0.5,"↑",IF(0.5*$L18>-0.5,"↔",IF(0.5*$L18>-1.5,"↓","⇊"))))) | T18: =IF($E18="","",IF(0.5*$L18-0.5*$K18>=1.5,"⇈",IF(0.5*$L18-0.5*$K18>=0.5,"↑",IF(0.5*$L18-0.5*$K18>-0.5,"↔",IF(0.5*$L18-0.5*$K18>-1.5,"↓","⇊"))))) | U18: =IF($E18="","",IF(0.4*$L18-0.6*$K18>=1.5,"⇈",IF(0.4*$L18-0.6*$K18>=0.5,"↑",IF(0.4*$L18-0.6*$K18>-0.5,"↔",IF(0.4*$L18-0.6*$K18>-1.5,"↓","⇊"))))) | V18: =IF($E18="","",IF(0.5*$L18>=1.5,"⇈",IF(0.5*$L18>=0.5,"↑",IF(0.5*$L18>-0.5,"↔",IF(0.5*$L18>-1.5,"↓","⇊"))))) | W18: =IF($E18="","",IF(AND($L18>=0.5,$K18<=0.5),"Risk-on",IF(OR($L18<=-0.5,$K18>=1),"Risk-off","Neutral"))) | X18: =IF($E18="","",IF(AND(IFERROR(INDEX(Lib_Importance,$Z18),0)>=4,ABS($I18)>=1),"High",IF(ABS($I18)<0.5,"Low","Medium"))) | Z18: =IF('Data Tracker'!$D18="","",IFERROR(MATCH('Data Tracker'!$D18,Lib_Name,0),""))
B19: =IF('Data Tracker'!$D19="","",'Data Tracker'!$B19) | C19: =IF('Data Tracker'!$D19="","",'Data Tracker'!$D19) | D19: =IF($Z19="","",IFERROR(INDEX(Lib_Cat,$Z19),"")) | E19: =IF('Data Tracker'!$D19="","",'Data Tracker'!$E19) | F19: =IF('Data Tracker'!$D19="","",'Data Tracker'!$F19) | G19: =IF('Data Tracker'!$D19="","",'Data Tracker'!$G19) | H19: =IF($E19="","",$E19-$F19) | I19: =IF($E19="","",IFERROR($H19/INDEX(Lib_Scale,$Z19),0)) | J19: =IF($E19="","",IF(ABS($I19)<0.5,"Neutral",IF($I19>0,"Hot","Cold"))) | K19: =IF($E19="","",$I19*INDEX(Lib_PolInfl,$Z19)*INDEX(Lib_Importance,$Z19)/5) | L19: =IF($E19="","",$I19*INDEX(Lib_PolGrow,$Z19)*INDEX(Lib_Importance,$Z19)/5) | M19: =IF($E19="","",IF($K19>0.5,"Inflationary",IF($K19<-0.5,"Disinflationary","Neutral"))) | N19: =IF($E19="","",IF($L19>0.5,"Growth+",IF($L19<-0.5,"Growth-","Neutral"))) | O19: =IF($E19="","",IF(0.6*$K19+0.4*$L19>=1.5,"⇈",IF(0.6*$K19+0.4*$L19>=0.5,"↑",IF(0.6*$K19+0.4*$L19>-0.5,"↔",IF(0.6*$K19+0.4*$L19>-1.5,"↓","⇊"))))) | P19: =IF($E19="","",IF(0.7*$K19+0.3*$L19>=1.5,"⇈",IF(0.7*$K19+0.3*$L19>=0.5,"↑",IF(0.7*$K19+0.3*$L19>-0.5,"↔",IF(0.7*$K19+0.3*$L19>-1.5,"↓","⇊"))))) | Q19: =IF($E19="","",IF(-(0.7*$K19+0.3*$L19)>=1.5,"⇈",IF(-(0.7*$K19+0.3*$L19)>=0.5,"↑",IF(-(0.7*$K19+0.3*$L19)>-0.5,"↔",IF(-(0.7*$K19+0.3*$L19)>-1.5,"↓","⇊"))))) | R19: =IF($E19="","",IF(-0.8*$K19>=1.5,"⇈",IF(-0.8*$K19>=0.5,"↑",IF(-0.8*$K19>-0.5,"↔",IF(-0.8*$K19>-1.5,"↓","⇊"))))) | S19: =IF($E19="","",IF(0.5*$L19>=1.5,"⇈",IF(0.5*$L19>=0.5,"↑",IF(0.5*$L19>-0.5,"↔",IF(0.5*$L19>-1.5,"↓","⇊"))))) | T19: =IF($E19="","",IF(0.5*$L19-0.5*$K19>=1.5,"⇈",IF(0.5*$L19-0.5*$K19>=0.5,"↑",IF(0.5*$L19-0.5*$K19>-0.5,"↔",IF(0.5*$L19-0.5*$K19>-1.5,"↓","⇊"))))) | U19: =IF($E19="","",IF(0.4*$L19-0.6*$K19>=1.5,"⇈",IF(0.4*$L19-0.6*$K19>=0.5,"↑",IF(0.4*$L19-0.6*$K19>-0.5,"↔",IF(0.4*$L19-0.6*$K19>-1.5,"↓","⇊"))))) | V19: =IF($E19="","",IF(0.5*$L19>=1.5,"⇈",IF(0.5*$L19>=0.5,"↑",IF(0.5*$L19>-0.5,"↔",IF(0.5*$L19>-1.5,"↓","⇊"))))) | W19: =IF($E19="","",IF(AND($L19>=0.5,$K19<=0.5),"Risk-on",IF(OR($L19<=-0.5,$K19>=1),"Risk-off","Neutral"))) | X19: =IF($E19="","",IF(AND(IFERROR(INDEX(Lib_Importance,$Z19),0)>=4,ABS($I19)>=1),"High",IF(ABS($I19)<0.5,"Low","Medium"))) | Z19: =IF('Data Tracker'!$D19="","",IFERROR(MATCH('Data Tracker'!$D19,Lib_Name,0),""))
B20: =IF('Data Tracker'!$D20="","",'Data Tracker'!$B20) | C20: =IF('Data Tracker'!$D20="","",'Data Tracker'!$D20) | D20: =IF($Z20="","",IFERROR(INDEX(Lib_Cat,$Z20),"")) | E20: =IF('Data Tracker'!$D20="","",'Data Tracker'!$E20) | F20: =IF('Data Tracker'!$D20="","",'Data Tracker'!$F20) | G20: =IF('Data Tracker'!$D20="","",'Data Tracker'!$G20) | H20: =IF($E20="","",$E20-$F20) | I20: =IF($E20="","",IFERROR($H20/INDEX(Lib_Scale,$Z20),0)) | J20: =IF($E20="","",IF(ABS($I20)<0.5,"Neutral",IF($I20>0,"Hot","Cold"))) | K20: =IF($E20="","",$I20*INDEX(Lib_PolInfl,$Z20)*INDEX(Lib_Importance,$Z20)/5) | L20: =IF($E20="","",$I20*INDEX(Lib_PolGrow,$Z20)*INDEX(Lib_Importance,$Z20)/5) | M20: =IF($E20="","",IF($K20>0.5,"Inflationary",IF($K20<-0.5,"Disinflationary","Neutral"))) | N20: =IF($E20="","",IF($L20>0.5,"Growth+",IF($L20<-0.5,"Growth-","Neutral"))) | O20: =IF($E20="","",IF(0.6*$K20+0.4*$L20>=1.5,"⇈",IF(0.6*$K20+0.4*$L20>=0.5,"↑",IF(0.6*$K20+0.4*$L20>-0.5,"↔",IF(0.6*$K20+0.4*$L20>-1.5,"↓","⇊"))))) | P20: =IF($E20="","",IF(0.7*$K20+0.3*$L20>=1.5,"⇈",IF(0.7*$K20+0.3*$L20>=0.5,"↑",IF(0.7*$K20+0.3*$L20>-0.5,"↔",IF(0.7*$K20+0.3*$L20>-1.5,"↓","⇊"))))) | Q20: =IF($E20="","",IF(-(0.7*$K20+0.3*$L20)>=1.5,"⇈",IF(-(0.7*$K20+0.3*$L20)>=0.5,"↑",IF(-(0.7*$K20+0.3*$L20)>-0.5,"↔",IF(-(0.7*$K20+0.3*$L20)>-1.5,"↓","⇊"))))) | R20: =IF($E20="","",IF(-0.8*$K20>=1.5,"⇈",IF(-0.8*$K20>=0.5,"↑",IF(-0.8*$K20>-0.5,"↔",IF(-0.8*$K20>-1.5,"↓","⇊"))))) | S20: =IF($E20="","",IF(0.5*$L20>=1.5,"⇈",IF(0.5*$L20>=0.5,"↑",IF(0.5*$L20>-0.5,"↔",IF(0.5*$L20>-1.5,"↓","⇊"))))) | T20: =IF($E20="","",IF(0.5*$L20-0.5*$K20>=1.5,"⇈",IF(0.5*$L20-0.5*$K20>=0.5,"↑",IF(0.5*$L20-0.5*$K20>-0.5,"↔",IF(0.5*$L20-0.5*$K20>-1.5,"↓","⇊"))))) | U20: =IF($E20="","",IF(0.4*$L20-0.6*$K20>=1.5,"⇈",IF(0.4*$L20-0.6*$K20>=0.5,"↑",IF(0.4*$L20-0.6*$K20>-0.5,"↔",IF(0.4*$L20-0.6*$K20>-1.5,"↓","⇊"))))) | V20: =IF($E20="","",IF(0.5*$L20>=1.5,"⇈",IF(0.5*$L20>=0.5,"↑",IF(0.5*$L20>-0.5,"↔",IF(0.5*$L20>-1.5,"↓","⇊"))))) | W20: =IF($E20="","",IF(AND($L20>=0.5,$K20<=0.5),"Risk-on",IF(OR($L20<=-0.5,$K20>=1),"Risk-off","Neutral"))) | X20: =IF($E20="","",IF(AND(IFERROR(INDEX(Lib_Importance,$Z20),0)>=4,ABS($I20)>=1),"High",IF(ABS($I20)<0.5,"Low","Medium"))) | Z20: =IF('Data Tracker'!$D20="","",IFERROR(MATCH('Data Tracker'!$D20,Lib_Name,0),""))
... B48: =IF('Data Tracker'!$D48="","",'Data Tracker'!$B48) | C48: =IF('Data Tracker'!$D48="","",'Data Tracker'!$D48) | D48: =IF($Z48="","",IFERROR(INDEX(Lib_Cat,$Z48),"")) | E48: =IF('Data Tracker'!$D48="","",'Data Tracker'!$E48) | F48: =IF('Data Tracker'!$D48="","",'Data Tracker'!$F48) | G48: =IF('Data Tracker'!$D48="","",'Data Tracker'!$G48) | H48: =IF($E48="","",$E48-$F48) | I48: =IF($E48="","",IFERROR($H48/INDEX(Lib_Scale,$Z48),0)) | J48: =IF($E48="","",IF(ABS($I48)<0.5,"Neutral",IF($I48>0,"Hot","Cold"))) | K48: =IF($E48="","",$I48*INDEX(Lib_PolInfl,$Z48)*INDEX(Lib_Importance,$Z48)/5) | L48: =IF($E48="","",$I48*INDEX(Lib_PolGrow,$Z48)*INDEX(Lib_Importance,$Z48)/5) | M48: =IF($E48="","",IF($K48>0.5,"Inflationary",IF($K48<-0.5,"Disinflationary","Neutral"))) | N48: =IF($E48="","",IF($L48>0.5,"Growth+",IF($L48<-0.5,"Growth-","Neutral"))) | O48: =IF($E48="","",IF(0.6*$K48+0.4*$L48>=1.5,"⇈",IF(0.6*$K48+0.4*$L48>=0.5,"↑",IF(0.6*$K48+0.4*$L48>-0.5,"↔",IF(0.6*$K48+0.4*$L48>-1.5,"↓","⇊"))))) | P48: =IF($E48="","",IF(0.7*$K48+0.3*$L48>=1.5,"⇈",IF(0.7*$K48+0.3*$L48>=0.5,"↑",IF(0.7*$K48+0.3*$L48>-0.5,"↔",IF(0.7*$K48+0.3*$L48>-1.5,"↓","⇊"))))) | Q48: =IF($E48="","",IF(-(0.7*$K48+0.3*$L48)>=1.5,"⇈",IF(-(0.7*$K48+0.3*$L48)>=0.5,"↑",IF(-(0.7*$K48+0.3*$L48)>-0.5,"↔",IF(-(0.7*$K48+0.3*$L48)>-1.5,"↓","⇊"))))) | R48: =IF($E48="","",IF(-0.8*$K48>=1.5,"⇈",IF(-0.8*$K48>=0.5,"↑",IF(-0.8*$K48>-0.5,"↔",IF(-0.8*$K48>-1.5,"↓","⇊"))))) | S48: =IF($E48="","",IF(0.5*$L48>=1.5,"⇈",IF(0.5*$L48>=0.5,"↑",IF(0.5*$L48>-0.5,"↔",IF(0.5*$L48>-1.5,"↓","⇊"))))) | T48: =IF($E48="","",IF(0.5*$L48-0.5*$K48>=1.5,"⇈",IF(0.5*$L48-0.5*$K48>=0.5,"↑",IF(0.5*$L48-0.5*$K48>-0.5,"↔",IF(0.5*$L48-0.5*$K48>-1.5,"↓","⇊"))))) | U48: =IF($E48="","",IF(0.4*$L48-0.6*$K48>=1.5,"⇈",IF(0.4*$L48-0.6*$K48>=0.5,"↑",IF(0.4*$L48-0.6*$K48>-0.5,"↔",IF(0.4*$L48-0.6*$K48>-1.5,"↓","⇊"))))) | V48: =IF($E48="","",IF(0.5*$L48>=1.5,"⇈",IF(0.5*$L48>=0.5,"↑",IF(0.5*$L48>-0.5,"↔",IF(0.5*$L48>-1.5,"↓","⇊"))))) | W48: =IF($E48="","",IF(AND($L48>=0.5,$K48<=0.5),"Risk-on",IF(OR($L48<=-0.5,$K48>=1),"Risk-off","Neutral"))) | X48: =IF($E48="","",IF(AND(IFERROR(INDEX(Lib_Importance,$Z48),0)>=4,ABS($I48)>=1),"High",IF(ABS($I48)<0.5,"Low","Medium"))) | Z48: =IF('Data Tracker'!$D48="","",IFERROR(MATCH('Data Tracker'!$D48,Lib_Name,0),""))
A50: How to read it
A51: Arrows show the USUAL first-order reaction to that surprise: ⇈ strong up · ↑ up · ↔ neutral · ↓ down · ⇊ strong down. UST px is the inverse of UST yld (prices fall when yields rise).
A52: Infl.imp (column K) is the hawkish impulse: positive = hawkish/inflationary, negative = dovish. The Fed Tracker averages these by category to build its bias score. GCC is shown as an oil/growth proxy - the dedicated GCC read comes with the Oil and USD modules in the next build phase.

Sheet Fed Tracker
A1: FED & CENTRAL BANK TRACKER
A2: What the Fed is doing, saying, and our hawkish/dovish score
A3: Macro Market Intelligence System - v0.9 (core)
A5: Cover | B5: Settings | C5: Impact Library | D5: Data Tracker | E5: Surprise Engine | F5: Fed Tracker
A8: What this sheet does
A9: The score blends seven inputs (each -2 dovish .. +2 hawkish): inflation, labor and growth surprises come straight from the Surprise Engine; the rest you set from Fed speeches and market moves. Weights live on Settings. Composite >= +1 = Hawkish, <= -1 = Dovish.
A12: Policy state
A13: Fed funds target range | C13: 4.25 | D13: 4.5 | E13: % lower / upper bound
A14: Last decision | C14: Hold
A15: Last meeting date | C15: 46191
A16: Next FOMC date | C16: 46232
A17: Days to next FOMC | C17: =IF(C16="","",C16-TODAY()) | E17: counts down automatically
A18: Market-implied path change (bps) | C18: 0 | E18: + = market priced more hawkish since last meeting
A19: Cuts priced this year | C19: 0
A20: Dot-plot direction | C20: Fewer cuts
A21: 2Y yield move since last (bps) | C21: 0
A22: 10Y real-yield move (bps) | C22: 0
A23: Balance sheet / QT | C23: QT ongoing at a reduced pace; balance-sheet runoff continues.
A25: Fed speech log (tone: -2 dovish .. +2 hawkish)
A26: Date | B26: Speaker | D26: Tone | E26: Comment / takeaway
A34: Hawkish / dovish score
A35: Sub-score | C35: Score | D35: Weight | E35: Contribution | F35: Source
A36: Inflation surprises | C36: =MEDIAN(-2,IFERROR(AVERAGEIF(SUR_CAT,"Inflation",SUR_INFLIMP),0),2) | D36: =INDEX(Fed_Weights,1) | E36: =C36*D36 | F36: Surprise Engine - Inflation category
A37: Labor-market strength | C37: =MEDIAN(-2,IFERROR(AVERAGEIF(SUR_CAT,"Labor",SUR_INFLIMP),0),2) | D37: =INDEX(Fed_Weights,2) | E37: =C37*D37 | F37: Surprise Engine - Labor category
A38: Growth strength | C38: =MEDIAN(-2,IFERROR(AVERAGEIF(SUR_CAT,"Growth",SUR_GROWIMP),0),2) | D38: =INDEX(Fed_Weights,3) | E38: =C38*D38 | F38: Surprise Engine - Growth category
A39: Fed-speech tone | C39: =MEDIAN(-2,IFERROR(AVERAGE(D27:D32),0),2) | D39: =INDEX(Fed_Weights,4) | E39: =C39*D39 | F39: average of the speech tones above
A40: Market-implied rate change | C40: =IF(C18>=15,2,IF(C18>=5,1,IF(C18>-5,0,IF(C18>-15,-1,-2)))) | D40: =INDEX(Fed_Weights,5) | E40: =C40*D40 | F40: market-implied path change (bps)
A41: Yield-curve move (2Y) | C41: =IF(C21>=15,2,IF(C21>=5,1,IF(C21>-5,0,IF(C21>-15,-1,-2)))) | D41: =INDEX(Fed_Weights,6) | E41: =C41*D41 | F41: 2Y yield move (bps)
A42: Real-yield move (10Y) | C42: =IF(C22>=15,2,IF(C22>=5,1,IF(C22>-5,0,IF(C22>-15,-1,-2)))) | D42: =INDEX(Fed_Weights,7) | E42: =C42*D42 | F42: 10Y real-yield move (bps)
A43: COMPOSITE FED SCORE | C43: =SUMPRODUCT(Fed_SubScores,Fed_Weights) | E43: =SUM(E36:E42) | F43: (equals SUMPRODUCT of scores x weights)
A44: FED POLICY BIAS | C44: =IF(C43>=1.0,"Hawkish",IF(C43>=0.33,"Mildly hawkish",IF(C43>=-0.33,"Neutral",IF(C43>=-1.0,"Mildly dovish","Dovish")))) | E44: ="Score "&TEXT(Score_Fed,"+0.00;-0.00;0.00")&" / band from Settings"
A46: Other major central banks
A47: Central bank | C47: Bias | E47: Note
A48: ECB | C48: Mildly dovish | E48: Cutting gradually as inflation eases
A49: BOE | C49: Neutral | E49: Data-dependent; services inflation still sticky
A50: SNB | C50: Dovish | E50: Low inflation, easing bias
A51: BOJ | C51: Mildly hawkish | E51: Normalizing policy very slowly
