Workbook
Name BaseCcy: 'Scenario Inputs'!$C$20
Name TotalInvested: 'Scenario Inputs'!$G$29
Name RiskFree: 'Risk & Return'!$C$13
Name RecBasis: 'Allocation'!$C$54

Sheet Overview
A1: PORTFOLIO ALLOCATION OPTIMIZER
A2: Scenario analysis, risk/return and recommended rebalancing
A3: Portfolio Allocation Optimizer - v1.0
A5: Overview | B5: Scenario Inputs | C5: Scenario Output | D5: Risk & Return | E5: Allocation | F5: Rebalancing | G5: Dashboard | H5: Formula Guide
A7: What this tool does
A8: It helps you understand four things, simply and transparently: (1) your CURRENT allocation, (2) the IMPACT of a market scenario on each asset and the whole portfolio, (3) the RISK and RETURN trade-off across allocation choices, and (4) a recommended set of REBALANCING actions.
A9: It is a clean, explainable Excel tool -- not a black-box quant model. Every result is a short, visible formula you can follow and audit.
A10: How to use it (in order)
A11: 1. Scenario Inputs | C11: Type your scenario: dates, each asset's start/end price and FX rate, amounts invested, and target/min/max weights. Includes a small bond calculator.
A12: 2. Scenario Output | C12: See each asset's local return, FX effect, currency-adjusted return and contribution to the portfolio return.
A13: 3. Risk & Return | C13: Enter long-term expected return, volatility and correlations -- the inputs behind the recommendation.
A14: 4. Allocation | C14: Compare six allocations and build the scenario-stressed recommendation; pick which one to rebalance toward.
A15: 5. Rebalancing | C15: Get the buy/sell/hold actions and the reason for each.
A16: 6. Dashboard | C16: See it all visually: allocation pies, scenario bars and a risk/return map.
A17: 7. Formula Guide | C17: Every formula explained in plain language.
A19: Investable assets
A20: SMI (Swiss Market Index) | D20: native currency: CHF
A21: S&P 500 | D21: native currency: USD
A22: SXI Real Estate Funds Broad Index | D22: native currency: CHF
A23: Gold | D23: native currency: USD
A24: US Government Bonds | D24: native currency: USD
A26: Market indicators (context / drivers only -- not holdings unless you mark them investable)
A27: DXY (US Dollar Index) | D27: Strength of the US dollar vs major currencies.
A28: CHF/USD | D28: Swiss franc per US dollar (drives USD-asset value in CHF terms).
A29: USD/KWD | D29: US dollar value in Kuwaiti dinar (FX for USD assets).
A30: CHF/KWD | D30: Swiss franc value in Kuwaiti dinar (FX for CHF assets).
A32: The six allocations compared
A33: Current | D33: Your portfolio today, from invested amounts.
A34: Equal-weight | D34: Every asset gets the same weight (1 / N).
A35: Custom target | D35: The target weights you type in.
A36: Max-Sharpe* | D36: Tilts to assets with the best long-term return per unit of risk.
A37: Min-volatility* | D37: Tilts to the calmer (lower-volatility) assets.
A38: Scenario-stressed | D38: Max-Sharpe base, modestly tilted by the scenario, within your limits.
A40: Legend: | B40: Input (type here) | D40: Formula | F40: Key output / link | H40: blue = input - black = formula - green = output
A42: Important
A43: The recommended allocation is model-based and should be used as a decision-support tool, not as a guaranteed perfect portfolio.

Sheet Scenario Inputs
A1: SCENARIO INPUTS
A2: Type your scenario here -- the whole workbook updates from this sheet
A3: Portfolio Allocation Optimizer - v1.0
A5: Overview | B5: Scenario Inputs | C5: Scenario Output | D5: Risk & Return | E5: Allocation | F5: Rebalancing | G5: Dashboard | H5: Formula Guide
A7: How to read this sheet
A8: WHAT THIS SHEET IS FOR: describe one scenario (e.g. 'Since Fed Rate Decision') and the price/FX moves over it.
A9: WHAT TO INPUT: the yellow cells -- scenario dates, each asset's start & end price, its FX rate vs your base currency, how much you have invested, and your target / minimum / maximum weights.
A10: FX RATE MEANING: the value of 1 unit of the asset's currency in your base currency (KWD). USD assets use USD/KWD; CHF assets use CHF/KWD.
A11: DXY and the FX pairs are DRIVERS / context only -- they are NOT portfolio holdings unless you set 'Investable?' to Yes.
A13: Legend: | B13: Input (type here) | D13: Formula | F13: Key output / link | H13: blue = input - black = formula - green = output
A15: Scenario
A16: Scenario name | C16: Since Fed Rate Decision
A17: Start date | C17: 2024-09-18
A18: End date | C18: 2024-12-15
A19: Holding period (days) | C19: 88
A20: Base currency | C20: KWD
A22: Portfolio Assets (investable)
A23: Asset | B23: Ccy | C23: Start price (local) | D23: End price (local) | E23: Start FX (1 ccy = ? KWD) | F23: End FX (? KWD) | G23: Invested (KWD) | H23: Current weight | I23: Target weight | J23: Min weight | K23: Max weight
A24: SMI (Swiss Market Index) | B24: CHF | C24: 12000 | D24: 11600 | E24: 0.36 | F24: 0.355 | G24: 25000 | H24: =IFERROR('Scenario Inputs'!$G$24/TotalInvested,0) | I24: 0.18 | J24: 0.05 | K24: 0.3
A25: S&P 500 | B25: USD | C25: 5600 | D25: 5950 | E25: 0.307 | F25: 0.31 | G25: 40000 | H25: =IFERROR('Scenario Inputs'!$G$25/TotalInvested,0) | I25: 0.32 | J25: 0.1 | K25: 0.4
A26: SXI Real Estate Funds Broad Index | B26: CHF | C26: 530 | D26: 545 | E26: 0.36 | F26: 0.355 | G26: 15000 | H26: =IFERROR('Scenario Inputs'!$G$26/TotalInvested,0) | I26: 0.12 | J26: 0.05 | K26: 0.25
A27: Gold | B27: USD | C27: 2580 | D27: 2650 | E27: 0.307 | F27: 0.31 | G27: 12000 | H27: =IFERROR('Scenario Inputs'!$G$27/TotalInvested,0) | I27: 0.1 | J27: 0.05 | K27: 0.2
A28: US Government Bonds | B28: USD | C28: 99 | D28: 98 | E28: 0.307 | F28: 0.31 | G28: 18000 | H28: =IFERROR('Scenario Inputs'!$G$28/TotalInvested,0) | I28: 0.28 | J28: 0.1 | K28: 0.4
A29: Total | G29: =SUM('Scenario Inputs'!$G$24:$G$28) | H29: =SUM('Scenario Inputs'!$H$24:$H$28) | I29: =SUM('Scenario Inputs'!$I$24:$I$28)
A30: Tip: target weights should sum to 100%. Current weights are computed from the amounts invested.
A32: Market Indicators (drivers / context only -- not holdings unless marked investable)
A33: Indicator | B33: Start | C33: End | D33: % change | E33: Investable? | F33: What it tells you
A34: DXY (US Dollar Index) | B34: 101 | C34: 107 | D34: =IFERROR('Scenario Inputs'!$C$34/'Scenario Inputs'!$B$34-1,"") | E34: No | F34: Strength of the US dollar vs major currencies.
A35: CHF/USD | B35: 1.18 | C35: 1.14 | D35: =IFERROR('Scenario Inputs'!$C$35/'Scenario Inputs'!$B$35-1,"") | E35: No | F35: Swiss franc per US dollar (drives USD-asset value in CHF terms).
A36: USD/KWD | B36: 0.307 | C36: 0.31 | D36: =IFERROR('Scenario Inputs'!$C$36/'Scenario Inputs'!$B$36-1,"") | E36: No | F36: US dollar value in Kuwaiti dinar (FX for USD assets).
A37: CHF/KWD | B37: 0.36 | C37: 0.355 | D37: =IFERROR('Scenario Inputs'!$C$37/'Scenario Inputs'!$B$37-1,"") | E37: No | F37: Swiss franc value in Kuwaiti dinar (FX for CHF assets).
A39: Bond Scenario Calculator (US Government Bonds)
A40: How the bond return works
A41: Bonds earn a coupon as well as moving in price, so we add the coupon to the price change.
A42: Bond return = (End price - Start price + Coupon earned) / Start price. Coupon earned = Face x Coupon rate x (Holding days / 365).
A43: This bond Total return feeds the 'US Government Bonds' local return on the Scenario Output sheet.
A45: Starting bond price | C45: 99
A46: Ending bond price | C46: 98
A47: Face value | C47: 100
A48: Coupon rate (annual) | C48: 0.04
...

Sheet Scenario Output
A1: SCENARIO OUTPUT
A2: What the scenario did to each asset and to the whole portfolio
A3: Portfolio Allocation Optimizer - v1.0
A5: Overview | B5: Scenario Inputs | C5: Scenario Output | D5: Risk & Return | E5: Allocation | F5: Rebalancing | G5: Dashboard | H5: Formula Guide
A7: How to read this sheet
A8: WHAT THIS SHEET TELLS YOU: how each asset performed in the scenario, in your base currency, and how much each one added to (or subtracted from) the total portfolio return.
A9: COLUMNS: Local return = price move in the asset's own currency. FX effect = currency move vs your base currency. Currency-adjusted return = the two combined (what you actually earned). Contribution = Current weight x Currency-adjusted return. Portfolio return = sum of all contributions.
A10: FORMULAS: Local = End / Start - 1 | FX = End FX / Start FX - 1 | Adjusted = (1 + Local) x (1 + FX) - 1 | Contribution = Weight x Adjusted.
A11: Note: 'US Government Bonds' local return comes from the Bond Calculator (price move + coupon), not price alone.
A14: Asset | B14: Start price | C14: End price | D14: Local return | E14: FX effect | F14: Currency-adj. return | G14: Current weight | H14: Contribution to return | I14: Start value (KWD) | J14: End value (KWD) | K14: Performance attribution
A15: SMI (Swiss Market Index) | B15: ='Scenario Inputs'!$C$24 | C15: ='Scenario Inputs'!$D$24 | D15: =IFERROR('Scenario Inputs'!$D$24/'Scenario Inputs'!$C$24-1,0) | E15: =IFERROR('Scenario Inputs'!$F$24/'Scenario Inputs'!$E$24-1,0) | F15: =(1+'Scenario Output'!$D$15)*(1+'Scenario Output'!$E$15)-1 | G15: ='Scenario Inputs'!$H$24 | H15: ='Scenario Output'!$G$15*'Scenario Output'!$F$15 | I15: ='Scenario Inputs'!$G$24 | J15: ='Scenario Output'!$I$15*(1+'Scenario Output'!$F$15) | K15: =IF('Scenario Output'!$F$15>=0,"Helped: +","Hurt: ")&TEXT('Scenario Output'!$H$15,"0.0%")&" of portfolio return"
A16: S&P 500 | B16: ='Scenario Inputs'!$C$25 | C16: ='Scenario Inputs'!$D$25 | D16: =IFERROR('Scenario Inputs'!$D$25/'Scenario Inputs'!$C$25-1,0) | E16: =IFERROR('Scenario Inputs'!$F$25/'Scenario Inputs'!$E$25-1,0) | F16: =(1+'Scenario Output'!$D$16)*(1+'Scenario Output'!$E$16)-1 | G16: ='Scenario Inputs'!$H$25 | H16: ='Scenario Output'!$G$16*'Scenario Output'!$F$16 | I16: ='Scenario Inputs'!$G$25 | J16: ='Scenario Output'!$I$16*(1+'Scenario Output'!$F$16) | K16: =IF('Scenario Output'!$F$16>=0,"Helped: +","Hurt: ")&TEXT('Scenario Output'!$H$16,"0.0%")&" of portfolio return"
A17: SXI Real Estate Funds Broad Index | B17: ='Scenario Inputs'!$C$26 | C17: ='Scenario Inputs'!$D$26 | D17: =IFERROR('Scenario Inputs'!$D$26/'Scenario Inputs'!$C$26-1,0) | E17: =IFERROR('Scenario Inputs'!$F$26/'Scenario Inputs'!$E$26-1,0) | F17: =(1+'Scenario Output'!$D$17)*(1+'Scenario Output'!$E$17)-1 | G17: ='Scenario Inputs'!$H$26 | H17: ='Scenario Output'!$G$17*'Scenario Output'!$F$17 | I17: ='Scenario Inputs'!$G$26 | J17: ='Scenario Output'!$I$17*(1+'Scenario Output'!$F$17) | K17: =IF('Scenario Output'!$F$17>=0,"Helped: +","Hurt: ")&TEXT('Scenario Output'!$H$17,"0.0%")&" of portfolio return"
A18: Gold | B18: ='Scenario Inputs'!$C$27 | C18: ='Scenario Inputs'!$D$27 | D18: =IFERROR('Scenario Inputs'!$D$27/'Scenario Inputs'!$C$27-1,0) | E18: =IFERROR('Scenario Inputs'!$F$27/'Scenario Inputs'!$E$27-1,0) | F18: =(1+'Scenario Output'!$D$18)*(1+'Scenario Output'!$E$18)-1 | G18: ='Scenario Inputs'!$H$27 | H18: ='Scenario Output'!$G$18*'Scenario Output'!$F$18 | I18: ='Scenario Inputs'!$G$27 | J18: ='Scenario Output'!$I$18*(1+'Scenario Output'!$F$18) | K18: =IF('Scenario Output'!$F$18>=0,"Helped: +","Hurt: ")&TEXT('Scenario Output'!$H$18,"0.0%")&" of portfolio return"
A19: US Government Bonds | B19: ='Scenario Inputs'!$C$28 | C19: ='Scenario Inputs'!$D$28 | D19: ='Scenario Inputs'!$C$53 | E19: =IFERROR('Scenario Inputs'!$F$28/'Scenario Inputs'!$E$28-1,0) | F19: =(1+'Scenario Output'!$D$19)*(1+'Scenario Output'!$E$19)-1 | G19: ='Scenario Inputs'!$H$28 | H19: ='Scenario Output'!$G$19*'Scenario Output'!$F$19 | I19: ='Scenario Inputs'!$G$28 | J19: ='Scenario Output'!$I$19*(1+'Scenario Output'!$F$19) | K19: =IF('Scenario Output'!$F$19>=0,"Helped: +","Hurt: ")&TEXT('Scenario Output'!$H$19,"0.0%")&" of portfolio return"
A20: Portfolio total | G20: =SUM('Scenario Output'!$G$15:$G$19) | H20: =SUM('Scenario Output'!$H$15:$H$19) | I20: =SUM('Scenario Output'!$I$15:$I$19) | J20: =SUM('Scenario Output'!$J$15:$J$19)
A22: Scenario portfolio return | C22: ='Scenario Output'!$H$20 | F22: Cross-check (End value / Start value - 1) | I22: =IFERROR('Scenario Output'!$J$20/'Scenario Output'!$I$20-1,"")
A23: The two match because each weight is the asset's share of the starting value.

Sheet Risk & Return
A1: RISK & RETURN
A2: Long-term assumptions used by the recommended allocation
A3: Portfolio Allocation Optimizer - v1.0
A5: Overview | B5: Scenario Inputs | C5: Scenario Output | D5: Risk & Return | E5: Allocation | F5: Rebalancing | G5: Dashboard | H5: Formula Guide
A7: How to read this sheet
A8: WHAT TO INPUT: a long-term (annual) expected return and a volatility for each asset, plus how the assets move together (the correlation table). These are long-run views, separate from the one-off scenario.
A9: WHAT IT MEANS: volatility = how much an asset bounces around (risk). Correlation = do two assets move together (near +1), independently (0), or opposite (near -1). Diversification works best with low correlation.
A10: Sharpe ratio = (expected return - risk-free) / volatility = return earned per unit of risk. Higher is better.
A13: Risk-free rate (annual) | C13: 0.025
A15: Capital-Market Assumptions
A16: Asset | B16: Expected return | C16: Volatility (risk) | D16: Scenario return | E16: Sharpe ratio
A17: SMI (Swiss Market Index) | B17: 0.06 | C17: 0.14 | D17: ='Scenario Output'!$F$15 | E17: =IFERROR(('Risk & Return'!$B$17-RiskFree)/'Risk & Return'!$C$17,"")
A18: S&P 500 | B18: 0.075 | C18: 0.16 | D18: ='Scenario Output'!$F$16 | E18: =IFERROR(('Risk & Return'!$B$18-RiskFree)/'Risk & Return'!$C$18,"")
A19: SXI Real Estate Funds Broad Index | B19: 0.045 | C19: 0.09 | D19: ='Scenario Output'!$F$17 | E19: =IFERROR(('Risk & Return'!$B$19-RiskFree)/'Risk & Return'!$C$19,"")
A20: Gold | B20: 0.04 | C20: 0.15 | D20: ='Scenario Output'!$F$18 | E20: =IFERROR(('Risk & Return'!$B$20-RiskFree)/'Risk & Return'!$C$20,"")
A21: US Government Bonds | B21: 0.03 | C21: 0.06 | D21: ='Scenario Output'!$F$19 | E21: =IFERROR(('Risk & Return'!$B$21-RiskFree)/'Risk & Return'!$C$21,"")
A23: Correlation Matrix (how assets move together; 1 = same, 0 = independent, -1 = opposite)
A24: Correlation | B24: SMI | C24: S&P 500 | D24: SXI RE | E24: Gold | F24: US Bonds
A25: SMI | B25: 1 | C25: 0.8 | D25: 0.55 | E25: 0.15 | F25: -0.1
A26: S&P 500 | B26: 0.8 | C26: 1 | D26: 0.45 | E26: 0.1 | F26: -0.15
A27: SXI RE | B27: 0.55 | C27: 0.45 | D27: 1 | E27: 0.2 | F27: 0.1
A28: Gold | B28: 0.15 | C28: 0.1 | D28: 0.2 | E28: 1 | F28: 0.25
A29: US Bonds | B29: -0.1 | C29: -0.15 | D29: 0.1 | E29: 0.25 | F29: 1
A31: Covariance Matrix (computed = volatility i x volatility j x correlation)
A32: Covariance | B32: SMI | C32: S&P 500 | D32: SXI RE | E32: Gold | F32: US Bonds
A33: SMI | B33: ='Risk & Return'!$C$17*'Risk & Return'!$C$17*'Risk & Return'!$B$25 | C33: ='Risk & Return'!$C$17*'Risk & Return'!$C$18*'Risk & Return'!$C$25 | D33: ='Risk & Return'!$C$17*'Risk & Return'!$C$19*'Risk & Return'!$D$25 | E33: ='Risk & Return'!$C$17*'Risk & Return'!$C$20*'Risk & Return'!$E$25 | F33: ='Risk & Return'!$C$17*'Risk & Return'!$C$21*'Risk & Return'!$F$25
A34: S&P 500 | B34: ='Risk & Return'!$C$18*'Risk & Return'!$C$17*'Risk & Return'!$B$26 | C34: ='Risk & Return'!$C$18*'Risk & Return'!$C$18*'Risk & Return'!$C$26 | D34: ='Risk & Return'!$C$18*'Risk & Return'!$C$19*'Risk & Return'!$D$26 | E34: ='Risk & Return'!$C$18*'Risk & Return'!$C$20*'Risk & Return'!$E$26 | F34: ='Risk & Return'!$C$18*'Risk & Return'!$C$21*'Risk & Return'!$F$26
A35: SXI RE | B35: ='Risk & Return'!$C$19*'Risk & Return'!$C$17*'Risk & Return'!$B$27 | C35: ='Risk & Return'!$C$19*'Risk & Return'!$C$18*'Risk & Return'!$C$27 | D35: ='Risk & Return'!$C$19*'Risk & Return'!$C$19*'Risk & Return'!$D$27 | E35: ='Risk & Return'!$C$19*'Risk & Return'!$C$20*'Risk & Return'!$E$27 | F35: ='Risk & Return'!$C$19*'Risk & Return'!$C$21*'Risk & Return'!$F$27
A36: Gold | B36: ='Risk & Return'!$C$20*'Risk & Return'!$C$17*'Risk & Return'!$B$28 | C36: ='Risk & Return'!$C$20*'Risk & Return'!$C$18*'Risk & Return'!$C$28 | D36: ='Risk & Return'!$C$20*'Risk & Return'!$C$19*'Risk & Return'!$D$28 | E36: ='Risk & Return'!$C$20*'Risk & Return'!$C$20*'Risk & Return'!$E$28 | F36: ='Risk & Return'!$C$20*'Risk & Return'!$C$21*'Risk & Return'!$F$28
A37: US Bonds | B37: ='Risk & Return'!$C$21*'Risk & Return'!$C$17*'Risk & Return'!$B$29 | C37: ='Risk & Return'!$C$21*'Risk & Return'!$C$18*'Risk & Return'!$C$29 | D37: ='Risk & Return'!$C$21*'Risk & Return'!$C$19*'Risk & Return'!$D$29 | E37: ='Risk & Return'!$C$21*'Risk & Return'!$C$20*'Risk & Return'!$E$29 | F37: ='Risk & Return'!$C$21*'Risk & Return'!$C$21*'Risk & Return'!$F$29
A39: The Allocation sheet multiplies these covariances by the portfolio weights to get each portfolio's volatility (risk). Lower correlations -> more diversification -> lower risk.

Sheet Allocation
A1: ALLOCATION
A2: Compare allocations and build a scenario-stressed recommendation
A3: Portfolio Allocation Optimizer - v1.0
A5: Overview | B5: Scenario Inputs | C5: Scenario Output | D5: Risk & Return | E5: Allocation | F5: Rebalancing | G5: Dashboard | H5: Formula Guide
A7: How to read this sheet
A8: WHAT THIS SHEET DOES: compares your Current allocation with Equal-weight, your Custom target, a simplified Max-Sharpe and Min-volatility mix, and a Scenario-stressed recommendation.
A9: HOW THE RECOMMENDATION IS BUILT: it starts from the Max-Sharpe mix (long-term return vs risk vs correlation), tilts modestly toward assets that did well in the scenario (capped so it never chases short-term moves), then respects your minimum/maximum weights.
A10: HOW TO READ IT: look at expected return AND volatility together -- higher return with higher risk is not automatically better. The Sharpe ratio (return per unit of risk) helps you compare.
A13: Step 1 - Building blocks (used by Max-Sharpe, Min-volatility and the scenario tilt)
A14: Asset | B14: Volatility | C14: 1 / Vol^2 (min-vol) | D14: Sharpe score (max-Sharpe) | E14: Scenario return | F14: Tilt (capped) | G14: Min weight | H14: Max weight
A15: SMI (Swiss Market Index) | B15: ='Risk & Return'!$C$17 | C15: =IFERROR(1/'Risk & Return'!$C$17^2,0) | D15: =IFERROR(MAX(0,'Risk & Return'!$B$17-RiskFree)/'Risk & Return'!$C$17^2,0) | E15: ='Risk & Return'!$D$17 | F15: =MEDIAN(-0.4,0.5*('Risk & Return'!$D$17-AVERAGE('Risk & Return'!$D$17:$D$21)),0.4) | G15: ='Scenario Inputs'!$J$24 | H15: ='Scenario Inputs'!$K$24
A16: S&P 500 | B16: ='Risk & Return'!$C$18 | C16: =IFERROR(1/'Risk & Return'!$C$18^2,0) | D16: =IFERROR(MAX(0,'Risk & Return'!$B$18-RiskFree)/'Risk & Return'!$C$18^2,0) | E16: ='Risk & Return'!$D$18 | F16: =MEDIAN(-0.4,0.5*('Risk & Return'!$D$18-AVERAGE('Risk & Return'!$D$17:$D$21)),0.4) | G16: ='Scenario Inputs'!$J$25 | H16: ='Scenario Inputs'!$K$25
A17: SXI Real Estate Funds Broad Index | B17: ='Risk & Return'!$C$19 | C17: =IFERROR(1/'Risk & Return'!$C$19^2,0) | D17: =IFERROR(MAX(0,'Risk & Return'!$B$19-RiskFree)/'Risk & Return'!$C$19^2,0) | E17: ='Risk & Return'!$D$19 | F17: =MEDIAN(-0.4,0.5*('Risk & Return'!$D$19-AVERAGE('Risk & Return'!$D$17:$D$21)),0.4) | G17: ='Scenario Inputs'!$J$26 | H17: ='Scenario Inputs'!$K$26
A18: Gold | B18: ='Risk & Return'!$C$20 | C18: =IFERROR(1/'Risk & Return'!$C$20^2,0) | D18: =IFERROR(MAX(0,'Risk & Return'!$B$20-RiskFree)/'Risk & Return'!$C$20^2,0) | E18: ='Risk & Return'!$D$20 | F18: =MEDIAN(-0.4,0.5*('Risk & Return'!$D$20-AVERAGE('Risk & Return'!$D$17:$D$21)),0.4) | G18: ='Scenario Inputs'!$J$27 | H18: ='Scenario Inputs'!$K$27
A19: US Government Bonds | B19: ='Risk & Return'!$C$21 | C19: =IFERROR(1/'Risk & Return'!$C$21^2,0) | D19: =IFERROR(MAX(0,'Risk & Return'!$B$21-RiskFree)/'Risk & Return'!$C$21^2,0) | E19: ='Risk & Return'!$D$21 | F19: =MEDIAN(-0.4,0.5*('Risk & Return'!$D$21-AVERAGE('Risk & Return'!$D$17:$D$21)),0.4) | G19: ='Scenario Inputs'!$J$28 | H19: ='Scenario Inputs'!$K$28
A20: Total | C20: =SUM(C15:C19) | D20: =SUM(D15:D19)
A22: Step 2 - How the scenario-stressed allocation is built (fit to your min/max, re-total to 100%, repeat so it settles)
A23: Asset | B23: Max-Sharpe base | C23: Tilt (capped) | D23: Raw = base x (1+tilt) | E23: Normalised | F23: Fit to min/max | G23: Re-total to 100% | H23: Fit again | I23: Final weight | J23: Within limits?
A24: SMI (Swiss Market Index) | B24: ='Allocation'!$E$33 | C24: ='Allocation'!$F$15 | D24: =$B$24*(1+$C$24) | E24: =IFERROR($D$24/SUM(D24:D28),0) | F24: =MEDIAN('Scenario Inputs'!$J$24,$E$24,'Scenario Inputs'!$K$24) | G24: =IFERROR($F$24/SUM(F24:F28),0) | H24: =MEDIAN('Scenario Inputs'!$J$24,$G$24,'Scenario Inputs'!$K$24) | I24: =IFERROR($H$24/SUM(H24:H28),0) | J24: =IF(AND($I$24>='Scenario Inputs'!$J$24-0.005,$I$24<='Scenario Inputs'!$K$24+0.005),"Within","Review")
A25: S&P 500 | B25: ='Allocation'!$E$34 | C25: ='Allocation'!$F$16 | D25: =$B$25*(1+$C$25) | E25: =IFERROR($D$25/SUM(D24:D28),0) | F25: =MEDIAN('Scenario Inputs'!$J$25,$E$25,'Scenario Inputs'!$K$25) | G25: =IFERROR($F$25/SUM(F24:F28),0) | H25: =MEDIAN('Scenario Inputs'!$J$25,$G$25,'Scenario Inputs'!$K$25) | I25: =IFERROR($H$25/SUM(H24:H28),0) | J25: =IF(AND($I$25>='Scenario Inputs'!$J$25-0.005,$I$25<='Scenario Inputs'!$K$25+0.005),"Within","Review")
A26: SXI Real Estate Funds Broad Index | B26: ='Allocation'!$E$35 | C26: ='Allocation'!$F$17 | D26: =$B$26*(1+$C$26) | E26: =IFERROR($D$26/SUM(D24:D28),0) | F26: =MEDIAN('Scenario Inputs'!$J$26,$E$26,'Scenario Inputs'!$K$26) | G26: =IFERROR($F$26/SUM(F24:F28),0) | H26: =MEDIAN('Scenario Inputs'!$J$26,$G$26,'Scenario Inputs'!$K$26) | I26: =IFERROR($H$26/SUM(H24:H28),0) | J26: =IF(AND($I$26>='Scenario Inputs'!$J$26-0.005,$I$26<='Scenario Inputs'!$K$26+0.005),"Within","Review")
A27: Gold | B27: ='Allocation'!$E$36 | C27: ='Allocation'!$F$18 | D27: =$B$27*(1+$C$27) | E27: =IFERROR($D$27/SUM(D24:D28),0) | F27: =MEDIAN('Scenario Inputs'!$J$27,$E$27,'Scenario Inputs'!$K$27) | G27: =IFERROR($F$27/SUM(F24:F28),0) | H27: =MEDIAN('Scenario Inputs'!$J$27,$G$27,'Scenario Inputs'!$K$27) | I27: =IFERROR($H$27/SUM(H24:H28),0) | J27: =IF(AND($I$27>='Scenario Inputs'!$J$27-0.005,$I$27<='Scenario Inputs'!$K$27+0.005),"Within","Review")
A28: US Government Bonds | B28: ='Allocation'!$E$37 | C28: ='Allocation'!$F$19 | D28: =$B$28*(1+$C$28) | E28: =IFERROR($D$28/SUM(D24:D28),0) | F28: =MEDIAN('Scenario Inputs'!$J$28,$E$28,'Scenario Inputs'!$K$28) | G28: =IFERROR($F$28/SUM(F24:F28),0) | H28: =MEDIAN('Scenario Inputs'!$J$28,$G$28,'Scenario Inputs'!$K$28) | I28: =IFERROR($H$28/SUM(H24:H28),0) | J28: =IF(AND($I$28>='Scenario Inputs'!$J$28-0.005,$I$28<='Scenario Inputs'!$K$28+0.005),"Within","Review")
A29: Total | I29: =SUM(I24:I28)
A31: Step 3 - Allocation comparison (each column sums to 100%)
A32: Asset | B32: Current | C32: Equal-weight | D32: Custom target | E32: Max-Sharpe* | F32: Min-volatility* | G32: Scenario-stressed
A33: SMI (Swiss Market Index) | B33: ='Scenario Output'!$G$15 | C33: =1/5 | D33: =IFERROR('Scenario Inputs'!$I$24/SUM('Scenario Inputs'!$I$24:$I$28),0) | E33: =IFERROR('Allocation'!$D$15/'Allocation'!$D$20,1/5) | F33: =IFERROR('Allocation'!$C$15/'Allocation'!$C$20,1/5) | G33: ='Allocation'!$I$24
A34: S&P 500 | B34: ='Scenario Output'!$G$16 | C34: =1/5 | D34: =IFERROR('Scenario Inputs'!$I$25/SUM('Scenario Inputs'!$I$24:$I$28),0) | E34: =IFERROR('Allocation'!$D$16/'Allocation'!$D$20,1/5) | F34: =IFERROR('Allocation'!$C$16/'Allocation'!$C$20,1/5) | G34: ='Allocation'!$I$25
A35: SXI Real Estate Funds Broad Index | B35: ='Scenario Output'!$G$17 | C35: =1/5 | D35: =IFERROR('Scenario Inputs'!$I$26/SUM('Scenario Inputs'!$I$24:$I$28),0) | E35: =IFERROR('Allocation'!$D$17/'Allocation'!$D$20,1/5) | F35: =IFERROR('Allocation'!$C$17/'Allocation'!$C$20,1/5) | G35: ='Allocation'!$I$26
A36: Gold | B36: ='Scenario Output'!$G$18 | C36: =1/5 | D36: =IFERROR('Scenario Inputs'!$I$27/SUM('Scenario Inputs'!$I$24:$I$28),0) | E36: =IFERROR('Allocation'!$D$18/'Allocation'!$D$20,1/5) | F36: =IFERROR('Allocation'!$C$18/'Allocation'!$C$20,1/5) | G36: ='Allocation'!$I$27
A37: US Government Bonds | B37: ='Scenario Output'!$G$19 | C37: =1/5 | D37: =IFERROR('Scenario Inputs'!$I$28/SUM('Scenario Inputs'!$I$24:$I$28),0) | E37: =IFERROR('Allocation'!$D$19/'Allocation'!$D$20,1/5) | F37: =IFERROR('Allocation'!$C$19/'Allocation'!$C$20,1/5) | G37: ='Allocation'!$I$28
A38: Total | B38: =SUM(B33:B37) | C38: =SUM(C33:C37) | D38: =SUM(D33:D37) | E38: =SUM(E33:E37) | F38: =SUM(F33:F37) | G38: =SUM(G33:G37)
A40: Step 4 - Portfolio risk & return for each allocation (engine - no need to edit)
A41: Allocation | B41: SMI | C41: S&P 500 | D41: SXI RE | E41: Gold | F41: US Bonds | G41: Exp. return | H41: cw SMI | I41: cw S&P 500 | J41: cw SXI RE | K41: cw Gold | L41: cw US Bonds | M41: Variance | N41: Volatility | O41: Sharpe
A42: Expected return (by asset) | B42: ='Risk & Return'!$B$17 | C42: ='Risk & Return'!$B$18 | D42: ='Risk & Return'!$B$19 | E42: ='Risk & Return'!$B$20 | F42: ='Risk & Return'!$B$21
A43: Current | B43: ='Allocation'!$B$33 | C43: ='Allocation'!$B$34 | D43: ='Allocation'!$B$35 | E43: ='Allocation'!$B$36 | F43: ='Allocation'!$B$37 | G43: =SUMPRODUCT(B43:F43,B42:F42) | H43: =SUMPRODUCT(B43:F43,'Risk & Return'!$B$33:$F$33) | I43: =SUMPRODUCT(B43:F43,'Risk & Return'!$B$34:$F$34) | J43: =SUMPRODUCT(B43:F43,'Risk & Return'!$B$35:$F$35) | K43: =SUMPRODUCT(B43:F43,'Risk & Return'!$B$36:$F$36) | L43: =SUMPRODUCT(B43:F43,'Risk & Return'!$B$37:$F$37) | M43: =SUMPRODUCT(B43:F43,H43:L43) | N43: =SQRT('Allocation'!$M$43) | O43: =IFERROR(('Allocation'!$G$43-RiskFree)/'Allocation'!$N$43,"")
A44: Equal-weight | B44: ='Allocation'!$C$33 | C44: ='Allocation'!$C$34 | D44: ='Allocation'!$C$35 | E44: ='Allocation'!$C$36 | F44: ='Allocation'!$C$37 | G44: =SUMPRODUCT(B44:F44,B42:F42) | H44: =SUMPRODUCT(B44:F44,'Risk & Return'!$B$33:$F$33) | I44: =SUMPRODUCT(B44:F44,'Risk & Return'!$B$34:$F$34) | J44: =SUMPRODUCT(B44:F44,'Risk & Return'!$B$35:$F$35) | K44: =SUMPRODUCT(B44:F44,'Risk & Return'!$B$36:$F$36) | L44: =SUMPRODUCT(B44:F44,'Risk & Return'!$B$37:$F$37) | M44: =SUMPRODUCT(B44:F44,H44:L44) | N44: =SQRT('Allocation'!$M$44) | O44: =IFERROR(('Allocation'!$G$44-RiskFree)/'Allocation'!$N$44,"")
A45: Custom target | B45: ='Allocation'!$D$33 | C45: ='Allocation'!$D$34 | D45: ='Allocation'!$D$35 | E45: ='Allocation'!$D$36 | F45: ='Allocation'!$D$37 | G45: =SUMPRODUCT(B45:F45,B42:F42) | H45: =SUMPRODUCT(B45:F45,'Risk & Return'!$B$33:$F$33) | I45: =SUMPRODUCT(B45:F45,'Risk & Return'!$B$34:$F$34) | J45: =SUMPRODUCT(B45:F45,'Risk & Return'!$B$35:$F$35) | K45: =SUMPRODUCT(B45:F45,'Risk & Return'!$B$36:$F$36) | L45: =SUMPRODUCT(B45:F45,'Risk & Return'!$B$37:$F$37) | M45: =SUMPRODUCT(B45:F45,H45:L45) | N45: =SQRT('Allocation'!$M$45) | O45: =IFERROR(('Allocation'!$G$45-RiskFree)/'Allocation'!$N$45,"")
A46: Max-Sharpe* | B46: ='Allocation'!$E$33 | C46: ='Allocation'!$E$34 | D46: ='Allocation'!$E$35 | E46: ='Allocation'!$E$36 | F46: ='Allocation'!$E$37 | G46: =SUMPRODUCT(B46:F46,B42:F42) | H46: =SUMPRODUCT(B46:F46,'Risk & Return'!$B$33:$F$33) | I46: =SUMPRODUCT(B46:F46,'Risk & Return'!$B$34:$F$34) | J46: =SUMPRODUCT(B46:F46,'Risk & Return'!$B$35:$F$35) | K46: =SUMPRODUCT(B46:F46,'Risk & Return'!$B$36:$F$36) | L46: =SUMPRODUCT(B46:F46,'Risk & Return'!$B$37:$F$37) | M46: =SUMPRODUCT(B46:F46,H46:L46) | N46: =SQRT('Allocation'!$M$46) | O46: =IFERROR(('Allocation'!$G$46-RiskFree)/'Allocation'!$N$46,"")
A47: Min-volatility* | B47: ='Allocation'!$F$33 | C47: ='Allocation'!$F$34 | D47: ='Allocation'!$F$35 | E47: ='Allocation'!$F$36 | F47: ='Allocation'!$F$37 | G47: =SUMPRODUCT(B47:F47,B42:F42) | H47: =SUMPRODUCT(B47:F47,'Risk & Return'!$B$33:$F$33) | I47: =SUMPRODUCT(B47:F47,'Risk & Return'!$B$34:$F$34) | J47: =SUMPRODUCT(B47:F47,'Risk & Return'!$B$35:$F$35) | K47: =SUMPRODUCT(B47:F47,'Risk & Return'!$B$36:$F$36) | L47: =SUMPRODUCT(B47:F47,'Risk & Return'!$B$37:$F$37) | M47: =SUMPRODUCT(B47:F47,H47:L47) | N47: =SQRT('Allocation'!$M$47) | O47: =IFERROR(('Allocation'!$G$47-RiskFree)/'Allocation'!$N$47,"")
...

Sheet Rebalancing
A1: REBALANCING
A2: What to buy, sell or hold to reach the recommended allocation
A3: Portfolio Allocation Optimizer - v1.0
A5: Overview | B5: Scenario Inputs | C5: Scenario Output | D5: Risk & Return | E5: Allocation | F5: Rebalancing | G5: Dashboard | H5: Formula Guide
A7: How to read this sheet
A8: WHAT THIS SHEET TELLS YOU: the exact trades to move from your current portfolio to the recommended one (chosen on the Allocation sheet, Step 5).
A9: HOW TO READ IT: Buy/Sell amount = Target value - Current value (positive = buy, negative = sell). If the weight gap is small (within 1%), the action is Hold so you don't trade on noise.
A10: The Reason column explains each action in plain language (risk, scenario and target weight).
A13: Asset | B13: Current value (KWD) | C13: Current weight | D13: Recommended weight | E13: Target value (KWD) | F13: Buy / Sell (KWD) | G13: Action | H13: Reason
A14: SMI (Swiss Market Index) | B14: ='Scenario Output'!$I$15 | C14: ='Scenario Output'!$G$15 | D14: ='Allocation'!$B$57 | E14: ='Allocation'!$B$57*TotalInvested | F14: =$E$14-$B$14 | G14: =IF(ABS('Allocation'!$B$57-'Scenario Output'!$G$15)<=0.01,"Hold",IF('Allocation'!$B$57>'Scenario Output'!$G$15,"Buy","Sell")) | H14: =IF($G$14="Hold","SMI (Swiss Market Index) is already near target - no trade needed.",IF($G$14="Buy","Increase SMI (Swiss Market Index) because "&IF('Risk & Return'!$C$17<=IFERROR(AVERAGE('Risk & Return'!$C$17:$C$21),0),"it is a calmer asset that lowers portfolio volatility","it improves long-term return per unit of risk")&".","Reduce SMI (Swiss Market Index) because "&IF('Scenario Output'!$F$15<0,"it was weak in this scenario and its weight is above target","its weight is above target and scenario-adjusted risk is high")&"."))
A15: S&P 500 | B15: ='Scenario Output'!$I$16 | C15: ='Scenario Output'!$G$16 | D15: ='Allocation'!$B$58 | E15: ='Allocation'!$B$58*TotalInvested | F15: =$E$15-$B$15 | G15: =IF(ABS('Allocation'!$B$58-'Scenario Output'!$G$16)<=0.01,"Hold",IF('Allocation'!$B$58>'Scenario Output'!$G$16,"Buy","Sell")) | H15: =IF($G$15="Hold","S&P 500 is already near target - no trade needed.",IF($G$15="Buy","Increase S&P 500 because "&IF('Risk & Return'!$C$18<=IFERROR(AVERAGE('Risk & Return'!$C$17:$C$21),0),"it is a calmer asset that lowers portfolio volatility","it improves long-term return per unit of risk")&".","Reduce S&P 500 because "&IF('Scenario Output'!$F$16<0,"it was weak in this scenario and its weight is above target","its weight is above target and scenario-adjusted risk is high")&"."))
A16: SXI Real Estate Funds Broad Index | B16: ='Scenario Output'!$I$17 | C16: ='Scenario Output'!$G$17 | D16: ='Allocation'!$B$59 | E16: ='Allocation'!$B$59*TotalInvested | F16: =$E$16-$B$16 | G16: =IF(ABS('Allocation'!$B$59-'Scenario Output'!$G$17)<=0.01,"Hold",IF('Allocation'!$B$59>'Scenario Output'!$G$17,"Buy","Sell")) | H16: =IF($G$16="Hold","SXI Real Estate Funds Broad Index is already near target - no trade needed.",IF($G$16="Buy","Increase SXI Real Estate Funds Broad Index because "&IF('Risk & Return'!$C$19<=IFERROR(AVERAGE('Risk & Return'!$C$17:$C$21),0),"it is a calmer asset that lowers portfolio volatility","it improves long-term return per unit of risk")&".","Reduce SXI Real Estate Funds Broad Index because "&IF('Scenario Output'!$F$17<0,"it was weak in this scenario and its weight is above target","its weight is above target and scenario-adjusted risk is high")&"."))
A17: Gold | B17: ='Scenario Output'!$I$18 | C17: ='Scenario Output'!$G$18 | D17: ='Allocation'!$B$60 | E17: ='Allocation'!$B$60*TotalInvested | F17: =$E$17-$B$17 | G17: =IF(ABS('Allocation'!$B$60-'Scenario Output'!$G$18)<=0.01,"Hold",IF('Allocation'!$B$60>'Scenario Output'!$G$18,"Buy","Sell")) | H17: =IF($G$17="Hold","Gold is already near target - no trade needed.",IF($G$17="Buy","Increase Gold because "&IF('Risk & Return'!$C$20<=IFERROR(AVERAGE('Risk & Return'!$C$17:$C$21),0),"it is a calmer asset that lowers portfolio volatility","it improves long-term return per unit of risk")&".","Reduce Gold because "&IF('Scenario Output'!$F$18<0,"it was weak in this scenario and its weight is above target","its weight is above target and scenario-adjusted risk is high")&"."))
A18: US Government Bonds | B18: ='Scenario Output'!$I$19 | C18: ='Scenario Output'!$G$19 | D18: ='Allocation'!$B$61 | E18: ='Allocation'!$B$61*TotalInvested | F18: =$E$18-$B$18 | G18: =IF(ABS('Allocation'!$B$61-'Scenario Output'!$G$19)<=0.01,"Hold",IF('Allocation'!$B$61>'Scenario Output'!$G$19,"Buy","Sell")) | H18: =IF($G$18="Hold","US Government Bonds is already near target - no trade needed.",IF($G$18="Buy","Increase US Government Bonds because "&IF('Risk & Return'!$C$21<=IFERROR(AVERAGE('Risk & Return'!$C$17:$C$21),0),"it is a calmer asset that lowers portfolio volatility","it improves long-term return per unit of risk")&".","Reduce US Government Bonds because "&IF('Scenario Output'!$F$19<0,"it was weak in this scenario and its weight is above target","its weight is above target and scenario-adjusted risk is high")&"."))
A19: Total | B19: =SUM('Scenario Output'!$I$15:$I$19) | C19: =SUM('Scenario Output'!$G$15:$G$19) | D19: =SUM('Allocation'!$B$57:$B$61) | E19: =SUM('Rebalancing'!$E$14:$E$18) | F19: =SUM('Rebalancing'!$F$14:$F$18)
A20: The Buy/Sell column should sum to about 0 (a rebalance moves money between assets, it does not add or remove cash).

Sheet Dashboard
A1: DASHBOARD
A2: Scenario impact, allocation and risk/return at a glance
A3: Portfolio Allocation Optimizer - v1.0
A5: Overview | B5: Scenario Inputs | C5: Scenario Output | D5: Risk & Return | E5: Allocation | F5: Rebalancing | G5: Dashboard | H5: Formula Guide
A7: How to read this sheet
A8: WHAT THIS SHEET SHOWS: your current vs recommended allocation, how each asset performed in the scenario, how much each contributed to the portfolio return, and where each portfolio sits on the risk/return map.
A9: It is a summary -- all the detail (and every formula) lives on the Scenario Output, Risk & Return and Allocation sheets. Charts update automatically when you change the inputs.
A12: Scenario summary
A13: Scenario | C13: ='Scenario Inputs'!$C$16 | G13: Portfolio scenario return | I13: ='Scenario Output'!$H$20
A14: Period | C14: ='Scenario Inputs'!$C$17&" to "&'Scenario Inputs'!$C$18 | G14: What happened | I14: ="In the "&'Scenario Inputs'!$C$16&" scenario, the portfolio returned "&TEXT('Scenario Output'!$H$20,"0.0%")&". "&INDEX(E17:E21,MATCH(MAX(G17:G21),G17:G21,0))&" helped most; "&INDEX(E17:E21,MATCH(MIN(G17:G21),G17:G21,0))&" detracted most."
A16: Asset | B16: Current | C16: Recommended | E16: Asset | F16: Scenario return | G16: Contribution | I16: Point | J16: Risk | K16: Return
A17: SMI | B17: ='Allocation'!$B$33 | C17: ='Allocation'!$B$57 | E17: SMI | F17: ='Scenario Output'!$F$15 | G17: ='Scenario Output'!$H$15 | I17: Current | J17: ='Allocation'!$N$43 | K17: ='Allocation'!$G$43
A18: S&P 500 | B18: ='Allocation'!$B$34 | C18: ='Allocation'!$B$58 | E18: S&P 500 | F18: ='Scenario Output'!$F$16 | G18: ='Scenario Output'!$H$16 | I18: Equal-weight | J18: ='Allocation'!$N$44 | K18: ='Allocation'!$G$44
A19: SXI RE | B19: ='Allocation'!$B$35 | C19: ='Allocation'!$B$59 | E19: SXI RE | F19: ='Scenario Output'!$F$17 | G19: ='Scenario Output'!$H$17 | I19: Custom target | J19: ='Allocation'!$N$45 | K19: ='Allocation'!$G$45
A20: Gold | B20: ='Allocation'!$B$36 | C20: ='Allocation'!$B$60 | E20: Gold | F20: ='Scenario Output'!$F$18 | G20: ='Scenario Output'!$H$18 | I20: Max-Sharpe* | J20: ='Allocation'!$N$46 | K20: ='Allocation'!$G$46
A21: US Bonds | B21: ='Allocation'!$B$37 | C21: ='Allocation'!$B$61 | E21: US Bonds | F21: ='Scenario Output'!$F$19 | G21: ='Scenario Output'!$H$19 | I21: Min-volatility* | J21: ='Allocation'!$N$47 | K21: ='Allocation'!$G$47
I22: Scenario-stressed | J22: ='Allocation'!$N$48 | K22: ='Allocation'!$G$48
I23: SMI | J23: ='Risk & Return'!$C$17 | K23: ='Risk & Return'!$B$17
I24: S&P 500 | J24: ='Risk & Return'!$C$18 | K24: ='Risk & Return'!$B$18
I25: SXI RE | J25: ='Risk & Return'!$C$19 | K25: ='Risk & Return'!$B$19
I26: Gold | J26: ='Risk & Return'!$C$20 | K26: ='Risk & Return'!$B$20
I27: US Bonds | J27: ='Risk & Return'!$C$21 | K27: ='Risk & Return'!$B$21

Sheet Formula Guide
A1: FORMULA GUIDE
A2: Every calculation, in plain language
A3: Portfolio Allocation Optimizer - v1.0
A5: Overview | B5: Scenario Inputs | C5: Scenario Output | D5: Risk & Return | E5: Allocation | F5: Rebalancing | G5: Dashboard | H5: Formula Guide
A7: How to read this sheet
A8: This sheet explains every formula the workbook uses. Read it once and you can audit any number in the tool.
A11: Concept | C11: Formula | F11: What it means
A12: Asset return (local) | C12: End price / Start price - 1 | F12: The price move in the asset's own currency over the scenario. Example: 110/100 - 1 = +10%.
A13: FX return | C13: End FX rate / Start FX rate - 1 | F13: The change in the value of the asset's currency against your base currency. If your base currency strengthens, foreign assets are worth less to you (a negative FX return).
A14: Currency-adjusted return | C14: (1 + Asset return) x (1 + FX return) - 1 | F14: What you actually earned in your own currency: the price move and the currency move combined. Example: (1+10%) x (1+2%) - 1 = +12.2%.
A15: Weight | C15: Asset value / Total portfolio value | F15: Each asset's share of the portfolio. All weights add up to 100%.
A16: Contribution to return | C16: Weight x Currency-adjusted return | F16: How much an asset added to the total return. A 20% weight earning +12% contributes +2.4%.
A17: Portfolio return | C17: Sum of all contributions | F17: Add up every asset's contribution to get the whole portfolio's return for the scenario.
A18: Bond return | C18: (End price - Start price + Coupon earned) / Start price | F18: Bonds earn a coupon as well as moving in price. Coupon earned = Face x Coupon rate x (Days held / 365). Adding the coupon to the price change gives the bond's total return.
A19: Expected return (long-term) | C19: Your annual view per asset (an input) | F19: The long-run return you expect from each asset, separate from the one-off scenario. Used for the recommendation.
A20: Volatility (risk) | C20: How much an asset's return bounces around (an input, annual) | F20: A higher number means a bumpier ride. It is the standard measure of risk.
A21: Correlation | C21: How two assets move together (-1 to +1) | F21: +1 = always move together, 0 = unrelated, -1 = move opposite. Mixing low-correlation assets lowers portfolio risk -- that is diversification.
A22: Portfolio volatility | C22: Built from the weights and the covariance table | F22: Covariance = Vol(i) x Vol(j) x Correlation(i,j). The portfolio's risk adds up every pair's combined risk, and falls when assets do not move together. Shown on the Allocation sheet for each allocation.
... A28: Rebalancing trade | C28: Target value - Current value; Target value = Recommended weight x Total invested | F28: The amount to buy (positive) or sell (negative) to reach the recommended allocation. Small gaps are left as Hold so you do not trade on noise.
