Workbook

Sheet Home
A1: Institutional Financial Ratio Analysis
A2: A fully formula-driven, auditable ratio-analysis platform · v1.0
A4: Company Profile
A5: Company name | B5: <Company name>
A6: Ticker | B6: <TICKER>
A7: Industry | B7: <Industry>
A8: Reporting currency | B8: USD
A9: Units | B9: millions
A10: Fiscal year end | B10: 31 December
A11: Analysis date | B11: =TODAY()
A13: Navigation
A14: Dashboard | B14: Inputs | C14: Common Size | D14: Profitability | E14: Liquidity | F14: Solvency | G14: Efficiency | H14: Growth
A15: Valuation | B15: Capital Allocation | C15: Quality | D15: Benchmarking | E15: Guide | F15: Quality Control
A17: LEGEND
B18: Input — editable (yellow)
B19: Formula / helper — protected (blue)
B20: Output — read-only result (green)
B21: Error / flag (red)
A22: Strong | B22: Moderate | C22: Weak | D22: ← traffic-light classification
A24: About This Workbook
A25: • 15 sheets covering every major ratio family plus quality scores, peer benchmarking, an interpretation guide and automated quality-control checks.
A26: • Every output is a live formula that traces back to the Inputs sheet — no hardcoded results. Yellow cells are the only ones you edit.
A27: • Calculations are deliberately broken into helper rows and short formulas so each ratio is understandable without opening Excel's formula auditor.
A28: • Classifications, trend arrows and commentary update automatically as you change the inputs.

Sheet Dashboard
A1: EXECUTIVE DASHBOARD
A2: <Company name> — quality scorecard & key signals
A3: Institutional Financial Ratio Analysis · v1.0
A5: Dashboard | B5: Inputs | C5: Common Size | D5: Profitability | E5: Liquidity | F5: Solvency | G5: Efficiency | H5: Growth
A6: Valuation | B6: Capital Allocation | C6: Quality | D6: Benchmarking | E6: Guide | F6: Quality Control
A7: Quality Scorecard (0–100, higher = better) | F7: Key-Metric Trends
A8: Category | B8: Score | C8: Assessment | F8: Metric | G8: Latest | H8: Trend | I8: Read
A9: Profitability | B9: =IFERROR(ROUND(AVERAGE(MIN('Profitability'!$K$14/0.2,1),MIN('Profitability'!$K$18/0.15,1),MIN('Profitability'!$K$20/0.12,1),MIN('Profitability'!$K$12/0.18,1))*100,0),"") | C9: =IF(ISNUMBER($B$9),CHOOSE(1+($B$9>=40)+($B$9>=70),"Weak","Moderate","Strong"),"") | F9: ROE | G9: ='Profitability'!$K$18 | H9: =IF(AND(ISNUMBER('Profitability'!$K$18),ISNUMBER('Profitability'!$J$18)),CHOOSE(2+('Profitability'!$K$18>'Profitability'!$J$18)-('Profitability'!$K$18<'Profitability'!$J$18),"▼","►","▲"),"") | I9: ='Profitability'!$R$18
A10: Liquidity | B10: =IFERROR(ROUND(AVERAGE(MIN('Liquidity'!$K$10/2,1),MIN('Liquidity'!$K$12/0.5,1),MIN('Liquidity'!$K$19/1,1))*100,0),"") | C10: =IF(ISNUMBER($B$10),CHOOSE(1+($B$10>=40)+($B$10>=70),"Weak","Moderate","Strong"),"") | F10: Operating margin | G10: ='Profitability'!$K$12 | H10: =IF(AND(ISNUMBER('Profitability'!$K$12),ISNUMBER('Profitability'!$J$12)),CHOOSE(2+('Profitability'!$K$12>'Profitability'!$J$12)-('Profitability'!$K$12<'Profitability'!$J$12),"▼","►","▲"),"") | I10: ='Profitability'!$R$12
A11: Solvency | B11: =IFERROR(ROUND(AVERAGE(MIN('Solvency'!$K$21/6,1),MIN('Solvency'!$K$14,1),MIN(MAX(0,1-'Solvency'!$K$18/4),1))*100,0),"") | C11: =IF(ISNUMBER($B$11),CHOOSE(1+($B$11>=40)+($B$11>=70),"Weak","Moderate","Strong"),"") | F11: Revenue growth | G11: ='Growth'!$K$10 | H11: =IF(AND(ISNUMBER('Growth'!$K$10),ISNUMBER('Growth'!$J$10)),CHOOSE(2+('Growth'!$K$10>'Growth'!$J$10)-('Growth'!$K$10<'Growth'!$J$10),"▼","►","▲"),"") | I11: ='Growth'!$R$10
A12: Efficiency | B12: =IFERROR(ROUND(AVERAGE(MIN('Efficiency'!$K$10/1,1),MIN('Efficiency'!$K$12/8,1),MIN('Efficiency'!$K$13/10,1))*100,0),"") | C12: =IF(ISNUMBER($B$12),CHOOSE(1+($B$12>=40)+($B$12>=70),"Weak","Moderate","Strong"),"") | F12: Net debt / EBITDA | G12: ='Solvency'!$K$18 | H12: =IF(AND(ISNUMBER('Solvency'!$K$18),ISNUMBER('Solvency'!$J$18)),CHOOSE(2+('Solvency'!$K$18>'Solvency'!$J$18)-('Solvency'!$K$18<'Solvency'!$J$18),"▼","►","▲"),"") | I12: ='Solvency'!$R$18
A13: Growth | B13: =IFERROR(ROUND(AVERAGE(MIN('Growth'!$C$20/0.1,1),MIN('Growth'!$C$23/0.1,1))*100,0),"") | C13: =IF(ISNUMBER($B$13),CHOOSE(1+($B$13>=40)+($B$13>=70),"Weak","Moderate","Strong"),"") | F13: FCF margin | G13: ='Profitability'!$K$15 | H13: =IF(AND(ISNUMBER('Profitability'!$K$15),ISNUMBER('Profitability'!$J$15)),CHOOSE(2+('Profitability'!$K$15>'Profitability'!$J$15)-('Profitability'!$K$15<'Profitability'!$J$15),"▼","►","▲"),"") | I13: ='Profitability'!$R$15
A14: Valuation (cheapness) | B14: =IFERROR(ROUND(AVERAGE(MIN('Valuation'!$K$31/0.06,1),MIN('Valuation'!$K$19/0.05,1))*100,0),"") | C14: =IF(ISNUMBER($B$14),CHOOSE(1+($B$14>=40)+($B$14>=70),"Weak","Moderate","Strong"),"") | F14: ROIC | G14: ='Profitability'!$K$20 | H14: =IF(AND(ISNUMBER('Profitability'!$K$20),ISNUMBER('Profitability'!$J$20)),CHOOSE(2+('Profitability'!$K$20>'Profitability'!$J$20)-('Profitability'!$K$20<'Profitability'!$J$20),"▼","►","▲"),"") | I14: ='Profitability'!$R$20
A15: OVERALL QUALITY SCORE | B15: =IFERROR(ROUND(AVERAGE(B9:B14),0),"") | C15: =IF(ISNUMBER($B$15),CHOOSE(1+($B$15>=40)+($B$15>=70),"Weak","Moderate","Strong"),"")
A16: Headline Metrics (latest year)
A17: Revenue | B17: Net income | C17: FCF | D17: ROIC − WACC | E17: Altman Z | F17: Piotroski F
A18: ='Inputs'!$K$10 | B18: ='Inputs'!$K$21 | C18: ='Inputs'!$K$48 | D18: =IFERROR('Profitability'!$K$20-'Inputs'!$B$82,"") | E18: ='Quality'!$K$15 | F18: ='Quality'!$K$33
A20: Automated Observations
A21: =IFERROR("» Profitability: ROE "&TEXT('Profitability'!$K$18,"0.0%")&" ("&'Profitability'!$R$18&"), ROIC "&TEXT('Profitability'!$K$20,"0.0%")&" vs WACC "&TEXT('Inputs'!$B$82,"0.0%")&".","(insufficient data — populate inputs)")
A22: =IFERROR("» Margins: operating margin "&TEXT('Profitability'!$K$12,"0.0%")&" — "&'Profitability'!$R$12&" versus history.","(insufficient data — populate inputs)")
A23: =IFERROR("» Leverage: net debt / EBITDA "&TEXT('Solvency'!$K$18,"0.0")&"x — "&'Solvency'!$R$18&" risk.","(insufficient data — populate inputs)")
A24: =IFERROR("» Cash: FCF margin "&TEXT('Profitability'!$K$15,"0.0%")&" ("&'Profitability'!$R$15&"); FCF "&TEXT('Inputs'!$K$48,"#,##0")&".","(insufficient data — populate inputs)")
A25: =IFERROR("» Quality: Altman Z "&TEXT('Quality'!$K$15,"0.0")&" ("&'Quality'!$R$15&"), Piotroski "&TEXT('Quality'!$K$33,"0")&"/9, Beneish "&'Quality'!$R$44&".","(insufficient data — populate inputs)")
A26: =IFERROR("» Data health: "&'Quality Control'!$B$8&".","(insufficient data — populate inputs)")

Sheet Inputs
A1: RAW FINANCIAL INPUTS
A2: 10 historical + 5 forecast years — the single data-entry layer
A3: Institutional Financial Ratio Analysis · v1.0
A5: Dashboard | B5: Inputs | C5: Common Size | D5: Profitability | E5: Liquidity | F5: Solvency | G5: Efficiency | H5: Growth
A6: Valuation | B6: Capital Allocation | C6: Quality | D6: Benchmarking | E6: Guide | F6: Quality Control
A7: All figures in USD millions unless stated; (F) = forecast year.
A8: Metric | B8: FY2015 | C8: FY2016 | D8: FY2017 | E8: FY2018 | F8: FY2019 | G8: FY2020 | H8: FY2021 | I8: FY2022 | J8: FY2023 | K8: FY2024 | L8: FY2025 (F) | M8: FY2026 (F) | N8: FY2027 (F) | O8: FY2028 (F) | P8: FY2029 (F)
A9: Income Statement
A10: Revenue
A11: Cost of goods sold
A12: Gross profit | B12: ='Inputs'!$B$10-'Inputs'!$B$11 | C12: ='Inputs'!$C$10-'Inputs'!$C$11 | D12: ='Inputs'!$D$10-'Inputs'!$D$11 | E12: ='Inputs'!$E$10-'Inputs'!$E$11 | F12: ='Inputs'!$F$10-'Inputs'!$F$11 | G12: ='Inputs'!$G$10-'Inputs'!$G$11 | H12: ='Inputs'!$H$10-'Inputs'!$H$11 | I12: ='Inputs'!$I$10-'Inputs'!$I$11 | J12: ='Inputs'!$J$10-'Inputs'!$J$11 | K12: ='Inputs'!$K$10-'Inputs'!$K$11 | L12: ='Inputs'!$L$10-'Inputs'!$L$11 | M12: ='Inputs'!$M$10-'Inputs'!$M$11 | N12: ='Inputs'!$N$10-'Inputs'!$N$11 | O12: ='Inputs'!$O$10-'Inputs'!$O$11 | P12: ='Inputs'!$P$10-'Inputs'!$P$11
A13: Operating expenses (ex-D&A)
A14: EBITDA | B14: ='Inputs'!$B$12-'Inputs'!$B$13 | C14: ='Inputs'!$C$12-'Inputs'!$C$13 | D14: ='Inputs'!$D$12-'Inputs'!$D$13 | E14: ='Inputs'!$E$12-'Inputs'!$E$13 | F14: ='Inputs'!$F$12-'Inputs'!$F$13 | G14: ='Inputs'!$G$12-'Inputs'!$G$13 | H14: ='Inputs'!$H$12-'Inputs'!$H$13 | I14: ='Inputs'!$I$12-'Inputs'!$I$13 | J14: ='Inputs'!$J$12-'Inputs'!$J$13 | K14: ='Inputs'!$K$12-'Inputs'!$K$13 | L14: ='Inputs'!$L$12-'Inputs'!$L$13 | M14: ='Inputs'!$M$12-'Inputs'!$M$13 | N14: ='Inputs'!$N$12-'Inputs'!$N$13 | O14: ='Inputs'!$O$12-'Inputs'!$O$13 | P14: ='Inputs'!$P$12-'Inputs'!$P$13
A15: Depreciation & amortisation
A16: EBIT (operating income) | B16: ='Inputs'!$B$14-'Inputs'!$B$15 | C16: ='Inputs'!$C$14-'Inputs'!$C$15 | D16: ='Inputs'!$D$14-'Inputs'!$D$15 | E16: ='Inputs'!$E$14-'Inputs'!$E$15 | F16: ='Inputs'!$F$14-'Inputs'!$F$15 | G16: ='Inputs'!$G$14-'Inputs'!$G$15 | H16: ='Inputs'!$H$14-'Inputs'!$H$15 | I16: ='Inputs'!$I$14-'Inputs'!$I$15 | J16: ='Inputs'!$J$14-'Inputs'!$J$15 | K16: ='Inputs'!$K$14-'Inputs'!$K$15 | L16: ='Inputs'!$L$14-'Inputs'!$L$15 | M16: ='Inputs'!$M$14-'Inputs'!$M$15 | N16: ='Inputs'!$N$14-'Inputs'!$N$15 | O16: ='Inputs'!$O$14-'Inputs'!$O$15 | P16: ='Inputs'!$P$14-'Inputs'!$P$15
A17: Interest expense
A18: Other income / (expense)
A19: Pre-tax income | B19: ='Inputs'!$B$16-'Inputs'!$B$17+'Inputs'!$B$18 | C19: ='Inputs'!$C$16-'Inputs'!$C$17+'Inputs'!$C$18 | D19: ='Inputs'!$D$16-'Inputs'!$D$17+'Inputs'!$D$18 | E19: ='Inputs'!$E$16-'Inputs'!$E$17+'Inputs'!$E$18 | F19: ='Inputs'!$F$16-'Inputs'!$F$17+'Inputs'!$F$18 | G19: ='Inputs'!$G$16-'Inputs'!$G$17+'Inputs'!$G$18 | H19: ='Inputs'!$H$16-'Inputs'!$H$17+'Inputs'!$H$18 | I19: ='Inputs'!$I$16-'Inputs'!$I$17+'Inputs'!$I$18 | J19: ='Inputs'!$J$16-'Inputs'!$J$17+'Inputs'!$J$18 | K19: ='Inputs'!$K$16-'Inputs'!$K$17+'Inputs'!$K$18 | L19: ='Inputs'!$L$16-'Inputs'!$L$17+'Inputs'!$L$18 | M19: ='Inputs'!$M$16-'Inputs'!$M$17+'Inputs'!$M$18 | N19: ='Inputs'!$N$16-'Inputs'!$N$17+'Inputs'!$N$18 | O19: ='Inputs'!$O$16-'Inputs'!$O$17+'Inputs'!$O$18 | P19: ='Inputs'!$P$16-'Inputs'!$P$17+'Inputs'!$P$18
A20: Income tax expense
A21: Net income | B21: ='Inputs'!$B$19-'Inputs'!$B$20 | C21: ='Inputs'!$C$19-'Inputs'!$C$20 | D21: ='Inputs'!$D$19-'Inputs'!$D$20 | E21: ='Inputs'!$E$19-'Inputs'!$E$20 | F21: ='Inputs'!$F$19-'Inputs'!$F$20 | G21: ='Inputs'!$G$19-'Inputs'!$G$20 | H21: ='Inputs'!$H$19-'Inputs'!$H$20 | I21: ='Inputs'!$I$19-'Inputs'!$I$20 | J21: ='Inputs'!$J$19-'Inputs'!$J$20 | K21: ='Inputs'!$K$19-'Inputs'!$K$20 | L21: ='Inputs'!$L$19-'Inputs'!$L$20 | M21: ='Inputs'!$M$19-'Inputs'!$M$20 | N21: ='Inputs'!$N$19-'Inputs'!$N$20 | O21: ='Inputs'!$O$19-'Inputs'!$O$20 | P21: ='Inputs'!$P$19-'Inputs'!$P$20
A22: Balance Sheet — Assets
A23: Cash & equivalents
A24: Accounts receivable
A25: Inventory
A26: Other current assets
A27: Total current assets | B27: =SUM('Inputs'!$B$23,'Inputs'!$B$24,'Inputs'!$B$25,'Inputs'!$B$26) | C27: =SUM('Inputs'!$C$23,'Inputs'!$C$24,'Inputs'!$C$25,'Inputs'!$C$26) | D27: =SUM('Inputs'!$D$23,'Inputs'!$D$24,'Inputs'!$D$25,'Inputs'!$D$26) | E27: =SUM('Inputs'!$E$23,'Inputs'!$E$24,'Inputs'!$E$25,'Inputs'!$E$26) | F27: =SUM('Inputs'!$F$23,'Inputs'!$F$24,'Inputs'!$F$25,'Inputs'!$F$26) | G27: =SUM('Inputs'!$G$23,'Inputs'!$G$24,'Inputs'!$G$25,'Inputs'!$G$26) | H27: =SUM('Inputs'!$H$23,'Inputs'!$H$24,'Inputs'!$H$25,'Inputs'!$H$26) | I27: =SUM('Inputs'!$I$23,'Inputs'!$I$24,'Inputs'!$I$25,'Inputs'!$I$26) | J27: =SUM('Inputs'!$J$23,'Inputs'!$J$24,'Inputs'!$J$25,'Inputs'!$J$26) | K27: =SUM('Inputs'!$K$23,'Inputs'!$K$24,'Inputs'!$K$25,'Inputs'!$K$26) | L27: =SUM('Inputs'!$L$23,'Inputs'!$L$24,'Inputs'!$L$25,'Inputs'!$L$26) | M27: =SUM('Inputs'!$M$23,'Inputs'!$M$24,'Inputs'!$M$25,'Inputs'!$M$26) | N27: =SUM('Inputs'!$N$23,'Inputs'!$N$24,'Inputs'!$N$25,'Inputs'!$N$26) | O27: =SUM('Inputs'!$O$23,'Inputs'!$O$24,'Inputs'!$O$25,'Inputs'!$O$26) | P27: =SUM('Inputs'!$P$23,'Inputs'!$P$24,'Inputs'!$P$25,'Inputs'!$P$26)
A28: Property, plant & equipment (net)
A29: Goodwill & intangibles
A30: Other non-current assets
A31: Total non-current assets | B31: =SUM('Inputs'!$B$28,'Inputs'!$B$29,'Inputs'!$B$30) | C31: =SUM('Inputs'!$C$28,'Inputs'!$C$29,'Inputs'!$C$30) | D31: =SUM('Inputs'!$D$28,'Inputs'!$D$29,'Inputs'!$D$30) | E31: =SUM('Inputs'!$E$28,'Inputs'!$E$29,'Inputs'!$E$30) | F31: =SUM('Inputs'!$F$28,'Inputs'!$F$29,'Inputs'!$F$30) | G31: =SUM('Inputs'!$G$28,'Inputs'!$G$29,'Inputs'!$G$30) | H31: =SUM('Inputs'!$H$28,'Inputs'!$H$29,'Inputs'!$H$30) | I31: =SUM('Inputs'!$I$28,'Inputs'!$I$29,'Inputs'!$I$30) | J31: =SUM('Inputs'!$J$28,'Inputs'!$J$29,'Inputs'!$J$30) | K31: =SUM('Inputs'!$K$28,'Inputs'!$K$29,'Inputs'!$K$30) | L31: =SUM('Inputs'!$L$28,'Inputs'!$L$29,'Inputs'!$L$30) | M31: =SUM('Inputs'!$M$28,'Inputs'!$M$29,'Inputs'!$M$30) | N31: =SUM('Inputs'!$N$28,'Inputs'!$N$29,'Inputs'!$N$30) | O31: =SUM('Inputs'!$O$28,'Inputs'!$O$29,'Inputs'!$O$30) | P31: =SUM('Inputs'!$P$28,'Inputs'!$P$29,'Inputs'!$P$30)
A32: TOTAL ASSETS | B32: ='Inputs'!$B$27+'Inputs'!$B$31 | C32: ='Inputs'!$C$27+'Inputs'!$C$31 | D32: ='Inputs'!$D$27+'Inputs'!$D$31 | E32: ='Inputs'!$E$27+'Inputs'!$E$31 | F32: ='Inputs'!$F$27+'Inputs'!$F$31 | G32: ='Inputs'!$G$27+'Inputs'!$G$31 | H32: ='Inputs'!$H$27+'Inputs'!$H$31 | I32: ='Inputs'!$I$27+'Inputs'!$I$31 | J32: ='Inputs'!$J$27+'Inputs'!$J$31 | K32: ='Inputs'!$K$27+'Inputs'!$K$31 | L32: ='Inputs'!$L$27+'Inputs'!$L$31 | M32: ='Inputs'!$M$27+'Inputs'!$M$31 | N32: ='Inputs'!$N$27+'Inputs'!$N$31 | O32: ='Inputs'!$O$27+'Inputs'!$O$31 | P32: ='Inputs'!$P$27+'Inputs'!$P$31
A33: Balance Sheet — Liabilities & Equity
A34: Accounts payable
A35: Short-term debt
A36: Other current liabilities
A37: Total current liabilities | B37: =SUM('Inputs'!$B$34,'Inputs'!$B$35,'Inputs'!$B$36) | C37: =SUM('Inputs'!$C$34,'Inputs'!$C$35,'Inputs'!$C$36) | D37: =SUM('Inputs'!$D$34,'Inputs'!$D$35,'Inputs'!$D$36) | E37: =SUM('Inputs'!$E$34,'Inputs'!$E$35,'Inputs'!$E$36) | F37: =SUM('Inputs'!$F$34,'Inputs'!$F$35,'Inputs'!$F$36) | G37: =SUM('Inputs'!$G$34,'Inputs'!$G$35,'Inputs'!$G$36) | H37: =SUM('Inputs'!$H$34,'Inputs'!$H$35,'Inputs'!$H$36) | I37: =SUM('Inputs'!$I$34,'Inputs'!$I$35,'Inputs'!$I$36) | J37: =SUM('Inputs'!$J$34,'Inputs'!$J$35,'Inputs'!$J$36) | K37: =SUM('Inputs'!$K$34,'Inputs'!$K$35,'Inputs'!$K$36) | L37: =SUM('Inputs'!$L$34,'Inputs'!$L$35,'Inputs'!$L$36) | M37: =SUM('Inputs'!$M$34,'Inputs'!$M$35,'Inputs'!$M$36) | N37: =SUM('Inputs'!$N$34,'Inputs'!$N$35,'Inputs'!$N$36) | O37: =SUM('Inputs'!$O$34,'Inputs'!$O$35,'Inputs'!$O$36) | P37: =SUM('Inputs'!$P$34,'Inputs'!$P$35,'Inputs'!$P$36)
A38: Long-term debt
A39: Other non-current liabilities
A40: Total non-current liabilities | B40: ='Inputs'!$B$38+'Inputs'!$B$39 | C40: ='Inputs'!$C$38+'Inputs'!$C$39 | D40: ='Inputs'!$D$38+'Inputs'!$D$39 | E40: ='Inputs'!$E$38+'Inputs'!$E$39 | F40: ='Inputs'!$F$38+'Inputs'!$F$39 | G40: ='Inputs'!$G$38+'Inputs'!$G$39 | H40: ='Inputs'!$H$38+'Inputs'!$H$39 | I40: ='Inputs'!$I$38+'Inputs'!$I$39 | J40: ='Inputs'!$J$38+'Inputs'!$J$39 | K40: ='Inputs'!$K$38+'Inputs'!$K$39 | L40: ='Inputs'!$L$38+'Inputs'!$L$39 | M40: ='Inputs'!$M$38+'Inputs'!$M$39 | N40: ='Inputs'!$N$38+'Inputs'!$N$39 | O40: ='Inputs'!$O$38+'Inputs'!$O$39 | P40: ='Inputs'!$P$38+'Inputs'!$P$39
A41: TOTAL LIABILITIES | B41: ='Inputs'!$B$37+'Inputs'!$B$40 | C41: ='Inputs'!$C$37+'Inputs'!$C$40 | D41: ='Inputs'!$D$37+'Inputs'!$D$40 | E41: ='Inputs'!$E$37+'Inputs'!$E$40 | F41: ='Inputs'!$F$37+'Inputs'!$F$40 | G41: ='Inputs'!$G$37+'Inputs'!$G$40 | H41: ='Inputs'!$H$37+'Inputs'!$H$40 | I41: ='Inputs'!$I$37+'Inputs'!$I$40 | J41: ='Inputs'!$J$37+'Inputs'!$J$40 | K41: ='Inputs'!$K$37+'Inputs'!$K$40 | L41: ='Inputs'!$L$37+'Inputs'!$L$40 | M41: ='Inputs'!$M$37+'Inputs'!$M$40 | N41: ='Inputs'!$N$37+'Inputs'!$N$40 | O41: ='Inputs'!$O$37+'Inputs'!$O$40 | P41: ='Inputs'!$P$37+'Inputs'!$P$40
...

Sheet Common Size
A1: COMMON SIZE & TREND ANALYSIS
A2: Income statement vs revenue, balance sheet vs assets, indexed trend
A3: Institutional Financial Ratio Analysis · v1.0
A5: Dashboard | B5: Inputs | C5: Common Size | D5: Profitability | E5: Liquidity | F5: Solvency | G5: Efficiency | H5: Growth
A6: Valuation | B6: Capital Allocation | C6: Quality | D6: Benchmarking | E6: Guide | F6: Quality Control
A7: All figures in USD millions unless stated; (F) = forecast year.
A8: Line item | B8: FY2015 | C8: FY2016 | D8: FY2017 | E8: FY2018 | F8: FY2019 | G8: FY2020 | H8: FY2021 | I8: FY2022 | J8: FY2023 | K8: FY2024 | L8: FY2025 (F) | M8: FY2026 (F) | N8: FY2027 (F) | O8: FY2028 (F) | P8: FY2029 (F) | Q8: Trend | R8: Assessment
A9: Income Statement — Common Size (% of revenue)
A10: Revenue | B10: =IFERROR('Inputs'!$B$10/'Inputs'!$B$10,"") | C10: =IFERROR('Inputs'!$C$10/'Inputs'!$C$10,"") | D10: =IFERROR('Inputs'!$D$10/'Inputs'!$D$10,"") | E10: =IFERROR('Inputs'!$E$10/'Inputs'!$E$10,"") | F10: =IFERROR('Inputs'!$F$10/'Inputs'!$F$10,"") | G10: =IFERROR('Inputs'!$G$10/'Inputs'!$G$10,"") | H10: =IFERROR('Inputs'!$H$10/'Inputs'!$H$10,"") | I10: =IFERROR('Inputs'!$I$10/'Inputs'!$I$10,"") | J10: =IFERROR('Inputs'!$J$10/'Inputs'!$J$10,"") | K10: =IFERROR('Inputs'!$K$10/'Inputs'!$K$10,"") | L10: =IFERROR('Inputs'!$L$10/'Inputs'!$L$10,"") | M10: =IFERROR('Inputs'!$M$10/'Inputs'!$M$10,"") | N10: =IFERROR('Inputs'!$N$10/'Inputs'!$N$10,"") | O10: =IFERROR('Inputs'!$O$10/'Inputs'!$O$10,"") | P10: =IFERROR('Inputs'!$P$10/'Inputs'!$P$10,"")
A11: Cost of goods sold | B11: =IFERROR('Inputs'!$B$11/'Inputs'!$B$10,"") | C11: =IFERROR('Inputs'!$C$11/'Inputs'!$C$10,"") | D11: =IFERROR('Inputs'!$D$11/'Inputs'!$D$10,"") | E11: =IFERROR('Inputs'!$E$11/'Inputs'!$E$10,"") | F11: =IFERROR('Inputs'!$F$11/'Inputs'!$F$10,"") | G11: =IFERROR('Inputs'!$G$11/'Inputs'!$G$10,"") | H11: =IFERROR('Inputs'!$H$11/'Inputs'!$H$10,"") | I11: =IFERROR('Inputs'!$I$11/'Inputs'!$I$10,"") | J11: =IFERROR('Inputs'!$J$11/'Inputs'!$J$10,"") | K11: =IFERROR('Inputs'!$K$11/'Inputs'!$K$10,"") | L11: =IFERROR('Inputs'!$L$11/'Inputs'!$L$10,"") | M11: =IFERROR('Inputs'!$M$11/'Inputs'!$M$10,"") | N11: =IFERROR('Inputs'!$N$11/'Inputs'!$N$10,"") | O11: =IFERROR('Inputs'!$O$11/'Inputs'!$O$10,"") | P11: =IFERROR('Inputs'!$P$11/'Inputs'!$P$10,"")
A12: Gross profit | B12: =IFERROR('Inputs'!$B$12/'Inputs'!$B$10,"") | C12: =IFERROR('Inputs'!$C$12/'Inputs'!$C$10,"") | D12: =IFERROR('Inputs'!$D$12/'Inputs'!$D$10,"") | E12: =IFERROR('Inputs'!$E$12/'Inputs'!$E$10,"") | F12: =IFERROR('Inputs'!$F$12/'Inputs'!$F$10,"") | G12: =IFERROR('Inputs'!$G$12/'Inputs'!$G$10,"") | H12: =IFERROR('Inputs'!$H$12/'Inputs'!$H$10,"") | I12: =IFERROR('Inputs'!$I$12/'Inputs'!$I$10,"") | J12: =IFERROR('Inputs'!$J$12/'Inputs'!$J$10,"") | K12: =IFERROR('Inputs'!$K$12/'Inputs'!$K$10,"") | L12: =IFERROR('Inputs'!$L$12/'Inputs'!$L$10,"") | M12: =IFERROR('Inputs'!$M$12/'Inputs'!$M$10,"") | N12: =IFERROR('Inputs'!$N$12/'Inputs'!$N$10,"") | O12: =IFERROR('Inputs'!$O$12/'Inputs'!$O$10,"") | P12: =IFERROR('Inputs'!$P$12/'Inputs'!$P$10,"")
A13: Operating expenses | B13: =IFERROR('Inputs'!$B$13/'Inputs'!$B$10,"") | C13: =IFERROR('Inputs'!$C$13/'Inputs'!$C$10,"") | D13: =IFERROR('Inputs'!$D$13/'Inputs'!$D$10,"") | E13: =IFERROR('Inputs'!$E$13/'Inputs'!$E$10,"") | F13: =IFERROR('Inputs'!$F$13/'Inputs'!$F$10,"") | G13: =IFERROR('Inputs'!$G$13/'Inputs'!$G$10,"") | H13: =IFERROR('Inputs'!$H$13/'Inputs'!$H$10,"") | I13: =IFERROR('Inputs'!$I$13/'Inputs'!$I$10,"") | J13: =IFERROR('Inputs'!$J$13/'Inputs'!$J$10,"") | K13: =IFERROR('Inputs'!$K$13/'Inputs'!$K$10,"") | L13: =IFERROR('Inputs'!$L$13/'Inputs'!$L$10,"") | M13: =IFERROR('Inputs'!$M$13/'Inputs'!$M$10,"") | N13: =IFERROR('Inputs'!$N$13/'Inputs'!$N$10,"") | O13: =IFERROR('Inputs'!$O$13/'Inputs'!$O$10,"") | P13: =IFERROR('Inputs'!$P$13/'Inputs'!$P$10,"")
A14: EBITDA | B14: =IFERROR('Inputs'!$B$14/'Inputs'!$B$10,"") | C14: =IFERROR('Inputs'!$C$14/'Inputs'!$C$10,"") | D14: =IFERROR('Inputs'!$D$14/'Inputs'!$D$10,"") | E14: =IFERROR('Inputs'!$E$14/'Inputs'!$E$10,"") | F14: =IFERROR('Inputs'!$F$14/'Inputs'!$F$10,"") | G14: =IFERROR('Inputs'!$G$14/'Inputs'!$G$10,"") | H14: =IFERROR('Inputs'!$H$14/'Inputs'!$H$10,"") | I14: =IFERROR('Inputs'!$I$14/'Inputs'!$I$10,"") | J14: =IFERROR('Inputs'!$J$14/'Inputs'!$J$10,"") | K14: =IFERROR('Inputs'!$K$14/'Inputs'!$K$10,"") | L14: =IFERROR('Inputs'!$L$14/'Inputs'!$L$10,"") | M14: =IFERROR('Inputs'!$M$14/'Inputs'!$M$10,"") | N14: =IFERROR('Inputs'!$N$14/'Inputs'!$N$10,"") | O14: =IFERROR('Inputs'!$O$14/'Inputs'!$O$10,"") | P14: =IFERROR('Inputs'!$P$14/'Inputs'!$P$10,"")
A15: Depreciation | B15: =IFERROR('Inputs'!$B$15/'Inputs'!$B$10,"") | C15: =IFERROR('Inputs'!$C$15/'Inputs'!$C$10,"") | D15: =IFERROR('Inputs'!$D$15/'Inputs'!$D$10,"") | E15: =IFERROR('Inputs'!$E$15/'Inputs'!$E$10,"") | F15: =IFERROR('Inputs'!$F$15/'Inputs'!$F$10,"") | G15: =IFERROR('Inputs'!$G$15/'Inputs'!$G$10,"") | H15: =IFERROR('Inputs'!$H$15/'Inputs'!$H$10,"") | I15: =IFERROR('Inputs'!$I$15/'Inputs'!$I$10,"") | J15: =IFERROR('Inputs'!$J$15/'Inputs'!$J$10,"") | K15: =IFERROR('Inputs'!$K$15/'Inputs'!$K$10,"") | L15: =IFERROR('Inputs'!$L$15/'Inputs'!$L$10,"") | M15: =IFERROR('Inputs'!$M$15/'Inputs'!$M$10,"") | N15: =IFERROR('Inputs'!$N$15/'Inputs'!$N$10,"") | O15: =IFERROR('Inputs'!$O$15/'Inputs'!$O$10,"") | P15: =IFERROR('Inputs'!$P$15/'Inputs'!$P$10,"")
A16: EBIT | B16: =IFERROR('Inputs'!$B$16/'Inputs'!$B$10,"") | C16: =IFERROR('Inputs'!$C$16/'Inputs'!$C$10,"") | D16: =IFERROR('Inputs'!$D$16/'Inputs'!$D$10,"") | E16: =IFERROR('Inputs'!$E$16/'Inputs'!$E$10,"") | F16: =IFERROR('Inputs'!$F$16/'Inputs'!$F$10,"") | G16: =IFERROR('Inputs'!$G$16/'Inputs'!$G$10,"") | H16: =IFERROR('Inputs'!$H$16/'Inputs'!$H$10,"") | I16: =IFERROR('Inputs'!$I$16/'Inputs'!$I$10,"") | J16: =IFERROR('Inputs'!$J$16/'Inputs'!$J$10,"") | K16: =IFERROR('Inputs'!$K$16/'Inputs'!$K$10,"") | L16: =IFERROR('Inputs'!$L$16/'Inputs'!$L$10,"") | M16: =IFERROR('Inputs'!$M$16/'Inputs'!$M$10,"") | N16: =IFERROR('Inputs'!$N$16/'Inputs'!$N$10,"") | O16: =IFERROR('Inputs'!$O$16/'Inputs'!$O$10,"") | P16: =IFERROR('Inputs'!$P$16/'Inputs'!$P$10,"")
A17: Interest expense | B17: =IFERROR('Inputs'!$B$17/'Inputs'!$B$10,"") | C17: =IFERROR('Inputs'!$C$17/'Inputs'!$C$10,"") | D17: =IFERROR('Inputs'!$D$17/'Inputs'!$D$10,"") | E17: =IFERROR('Inputs'!$E$17/'Inputs'!$E$10,"") | F17: =IFERROR('Inputs'!$F$17/'Inputs'!$F$10,"") | G17: =IFERROR('Inputs'!$G$17/'Inputs'!$G$10,"") | H17: =IFERROR('Inputs'!$H$17/'Inputs'!$H$10,"") | I17: =IFERROR('Inputs'!$I$17/'Inputs'!$I$10,"") | J17: =IFERROR('Inputs'!$J$17/'Inputs'!$J$10,"") | K17: =IFERROR('Inputs'!$K$17/'Inputs'!$K$10,"") | L17: =IFERROR('Inputs'!$L$17/'Inputs'!$L$10,"") | M17: =IFERROR('Inputs'!$M$17/'Inputs'!$M$10,"") | N17: =IFERROR('Inputs'!$N$17/'Inputs'!$N$10,"") | O17: =IFERROR('Inputs'!$O$17/'Inputs'!$O$10,"") | P17: =IFERROR('Inputs'!$P$17/'Inputs'!$P$10,"")
A18: Pre-tax income | B18: =IFERROR('Inputs'!$B$19/'Inputs'!$B$10,"") | C18: =IFERROR('Inputs'!$C$19/'Inputs'!$C$10,"") | D18: =IFERROR('Inputs'!$D$19/'Inputs'!$D$10,"") | E18: =IFERROR('Inputs'!$E$19/'Inputs'!$E$10,"") | F18: =IFERROR('Inputs'!$F$19/'Inputs'!$F$10,"") | G18: =IFERROR('Inputs'!$G$19/'Inputs'!$G$10,"") | H18: =IFERROR('Inputs'!$H$19/'Inputs'!$H$10,"") | I18: =IFERROR('Inputs'!$I$19/'Inputs'!$I$10,"") | J18: =IFERROR('Inputs'!$J$19/'Inputs'!$J$10,"") | K18: =IFERROR('Inputs'!$K$19/'Inputs'!$K$10,"") | L18: =IFERROR('Inputs'!$L$19/'Inputs'!$L$10,"") | M18: =IFERROR('Inputs'!$M$19/'Inputs'!$M$10,"") | N18: =IFERROR('Inputs'!$N$19/'Inputs'!$N$10,"") | O18: =IFERROR('Inputs'!$O$19/'Inputs'!$O$10,"") | P18: =IFERROR('Inputs'!$P$19/'Inputs'!$P$10,"")
A19: Income tax | B19: =IFERROR('Inputs'!$B$20/'Inputs'!$B$10,"") | C19: =IFERROR('Inputs'!$C$20/'Inputs'!$C$10,"") | D19: =IFERROR('Inputs'!$D$20/'Inputs'!$D$10,"") | E19: =IFERROR('Inputs'!$E$20/'Inputs'!$E$10,"") | F19: =IFERROR('Inputs'!$F$20/'Inputs'!$F$10,"") | G19: =IFERROR('Inputs'!$G$20/'Inputs'!$G$10,"") | H19: =IFERROR('Inputs'!$H$20/'Inputs'!$H$10,"") | I19: =IFERROR('Inputs'!$I$20/'Inputs'!$I$10,"") | J19: =IFERROR('Inputs'!$J$20/'Inputs'!$J$10,"") | K19: =IFERROR('Inputs'!$K$20/'Inputs'!$K$10,"") | L19: =IFERROR('Inputs'!$L$20/'Inputs'!$L$10,"") | M19: =IFERROR('Inputs'!$M$20/'Inputs'!$M$10,"") | N19: =IFERROR('Inputs'!$N$20/'Inputs'!$N$10,"") | O19: =IFERROR('Inputs'!$O$20/'Inputs'!$O$10,"") | P19: =IFERROR('Inputs'!$P$20/'Inputs'!$P$10,"")
A20: Net income | B20: =IFERROR('Inputs'!$B$21/'Inputs'!$B$10,"") | C20: =IFERROR('Inputs'!$C$21/'Inputs'!$C$10,"") | D20: =IFERROR('Inputs'!$D$21/'Inputs'!$D$10,"") | E20: =IFERROR('Inputs'!$E$21/'Inputs'!$E$10,"") | F20: =IFERROR('Inputs'!$F$21/'Inputs'!$F$10,"") | G20: =IFERROR('Inputs'!$G$21/'Inputs'!$G$10,"") | H20: =IFERROR('Inputs'!$H$21/'Inputs'!$H$10,"") | I20: =IFERROR('Inputs'!$I$21/'Inputs'!$I$10,"") | J20: =IFERROR('Inputs'!$J$21/'Inputs'!$J$10,"") | K20: =IFERROR('Inputs'!$K$21/'Inputs'!$K$10,"") | L20: =IFERROR('Inputs'!$L$21/'Inputs'!$L$10,"") | M20: =IFERROR('Inputs'!$M$21/'Inputs'!$M$10,"") | N20: =IFERROR('Inputs'!$N$21/'Inputs'!$N$10,"") | O20: =IFERROR('Inputs'!$O$21/'Inputs'!$O$10,"") | P20: =IFERROR('Inputs'!$P$21/'Inputs'!$P$10,"")
A22: Balance Sheet — Common Size (% of total assets)
A23: Cash & equivalents | B23: =IFERROR('Inputs'!$B$23/'Inputs'!$B$32,"") | C23: =IFERROR('Inputs'!$C$23/'Inputs'!$C$32,"") | D23: =IFERROR('Inputs'!$D$23/'Inputs'!$D$32,"") | E23: =IFERROR('Inputs'!$E$23/'Inputs'!$E$32,"") | F23: =IFERROR('Inputs'!$F$23/'Inputs'!$F$32,"") | G23: =IFERROR('Inputs'!$G$23/'Inputs'!$G$32,"") | H23: =IFERROR('Inputs'!$H$23/'Inputs'!$H$32,"") | I23: =IFERROR('Inputs'!$I$23/'Inputs'!$I$32,"") | J23: =IFERROR('Inputs'!$J$23/'Inputs'!$J$32,"") | K23: =IFERROR('Inputs'!$K$23/'Inputs'!$K$32,"") | L23: =IFERROR('Inputs'!$L$23/'Inputs'!$L$32,"") | M23: =IFERROR('Inputs'!$M$23/'Inputs'!$M$32,"") | N23: =IFERROR('Inputs'!$N$23/'Inputs'!$N$32,"") | O23: =IFERROR('Inputs'!$O$23/'Inputs'!$O$32,"") | P23: =IFERROR('Inputs'!$P$23/'Inputs'!$P$32,"")
A24: Receivables | B24: =IFERROR('Inputs'!$B$24/'Inputs'!$B$32,"") | C24: =IFERROR('Inputs'!$C$24/'Inputs'!$C$32,"") | D24: =IFERROR('Inputs'!$D$24/'Inputs'!$D$32,"") | E24: =IFERROR('Inputs'!$E$24/'Inputs'!$E$32,"") | F24: =IFERROR('Inputs'!$F$24/'Inputs'!$F$32,"") | G24: =IFERROR('Inputs'!$G$24/'Inputs'!$G$32,"") | H24: =IFERROR('Inputs'!$H$24/'Inputs'!$H$32,"") | I24: =IFERROR('Inputs'!$I$24/'Inputs'!$I$32,"") | J24: =IFERROR('Inputs'!$J$24/'Inputs'!$J$32,"") | K24: =IFERROR('Inputs'!$K$24/'Inputs'!$K$32,"") | L24: =IFERROR('Inputs'!$L$24/'Inputs'!$L$32,"") | M24: =IFERROR('Inputs'!$M$24/'Inputs'!$M$32,"") | N24: =IFERROR('Inputs'!$N$24/'Inputs'!$N$32,"") | O24: =IFERROR('Inputs'!$O$24/'Inputs'!$O$32,"") | P24: =IFERROR('Inputs'!$P$24/'Inputs'!$P$32,"")
A25: Inventory | B25: =IFERROR('Inputs'!$B$25/'Inputs'!$B$32,"") | C25: =IFERROR('Inputs'!$C$25/'Inputs'!$C$32,"") | D25: =IFERROR('Inputs'!$D$25/'Inputs'!$D$32,"") | E25: =IFERROR('Inputs'!$E$25/'Inputs'!$E$32,"") | F25: =IFERROR('Inputs'!$F$25/'Inputs'!$F$32,"") | G25: =IFERROR('Inputs'!$G$25/'Inputs'!$G$32,"") | H25: =IFERROR('Inputs'!$H$25/'Inputs'!$H$32,"") | I25: =IFERROR('Inputs'!$I$25/'Inputs'!$I$32,"") | J25: =IFERROR('Inputs'!$J$25/'Inputs'!$J$32,"") | K25: =IFERROR('Inputs'!$K$25/'Inputs'!$K$32,"") | L25: =IFERROR('Inputs'!$L$25/'Inputs'!$L$32,"") | M25: =IFERROR('Inputs'!$M$25/'Inputs'!$M$32,"") | N25: =IFERROR('Inputs'!$N$25/'Inputs'!$N$32,"") | O25: =IFERROR('Inputs'!$O$25/'Inputs'!$O$32,"") | P25: =IFERROR('Inputs'!$P$25/'Inputs'!$P$32,"")
A26: Other current assets | B26: =IFERROR('Inputs'!$B$26/'Inputs'!$B$32,"") | C26: =IFERROR('Inputs'!$C$26/'Inputs'!$C$32,"") | D26: =IFERROR('Inputs'!$D$26/'Inputs'!$D$32,"") | E26: =IFERROR('Inputs'!$E$26/'Inputs'!$E$32,"") | F26: =IFERROR('Inputs'!$F$26/'Inputs'!$F$32,"") | G26: =IFERROR('Inputs'!$G$26/'Inputs'!$G$32,"") | H26: =IFERROR('Inputs'!$H$26/'Inputs'!$H$32,"") | I26: =IFERROR('Inputs'!$I$26/'Inputs'!$I$32,"") | J26: =IFERROR('Inputs'!$J$26/'Inputs'!$J$32,"") | K26: =IFERROR('Inputs'!$K$26/'Inputs'!$K$32,"") | L26: =IFERROR('Inputs'!$L$26/'Inputs'!$L$32,"") | M26: =IFERROR('Inputs'!$M$26/'Inputs'!$M$32,"") | N26: =IFERROR('Inputs'!$N$26/'Inputs'!$N$32,"") | O26: =IFERROR('Inputs'!$O$26/'Inputs'!$O$32,"") | P26: =IFERROR('Inputs'!$P$26/'Inputs'!$P$32,"")
A27: Total current assets | B27: =IFERROR('Inputs'!$B$27/'Inputs'!$B$32,"") | C27: =IFERROR('Inputs'!$C$27/'Inputs'!$C$32,"") | D27: =IFERROR('Inputs'!$D$27/'Inputs'!$D$32,"") | E27: =IFERROR('Inputs'!$E$27/'Inputs'!$E$32,"") | F27: =IFERROR('Inputs'!$F$27/'Inputs'!$F$32,"") | G27: =IFERROR('Inputs'!$G$27/'Inputs'!$G$32,"") | H27: =IFERROR('Inputs'!$H$27/'Inputs'!$H$32,"") | I27: =IFERROR('Inputs'!$I$27/'Inputs'!$I$32,"") | J27: =IFERROR('Inputs'!$J$27/'Inputs'!$J$32,"") | K27: =IFERROR('Inputs'!$K$27/'Inputs'!$K$32,"") | L27: =IFERROR('Inputs'!$L$27/'Inputs'!$L$32,"") | M27: =IFERROR('Inputs'!$M$27/'Inputs'!$M$32,"") | N27: =IFERROR('Inputs'!$N$27/'Inputs'!$N$32,"") | O27: =IFERROR('Inputs'!$O$27/'Inputs'!$O$32,"") | P27: =IFERROR('Inputs'!$P$27/'Inputs'!$P$32,"")
A28: PP&E (net) | B28: =IFERROR('Inputs'!$B$28/'Inputs'!$B$32,"") | C28: =IFERROR('Inputs'!$C$28/'Inputs'!$C$32,"") | D28: =IFERROR('Inputs'!$D$28/'Inputs'!$D$32,"") | E28: =IFERROR('Inputs'!$E$28/'Inputs'!$E$32,"") | F28: =IFERROR('Inputs'!$F$28/'Inputs'!$F$32,"") | G28: =IFERROR('Inputs'!$G$28/'Inputs'!$G$32,"") | H28: =IFERROR('Inputs'!$H$28/'Inputs'!$H$32,"") | I28: =IFERROR('Inputs'!$I$28/'Inputs'!$I$32,"") | J28: =IFERROR('Inputs'!$J$28/'Inputs'!$J$32,"") | K28: =IFERROR('Inputs'!$K$28/'Inputs'!$K$32,"") | L28: =IFERROR('Inputs'!$L$28/'Inputs'!$L$32,"") | M28: =IFERROR('Inputs'!$M$28/'Inputs'!$M$32,"") | N28: =IFERROR('Inputs'!$N$28/'Inputs'!$N$32,"") | O28: =IFERROR('Inputs'!$O$28/'Inputs'!$O$32,"") | P28: =IFERROR('Inputs'!$P$28/'Inputs'!$P$32,"")
A29: Goodwill & intangibles | B29: =IFERROR('Inputs'!$B$29/'Inputs'!$B$32,"") | C29: =IFERROR('Inputs'!$C$29/'Inputs'!$C$32,"") | D29: =IFERROR('Inputs'!$D$29/'Inputs'!$D$32,"") | E29: =IFERROR('Inputs'!$E$29/'Inputs'!$E$32,"") | F29: =IFERROR('Inputs'!$F$29/'Inputs'!$F$32,"") | G29: =IFERROR('Inputs'!$G$29/'Inputs'!$G$32,"") | H29: =IFERROR('Inputs'!$H$29/'Inputs'!$H$32,"") | I29: =IFERROR('Inputs'!$I$29/'Inputs'!$I$32,"") | J29: =IFERROR('Inputs'!$J$29/'Inputs'!$J$32,"") | K29: =IFERROR('Inputs'!$K$29/'Inputs'!$K$32,"") | L29: =IFERROR('Inputs'!$L$29/'Inputs'!$L$32,"") | M29: =IFERROR('Inputs'!$M$29/'Inputs'!$M$32,"") | N29: =IFERROR('Inputs'!$N$29/'Inputs'!$N$32,"") | O29: =IFERROR('Inputs'!$O$29/'Inputs'!$O$32,"") | P29: =IFERROR('Inputs'!$P$29/'Inputs'!$P$32,"")
A30: Other non-current assets | B30: =IFERROR('Inputs'!$B$30/'Inputs'!$B$32,"") | C30: =IFERROR('Inputs'!$C$30/'Inputs'!$C$32,"") | D30: =IFERROR('Inputs'!$D$30/'Inputs'!$D$32,"") | E30: =IFERROR('Inputs'!$E$30/'Inputs'!$E$32,"") | F30: =IFERROR('Inputs'!$F$30/'Inputs'!$F$32,"") | G30: =IFERROR('Inputs'!$G$30/'Inputs'!$G$32,"") | H30: =IFERROR('Inputs'!$H$30/'Inputs'!$H$32,"") | I30: =IFERROR('Inputs'!$I$30/'Inputs'!$I$32,"") | J30: =IFERROR('Inputs'!$J$30/'Inputs'!$J$32,"") | K30: =IFERROR('Inputs'!$K$30/'Inputs'!$K$32,"") | L30: =IFERROR('Inputs'!$L$30/'Inputs'!$L$32,"") | M30: =IFERROR('Inputs'!$M$30/'Inputs'!$M$32,"") | N30: =IFERROR('Inputs'!$N$30/'Inputs'!$N$32,"") | O30: =IFERROR('Inputs'!$O$30/'Inputs'!$O$32,"") | P30: =IFERROR('Inputs'!$P$30/'Inputs'!$P$32,"")
A31: Total current liabilities | B31: =IFERROR('Inputs'!$B$37/'Inputs'!$B$32,"") | C31: =IFERROR('Inputs'!$C$37/'Inputs'!$C$32,"") | D31: =IFERROR('Inputs'!$D$37/'Inputs'!$D$32,"") | E31: =IFERROR('Inputs'!$E$37/'Inputs'!$E$32,"") | F31: =IFERROR('Inputs'!$F$37/'Inputs'!$F$32,"") | G31: =IFERROR('Inputs'!$G$37/'Inputs'!$G$32,"") | H31: =IFERROR('Inputs'!$H$37/'Inputs'!$H$32,"") | I31: =IFERROR('Inputs'!$I$37/'Inputs'!$I$32,"") | J31: =IFERROR('Inputs'!$J$37/'Inputs'!$J$32,"") | K31: =IFERROR('Inputs'!$K$37/'Inputs'!$K$32,"") | L31: =IFERROR('Inputs'!$L$37/'Inputs'!$L$32,"") | M31: =IFERROR('Inputs'!$M$37/'Inputs'!$M$32,"") | N31: =IFERROR('Inputs'!$N$37/'Inputs'!$N$32,"") | O31: =IFERROR('Inputs'!$O$37/'Inputs'!$O$32,"") | P31: =IFERROR('Inputs'!$P$37/'Inputs'!$P$32,"")
A32: Long-term debt | B32: =IFERROR('Inputs'!$B$38/'Inputs'!$B$32,"") | C32: =IFERROR('Inputs'!$C$38/'Inputs'!$C$32,"") | D32: =IFERROR('Inputs'!$D$38/'Inputs'!$D$32,"") | E32: =IFERROR('Inputs'!$E$38/'Inputs'!$E$32,"") | F32: =IFERROR('Inputs'!$F$38/'Inputs'!$F$32,"") | G32: =IFERROR('Inputs'!$G$38/'Inputs'!$G$32,"") | H32: =IFERROR('Inputs'!$H$38/'Inputs'!$H$32,"") | I32: =IFERROR('Inputs'!$I$38/'Inputs'!$I$32,"") | J32: =IFERROR('Inputs'!$J$38/'Inputs'!$J$32,"") | K32: =IFERROR('Inputs'!$K$38/'Inputs'!$K$32,"") | L32: =IFERROR('Inputs'!$L$38/'Inputs'!$L$32,"") | M32: =IFERROR('Inputs'!$M$38/'Inputs'!$M$32,"") | N32: =IFERROR('Inputs'!$N$38/'Inputs'!$N$32,"") | O32: =IFERROR('Inputs'!$O$38/'Inputs'!$O$32,"") | P32: =IFERROR('Inputs'!$P$38/'Inputs'!$P$32,"")
A33: Total liabilities | B33: =IFERROR('Inputs'!$B$41/'Inputs'!$B$32,"") | C33: =IFERROR('Inputs'!$C$41/'Inputs'!$C$32,"") | D33: =IFERROR('Inputs'!$D$41/'Inputs'!$D$32,"") | E33: =IFERROR('Inputs'!$E$41/'Inputs'!$E$32,"") | F33: =IFERROR('Inputs'!$F$41/'Inputs'!$F$32,"") | G33: =IFERROR('Inputs'!$G$41/'Inputs'!$G$32,"") | H33: =IFERROR('Inputs'!$H$41/'Inputs'!$H$32,"") | I33: =IFERROR('Inputs'!$I$41/'Inputs'!$I$32,"") | J33: =IFERROR('Inputs'!$J$41/'Inputs'!$J$32,"") | K33: =IFERROR('Inputs'!$K$41/'Inputs'!$K$32,"") | L33: =IFERROR('Inputs'!$L$41/'Inputs'!$L$32,"") | M33: =IFERROR('Inputs'!$M$41/'Inputs'!$M$32,"") | N33: =IFERROR('Inputs'!$N$41/'Inputs'!$N$32,"") | O33: =IFERROR('Inputs'!$O$41/'Inputs'!$O$32,"") | P33: =IFERROR('Inputs'!$P$41/'Inputs'!$P$32,"")
A34: Shareholders' equity | B34: =IFERROR('Inputs'!$B$42/'Inputs'!$B$32,"") | C34: =IFERROR('Inputs'!$C$42/'Inputs'!$C$32,"") | D34: =IFERROR('Inputs'!$D$42/'Inputs'!$D$32,"") | E34: =IFERROR('Inputs'!$E$42/'Inputs'!$E$32,"") | F34: =IFERROR('Inputs'!$F$42/'Inputs'!$F$32,"") | G34: =IFERROR('Inputs'!$G$42/'Inputs'!$G$32,"") | H34: =IFERROR('Inputs'!$H$42/'Inputs'!$H$32,"") | I34: =IFERROR('Inputs'!$I$42/'Inputs'!$I$32,"") | J34: =IFERROR('Inputs'!$J$42/'Inputs'!$J$32,"") | K34: =IFERROR('Inputs'!$K$42/'Inputs'!$K$32,"") | L34: =IFERROR('Inputs'!$L$42/'Inputs'!$L$32,"") | M34: =IFERROR('Inputs'!$M$42/'Inputs'!$M$32,"") | N34: =IFERROR('Inputs'!$N$42/'Inputs'!$N$32,"") | O34: =IFERROR('Inputs'!$O$42/'Inputs'!$O$32,"") | P34: =IFERROR('Inputs'!$P$42/'Inputs'!$P$32,"")
A36: Horizontal / Trend Analysis (indexed to first year = 100)
A37: Revenue index (FY2015=100) | B37: =IFERROR('Inputs'!$B$10/'Inputs'!$B$10*100,"") | C37: =IFERROR('Inputs'!$C$10/'Inputs'!$B$10*100,"") | D37: =IFERROR('Inputs'!$D$10/'Inputs'!$B$10*100,"") | E37: =IFERROR('Inputs'!$E$10/'Inputs'!$B$10*100,"") | F37: =IFERROR('Inputs'!$F$10/'Inputs'!$B$10*100,"") | G37: =IFERROR('Inputs'!$G$10/'Inputs'!$B$10*100,"") | H37: =IFERROR('Inputs'!$H$10/'Inputs'!$B$10*100,"") | I37: =IFERROR('Inputs'!$I$10/'Inputs'!$B$10*100,"") | J37: =IFERROR('Inputs'!$J$10/'Inputs'!$B$10*100,"") | K37: =IFERROR('Inputs'!$K$10/'Inputs'!$B$10*100,"") | L37: =IFERROR('Inputs'!$L$10/'Inputs'!$B$10*100,"") | M37: =IFERROR('Inputs'!$M$10/'Inputs'!$B$10*100,"") | N37: =IFERROR('Inputs'!$N$10/'Inputs'!$B$10*100,"") | O37: =IFERROR('Inputs'!$O$10/'Inputs'!$B$10*100,"") | P37: =IFERROR('Inputs'!$P$10/'Inputs'!$B$10*100,"")
A38: Net income index (FY2015=100) | B38: =IFERROR('Inputs'!$B$21/'Inputs'!$B$21*100,"") | C38: =IFERROR('Inputs'!$C$21/'Inputs'!$B$21*100,"") | D38: =IFERROR('Inputs'!$D$21/'Inputs'!$B$21*100,"") | E38: =IFERROR('Inputs'!$E$21/'Inputs'!$B$21*100,"") | F38: =IFERROR('Inputs'!$F$21/'Inputs'!$B$21*100,"") | G38: =IFERROR('Inputs'!$G$21/'Inputs'!$B$21*100,"") | H38: =IFERROR('Inputs'!$H$21/'Inputs'!$B$21*100,"") | I38: =IFERROR('Inputs'!$I$21/'Inputs'!$B$21*100,"") | J38: =IFERROR('Inputs'!$J$21/'Inputs'!$B$21*100,"") | K38: =IFERROR('Inputs'!$K$21/'Inputs'!$B$21*100,"") | L38: =IFERROR('Inputs'!$L$21/'Inputs'!$B$21*100,"") | M38: =IFERROR('Inputs'!$M$21/'Inputs'!$B$21*100,"") | N38: =IFERROR('Inputs'!$N$21/'Inputs'!$B$21*100,"") | O38: =IFERROR('Inputs'!$O$21/'Inputs'!$B$21*100,"") | P38: =IFERROR('Inputs'!$P$21/'Inputs'!$B$21*100,"")
A39: Equity index (FY2015=100) | B39: =IFERROR('Inputs'!$B$42/'Inputs'!$B$42*100,"") | C39: =IFERROR('Inputs'!$C$42/'Inputs'!$B$42*100,"") | D39: =IFERROR('Inputs'!$D$42/'Inputs'!$B$42*100,"") | E39: =IFERROR('Inputs'!$E$42/'Inputs'!$B$42*100,"") | F39: =IFERROR('Inputs'!$F$42/'Inputs'!$B$42*100,"") | G39: =IFERROR('Inputs'!$G$42/'Inputs'!$B$42*100,"") | H39: =IFERROR('Inputs'!$H$42/'Inputs'!$B$42*100,"") | I39: =IFERROR('Inputs'!$I$42/'Inputs'!$B$42*100,"") | J39: =IFERROR('Inputs'!$J$42/'Inputs'!$B$42*100,"") | K39: =IFERROR('Inputs'!$K$42/'Inputs'!$B$42*100,"") | L39: =IFERROR('Inputs'!$L$42/'Inputs'!$B$42*100,"") | M39: =IFERROR('Inputs'!$M$42/'Inputs'!$B$42*100,"") | N39: =IFERROR('Inputs'!$N$42/'Inputs'!$B$42*100,"") | O39: =IFERROR('Inputs'!$O$42/'Inputs'!$B$42*100,"") | P39: =IFERROR('Inputs'!$P$42/'Inputs'!$B$42*100,"")
A41: Common-size analysis normalises the statements so structural shifts and trends are visible regardless of absolute size. Heat-maps highlight the gradient.

Sheet Profitability
A1: PROFITABILITY RATIOS
A2: Margins, returns on capital and DuPont decomposition
A3: Institutional Financial Ratio Analysis · v1.0
A5: Dashboard | B5: Inputs | C5: Common Size | D5: Profitability | E5: Liquidity | F5: Solvency | G5: Efficiency | H5: Growth
A6: Valuation | B6: Capital Allocation | C6: Quality | D6: Benchmarking | E6: Guide | F6: Quality Control
A7: All figures in USD millions unless stated; (F) = forecast year.
A8: Profitability ratio | B8: FY2015 | C8: FY2016 | D8: FY2017 | E8: FY2018 | F8: FY2019 | G8: FY2020 | H8: FY2021 | I8: FY2022 | J8: FY2023 | K8: FY2024 | L8: FY2025 (F) | M8: FY2026 (F) | N8: FY2027 (F) | O8: FY2028 (F) | P8: FY2029 (F) | Q8: Trend | R8: Assessment
A9: Margins
A10: Gross margin | B10: =IFERROR('Inputs'!$B$12/'Inputs'!$B$10,"") | C10: =IFERROR('Inputs'!$C$12/'Inputs'!$C$10,"") | D10: =IFERROR('Inputs'!$D$12/'Inputs'!$D$10,"") | E10: =IFERROR('Inputs'!$E$12/'Inputs'!$E$10,"") | F10: =IFERROR('Inputs'!$F$12/'Inputs'!$F$10,"") | G10: =IFERROR('Inputs'!$G$12/'Inputs'!$G$10,"") | H10: =IFERROR('Inputs'!$H$12/'Inputs'!$H$10,"") | I10: =IFERROR('Inputs'!$I$12/'Inputs'!$I$10,"") | J10: =IFERROR('Inputs'!$J$12/'Inputs'!$J$10,"") | K10: =IFERROR('Inputs'!$K$12/'Inputs'!$K$10,"") | L10: =IFERROR('Inputs'!$L$12/'Inputs'!$L$10,"") | M10: =IFERROR('Inputs'!$M$12/'Inputs'!$M$10,"") | N10: =IFERROR('Inputs'!$N$12/'Inputs'!$N$10,"") | O10: =IFERROR('Inputs'!$O$12/'Inputs'!$O$10,"") | P10: =IFERROR('Inputs'!$P$12/'Inputs'!$P$10,"") | Q10: =IF(AND(ISNUMBER($K$10),ISNUMBER($J$10)),CHOOSE(2+($K$10>$J$10)-($K$10<$J$10),"▼","►","▲"),"") | R10: =IF(ISNUMBER($K$10),CHOOSE(1+($K$10>=0.2)+($K$10>=0.4),"Low","Average","High"),"")
A11: EBITDA margin | B11: =IFERROR('Inputs'!$B$14/'Inputs'!$B$10,"") | C11: =IFERROR('Inputs'!$C$14/'Inputs'!$C$10,"") | D11: =IFERROR('Inputs'!$D$14/'Inputs'!$D$10,"") | E11: =IFERROR('Inputs'!$E$14/'Inputs'!$E$10,"") | F11: =IFERROR('Inputs'!$F$14/'Inputs'!$F$10,"") | G11: =IFERROR('Inputs'!$G$14/'Inputs'!$G$10,"") | H11: =IFERROR('Inputs'!$H$14/'Inputs'!$H$10,"") | I11: =IFERROR('Inputs'!$I$14/'Inputs'!$I$10,"") | J11: =IFERROR('Inputs'!$J$14/'Inputs'!$J$10,"") | K11: =IFERROR('Inputs'!$K$14/'Inputs'!$K$10,"") | L11: =IFERROR('Inputs'!$L$14/'Inputs'!$L$10,"") | M11: =IFERROR('Inputs'!$M$14/'Inputs'!$M$10,"") | N11: =IFERROR('Inputs'!$N$14/'Inputs'!$N$10,"") | O11: =IFERROR('Inputs'!$O$14/'Inputs'!$O$10,"") | P11: =IFERROR('Inputs'!$P$14/'Inputs'!$P$10,"") | Q11: =IF(AND(ISNUMBER($K$11),ISNUMBER($J$11)),CHOOSE(2+($K$11>$J$11)-($K$11<$J$11),"▼","►","▲"),"") | R11: =IF(AND(ISNUMBER($K$11),ISNUMBER(AVERAGE($B$11:$K$11))),CHOOSE(2+($K$11>AVERAGE($B$11:$K$11)*(1+0.05))-($K$11<AVERAGE($B$11:$K$11)*(1-0.05)),"Compressing","Stable","Expanding"),"")
A12: Operating margin (EBIT) | B12: =IFERROR('Inputs'!$B$16/'Inputs'!$B$10,"") | C12: =IFERROR('Inputs'!$C$16/'Inputs'!$C$10,"") | D12: =IFERROR('Inputs'!$D$16/'Inputs'!$D$10,"") | E12: =IFERROR('Inputs'!$E$16/'Inputs'!$E$10,"") | F12: =IFERROR('Inputs'!$F$16/'Inputs'!$F$10,"") | G12: =IFERROR('Inputs'!$G$16/'Inputs'!$G$10,"") | H12: =IFERROR('Inputs'!$H$16/'Inputs'!$H$10,"") | I12: =IFERROR('Inputs'!$I$16/'Inputs'!$I$10,"") | J12: =IFERROR('Inputs'!$J$16/'Inputs'!$J$10,"") | K12: =IFERROR('Inputs'!$K$16/'Inputs'!$K$10,"") | L12: =IFERROR('Inputs'!$L$16/'Inputs'!$L$10,"") | M12: =IFERROR('Inputs'!$M$16/'Inputs'!$M$10,"") | N12: =IFERROR('Inputs'!$N$16/'Inputs'!$N$10,"") | O12: =IFERROR('Inputs'!$O$16/'Inputs'!$O$10,"") | P12: =IFERROR('Inputs'!$P$16/'Inputs'!$P$10,"") | Q12: =IF(AND(ISNUMBER($K$12),ISNUMBER($J$12)),CHOOSE(2+($K$12>$J$12)-($K$12<$J$12),"▼","►","▲"),"") | R12: =IF(ISNUMBER($K$12),CHOOSE(1+($K$12>=0.08)+($K$12>=0.18),"Low","Average","High"),"")
A13: Pre-tax margin | B13: =IFERROR('Inputs'!$B$19/'Inputs'!$B$10,"") | C13: =IFERROR('Inputs'!$C$19/'Inputs'!$C$10,"") | D13: =IFERROR('Inputs'!$D$19/'Inputs'!$D$10,"") | E13: =IFERROR('Inputs'!$E$19/'Inputs'!$E$10,"") | F13: =IFERROR('Inputs'!$F$19/'Inputs'!$F$10,"") | G13: =IFERROR('Inputs'!$G$19/'Inputs'!$G$10,"") | H13: =IFERROR('Inputs'!$H$19/'Inputs'!$H$10,"") | I13: =IFERROR('Inputs'!$I$19/'Inputs'!$I$10,"") | J13: =IFERROR('Inputs'!$J$19/'Inputs'!$J$10,"") | K13: =IFERROR('Inputs'!$K$19/'Inputs'!$K$10,"") | L13: =IFERROR('Inputs'!$L$19/'Inputs'!$L$10,"") | M13: =IFERROR('Inputs'!$M$19/'Inputs'!$M$10,"") | N13: =IFERROR('Inputs'!$N$19/'Inputs'!$N$10,"") | O13: =IFERROR('Inputs'!$O$19/'Inputs'!$O$10,"") | P13: =IFERROR('Inputs'!$P$19/'Inputs'!$P$10,"") | Q13: =IF(AND(ISNUMBER($K$13),ISNUMBER($J$13)),CHOOSE(2+($K$13>$J$13)-($K$13<$J$13),"▼","►","▲"),"") | R13: =IF(AND(ISNUMBER($K$13),ISNUMBER(AVERAGE($B$13:$K$13))),CHOOSE(2+($K$13>AVERAGE($B$13:$K$13)*(1+0.05))-($K$13<AVERAGE($B$13:$K$13)*(1-0.05)),"Compressing","Stable","Expanding"),"")
A14: Net margin | B14: =IFERROR('Inputs'!$B$21/'Inputs'!$B$10,"") | C14: =IFERROR('Inputs'!$C$21/'Inputs'!$C$10,"") | D14: =IFERROR('Inputs'!$D$21/'Inputs'!$D$10,"") | E14: =IFERROR('Inputs'!$E$21/'Inputs'!$E$10,"") | F14: =IFERROR('Inputs'!$F$21/'Inputs'!$F$10,"") | G14: =IFERROR('Inputs'!$G$21/'Inputs'!$G$10,"") | H14: =IFERROR('Inputs'!$H$21/'Inputs'!$H$10,"") | I14: =IFERROR('Inputs'!$I$21/'Inputs'!$I$10,"") | J14: =IFERROR('Inputs'!$J$21/'Inputs'!$J$10,"") | K14: =IFERROR('Inputs'!$K$21/'Inputs'!$K$10,"") | L14: =IFERROR('Inputs'!$L$21/'Inputs'!$L$10,"") | M14: =IFERROR('Inputs'!$M$21/'Inputs'!$M$10,"") | N14: =IFERROR('Inputs'!$N$21/'Inputs'!$N$10,"") | O14: =IFERROR('Inputs'!$O$21/'Inputs'!$O$10,"") | P14: =IFERROR('Inputs'!$P$21/'Inputs'!$P$10,"") | Q14: =IF(AND(ISNUMBER($K$14),ISNUMBER($J$14)),CHOOSE(2+($K$14>$J$14)-($K$14<$J$14),"▼","►","▲"),"") | R14: =IF(ISNUMBER($K$14),CHOOSE(1+($K$14>=0.05)+($K$14>=0.12),"Low","Average","High"),"")
A15: FCF margin | B15: =IFERROR('Inputs'!$B$48/'Inputs'!$B$10,"") | C15: =IFERROR('Inputs'!$C$48/'Inputs'!$C$10,"") | D15: =IFERROR('Inputs'!$D$48/'Inputs'!$D$10,"") | E15: =IFERROR('Inputs'!$E$48/'Inputs'!$E$10,"") | F15: =IFERROR('Inputs'!$F$48/'Inputs'!$F$10,"") | G15: =IFERROR('Inputs'!$G$48/'Inputs'!$G$10,"") | H15: =IFERROR('Inputs'!$H$48/'Inputs'!$H$10,"") | I15: =IFERROR('Inputs'!$I$48/'Inputs'!$I$10,"") | J15: =IFERROR('Inputs'!$J$48/'Inputs'!$J$10,"") | K15: =IFERROR('Inputs'!$K$48/'Inputs'!$K$10,"") | L15: =IFERROR('Inputs'!$L$48/'Inputs'!$L$10,"") | M15: =IFERROR('Inputs'!$M$48/'Inputs'!$M$10,"") | N15: =IFERROR('Inputs'!$N$48/'Inputs'!$N$10,"") | O15: =IFERROR('Inputs'!$O$48/'Inputs'!$O$10,"") | P15: =IFERROR('Inputs'!$P$48/'Inputs'!$P$10,"") | Q15: =IF(AND(ISNUMBER($K$15),ISNUMBER($J$15)),CHOOSE(2+($K$15>$J$15)-($K$15<$J$15),"▼","►","▲"),"") | R15: =IF(ISNUMBER($K$15),CHOOSE(1+($K$15>=0.03)+($K$15>=0.1),"Weak","Average","Strong"),"")
A17: Returns on Capital
A18: Return on equity (ROE) | C18: =IFERROR('Inputs'!$C$21/'Inputs'!$C$74,"") | D18: =IFERROR('Inputs'!$D$21/'Inputs'!$D$74,"") | E18: =IFERROR('Inputs'!$E$21/'Inputs'!$E$74,"") | F18: =IFERROR('Inputs'!$F$21/'Inputs'!$F$74,"") | G18: =IFERROR('Inputs'!$G$21/'Inputs'!$G$74,"") | H18: =IFERROR('Inputs'!$H$21/'Inputs'!$H$74,"") | I18: =IFERROR('Inputs'!$I$21/'Inputs'!$I$74,"") | J18: =IFERROR('Inputs'!$J$21/'Inputs'!$J$74,"") | K18: =IFERROR('Inputs'!$K$21/'Inputs'!$K$74,"") | L18: =IFERROR('Inputs'!$L$21/'Inputs'!$L$74,"") | M18: =IFERROR('Inputs'!$M$21/'Inputs'!$M$74,"") | N18: =IFERROR('Inputs'!$N$21/'Inputs'!$N$74,"") | O18: =IFERROR('Inputs'!$O$21/'Inputs'!$O$74,"") | P18: =IFERROR('Inputs'!$P$21/'Inputs'!$P$74,"") | Q18: =IF(AND(ISNUMBER($K$18),ISNUMBER($J$18)),CHOOSE(2+($K$18>$J$18)-($K$18<$J$18),"▼","►","▲"),"") | R18: =IF(ISNUMBER($K$18),CHOOSE(1+($K$18>=0.08)+($K$18>=0.15),"Weak","Average","Strong"),"")
A19: Return on assets (ROA) | C19: =IFERROR('Inputs'!$C$21/'Inputs'!$C$75,"") | D19: =IFERROR('Inputs'!$D$21/'Inputs'!$D$75,"") | E19: =IFERROR('Inputs'!$E$21/'Inputs'!$E$75,"") | F19: =IFERROR('Inputs'!$F$21/'Inputs'!$F$75,"") | G19: =IFERROR('Inputs'!$G$21/'Inputs'!$G$75,"") | H19: =IFERROR('Inputs'!$H$21/'Inputs'!$H$75,"") | I19: =IFERROR('Inputs'!$I$21/'Inputs'!$I$75,"") | J19: =IFERROR('Inputs'!$J$21/'Inputs'!$J$75,"") | K19: =IFERROR('Inputs'!$K$21/'Inputs'!$K$75,"") | L19: =IFERROR('Inputs'!$L$21/'Inputs'!$L$75,"") | M19: =IFERROR('Inputs'!$M$21/'Inputs'!$M$75,"") | N19: =IFERROR('Inputs'!$N$21/'Inputs'!$N$75,"") | O19: =IFERROR('Inputs'!$O$21/'Inputs'!$O$75,"") | P19: =IFERROR('Inputs'!$P$21/'Inputs'!$P$75,"") | Q19: =IF(AND(ISNUMBER($K$19),ISNUMBER($J$19)),CHOOSE(2+($K$19>$J$19)-($K$19<$J$19),"▼","►","▲"),"") | R19: =IF(ISNUMBER($K$19),CHOOSE(1+($K$19>=0.03)+($K$19>=0.07),"Weak","Average","Strong"),"")
A20: Return on invested capital (ROIC) | C20: =IFERROR('Inputs'!$C$71/'Inputs'!$C$80,"") | D20: =IFERROR('Inputs'!$D$71/'Inputs'!$D$80,"") | E20: =IFERROR('Inputs'!$E$71/'Inputs'!$E$80,"") | F20: =IFERROR('Inputs'!$F$71/'Inputs'!$F$80,"") | G20: =IFERROR('Inputs'!$G$71/'Inputs'!$G$80,"") | H20: =IFERROR('Inputs'!$H$71/'Inputs'!$H$80,"") | I20: =IFERROR('Inputs'!$I$71/'Inputs'!$I$80,"") | J20: =IFERROR('Inputs'!$J$71/'Inputs'!$J$80,"") | K20: =IFERROR('Inputs'!$K$71/'Inputs'!$K$80,"") | L20: =IFERROR('Inputs'!$L$71/'Inputs'!$L$80,"") | M20: =IFERROR('Inputs'!$M$71/'Inputs'!$M$80,"") | N20: =IFERROR('Inputs'!$N$71/'Inputs'!$N$80,"") | O20: =IFERROR('Inputs'!$O$71/'Inputs'!$O$80,"") | P20: =IFERROR('Inputs'!$P$71/'Inputs'!$P$80,"") | Q20: =IF(AND(ISNUMBER($K$20),ISNUMBER($J$20)),CHOOSE(2+($K$20>$J$20)-($K$20<$J$20),"▼","►","▲"),"") | R20: =IF(ISNUMBER($K$20),CHOOSE(1+($K$20>=0.08)+($K$20>=0.12),"Weak","Average","Strong"),"")
A21: Return on capital employed (ROCE) | B21: =IFERROR('Inputs'!$B$16/'Inputs'!$B$69,"") | C21: =IFERROR('Inputs'!$C$16/'Inputs'!$C$69,"") | D21: =IFERROR('Inputs'!$D$16/'Inputs'!$D$69,"") | E21: =IFERROR('Inputs'!$E$16/'Inputs'!$E$69,"") | F21: =IFERROR('Inputs'!$F$16/'Inputs'!$F$69,"") | G21: =IFERROR('Inputs'!$G$16/'Inputs'!$G$69,"") | H21: =IFERROR('Inputs'!$H$16/'Inputs'!$H$69,"") | I21: =IFERROR('Inputs'!$I$16/'Inputs'!$I$69,"") | J21: =IFERROR('Inputs'!$J$16/'Inputs'!$J$69,"") | K21: =IFERROR('Inputs'!$K$16/'Inputs'!$K$69,"") | L21: =IFERROR('Inputs'!$L$16/'Inputs'!$L$69,"") | M21: =IFERROR('Inputs'!$M$16/'Inputs'!$M$69,"") | N21: =IFERROR('Inputs'!$N$16/'Inputs'!$N$69,"") | O21: =IFERROR('Inputs'!$O$16/'Inputs'!$O$69,"") | P21: =IFERROR('Inputs'!$P$16/'Inputs'!$P$69,"") | Q21: =IF(AND(ISNUMBER($K$21),ISNUMBER($J$21)),CHOOSE(2+($K$21>$J$21)-($K$21<$J$21),"▼","►","▲"),"") | R21: =IF(ISNUMBER($K$21),CHOOSE(1+($K$21>=0.08)+($K$21>=0.12),"Weak","Average","Strong"),"")
A22: Cash ROIC (FCF / invested capital) | B22: =IFERROR('Inputs'!$B$48/'Inputs'!$B$70,"") | C22: =IFERROR('Inputs'!$C$48/'Inputs'!$C$70,"") | D22: =IFERROR('Inputs'!$D$48/'Inputs'!$D$70,"") | E22: =IFERROR('Inputs'!$E$48/'Inputs'!$E$70,"") | F22: =IFERROR('Inputs'!$F$48/'Inputs'!$F$70,"") | G22: =IFERROR('Inputs'!$G$48/'Inputs'!$G$70,"") | H22: =IFERROR('Inputs'!$H$48/'Inputs'!$H$70,"") | I22: =IFERROR('Inputs'!$I$48/'Inputs'!$I$70,"") | J22: =IFERROR('Inputs'!$J$48/'Inputs'!$J$70,"") | K22: =IFERROR('Inputs'!$K$48/'Inputs'!$K$70,"") | L22: =IFERROR('Inputs'!$L$48/'Inputs'!$L$70,"") | M22: =IFERROR('Inputs'!$M$48/'Inputs'!$M$70,"") | N22: =IFERROR('Inputs'!$N$48/'Inputs'!$N$70,"") | O22: =IFERROR('Inputs'!$O$48/'Inputs'!$O$70,"") | P22: =IFERROR('Inputs'!$P$48/'Inputs'!$P$70,"") | Q22: =IF(AND(ISNUMBER($K$22),ISNUMBER($J$22)),CHOOSE(2+($K$22>$J$22)-($K$22<$J$22),"▼","►","▲"),"") | R22: =IF(AND(ISNUMBER($K$22),ISNUMBER(AVERAGE($B$22:$K$22))),CHOOSE(2+($K$22>AVERAGE($B$22:$K$22)*(1+0.05))-($K$22<AVERAGE($B$22:$K$22)*(1-0.05)),"Weak","Stable","Strong"),"")
A24: DuPont Decomposition (ROE = Net margin × Asset turnover × Equity multiplier)
A25: Net profit margin | B25: =IFERROR('Inputs'!$B$21/'Inputs'!$B$10,"") | C25: =IFERROR('Inputs'!$C$21/'Inputs'!$C$10,"") | D25: =IFERROR('Inputs'!$D$21/'Inputs'!$D$10,"") | E25: =IFERROR('Inputs'!$E$21/'Inputs'!$E$10,"") | F25: =IFERROR('Inputs'!$F$21/'Inputs'!$F$10,"") | G25: =IFERROR('Inputs'!$G$21/'Inputs'!$G$10,"") | H25: =IFERROR('Inputs'!$H$21/'Inputs'!$H$10,"") | I25: =IFERROR('Inputs'!$I$21/'Inputs'!$I$10,"") | J25: =IFERROR('Inputs'!$J$21/'Inputs'!$J$10,"") | K25: =IFERROR('Inputs'!$K$21/'Inputs'!$K$10,"") | L25: =IFERROR('Inputs'!$L$21/'Inputs'!$L$10,"") | M25: =IFERROR('Inputs'!$M$21/'Inputs'!$M$10,"") | N25: =IFERROR('Inputs'!$N$21/'Inputs'!$N$10,"") | O25: =IFERROR('Inputs'!$O$21/'Inputs'!$O$10,"") | P25: =IFERROR('Inputs'!$P$21/'Inputs'!$P$10,"") | Q25: =IF(AND(ISNUMBER($K$25),ISNUMBER($J$25)),CHOOSE(2+($K$25>$J$25)-($K$25<$J$25),"▼","►","▲"),"")
A26: Asset turnover | C26: =IFERROR('Inputs'!$C$10/'Inputs'!$C$75,"") | D26: =IFERROR('Inputs'!$D$10/'Inputs'!$D$75,"") | E26: =IFERROR('Inputs'!$E$10/'Inputs'!$E$75,"") | F26: =IFERROR('Inputs'!$F$10/'Inputs'!$F$75,"") | G26: =IFERROR('Inputs'!$G$10/'Inputs'!$G$75,"") | H26: =IFERROR('Inputs'!$H$10/'Inputs'!$H$75,"") | I26: =IFERROR('Inputs'!$I$10/'Inputs'!$I$75,"") | J26: =IFERROR('Inputs'!$J$10/'Inputs'!$J$75,"") | K26: =IFERROR('Inputs'!$K$10/'Inputs'!$K$75,"") | L26: =IFERROR('Inputs'!$L$10/'Inputs'!$L$75,"") | M26: =IFERROR('Inputs'!$M$10/'Inputs'!$M$75,"") | N26: =IFERROR('Inputs'!$N$10/'Inputs'!$N$75,"") | O26: =IFERROR('Inputs'!$O$10/'Inputs'!$O$75,"") | P26: =IFERROR('Inputs'!$P$10/'Inputs'!$P$75,"") | Q26: =IF(AND(ISNUMBER($K$26),ISNUMBER($J$26)),CHOOSE(2+($K$26>$J$26)-($K$26<$J$26),"▼","►","▲"),"")
A27: Equity multiplier (leverage) | C27: =IFERROR('Inputs'!$C$75/'Inputs'!$C$74,"") | D27: =IFERROR('Inputs'!$D$75/'Inputs'!$D$74,"") | E27: =IFERROR('Inputs'!$E$75/'Inputs'!$E$74,"") | F27: =IFERROR('Inputs'!$F$75/'Inputs'!$F$74,"") | G27: =IFERROR('Inputs'!$G$75/'Inputs'!$G$74,"") | H27: =IFERROR('Inputs'!$H$75/'Inputs'!$H$74,"") | I27: =IFERROR('Inputs'!$I$75/'Inputs'!$I$74,"") | J27: =IFERROR('Inputs'!$J$75/'Inputs'!$J$74,"") | K27: =IFERROR('Inputs'!$K$75/'Inputs'!$K$74,"") | L27: =IFERROR('Inputs'!$L$75/'Inputs'!$L$74,"") | M27: =IFERROR('Inputs'!$M$75/'Inputs'!$M$74,"") | N27: =IFERROR('Inputs'!$N$75/'Inputs'!$N$74,"") | O27: =IFERROR('Inputs'!$O$75/'Inputs'!$O$74,"") | P27: =IFERROR('Inputs'!$P$75/'Inputs'!$P$74,"") | Q27: =IF(AND(ISNUMBER($K$27),ISNUMBER($J$27)),CHOOSE(2+($K$27>$J$27)-($K$27<$J$27),"▼","►","▲"),"")
A28: ROE (DuPont, computed) | C28: =IFERROR('Profitability'!$C$25*'Profitability'!$C$26*'Profitability'!$C$27,"") | D28: =IFERROR('Profitability'!$D$25*'Profitability'!$D$26*'Profitability'!$D$27,"") | E28: =IFERROR('Profitability'!$E$25*'Profitability'!$E$26*'Profitability'!$E$27,"") | F28: =IFERROR('Profitability'!$F$25*'Profitability'!$F$26*'Profitability'!$F$27,"") | G28: =IFERROR('Profitability'!$G$25*'Profitability'!$G$26*'Profitability'!$G$27,"") | H28: =IFERROR('Profitability'!$H$25*'Profitability'!$H$26*'Profitability'!$H$27,"") | I28: =IFERROR('Profitability'!$I$25*'Profitability'!$I$26*'Profitability'!$I$27,"") | J28: =IFERROR('Profitability'!$J$25*'Profitability'!$J$26*'Profitability'!$J$27,"") | K28: =IFERROR('Profitability'!$K$25*'Profitability'!$K$26*'Profitability'!$K$27,"") | L28: =IFERROR('Profitability'!$L$25*'Profitability'!$L$26*'Profitability'!$L$27,"") | M28: =IFERROR('Profitability'!$M$25*'Profitability'!$M$26*'Profitability'!$M$27,"") | N28: =IFERROR('Profitability'!$N$25*'Profitability'!$N$26*'Profitability'!$N$27,"") | O28: =IFERROR('Profitability'!$O$25*'Profitability'!$O$26*'Profitability'!$O$27,"") | P28: =IFERROR('Profitability'!$P$25*'Profitability'!$P$26*'Profitability'!$P$27,"") | Q28: =IF(AND(ISNUMBER($K$28),ISNUMBER($J$28)),CHOOSE(2+($K$28>$J$28)-($K$28<$J$28),"▼","►","▲"),"")
A29: DuPont ROE should equal the ROE above — a built-in audit of the decomposition.
A31: Capital Retention
A32: Retention ratio (1 − payout) | B32: =IFERROR(1-'Inputs'!$B$49/'Inputs'!$B$21,"") | C32: =IFERROR(1-'Inputs'!$C$49/'Inputs'!$C$21,"") | D32: =IFERROR(1-'Inputs'!$D$49/'Inputs'!$D$21,"") | E32: =IFERROR(1-'Inputs'!$E$49/'Inputs'!$E$21,"") | F32: =IFERROR(1-'Inputs'!$F$49/'Inputs'!$F$21,"") | G32: =IFERROR(1-'Inputs'!$G$49/'Inputs'!$G$21,"") | H32: =IFERROR(1-'Inputs'!$H$49/'Inputs'!$H$21,"") | I32: =IFERROR(1-'Inputs'!$I$49/'Inputs'!$I$21,"") | J32: =IFERROR(1-'Inputs'!$J$49/'Inputs'!$J$21,"") | K32: =IFERROR(1-'Inputs'!$K$49/'Inputs'!$K$21,"") | L32: =IFERROR(1-'Inputs'!$L$49/'Inputs'!$L$21,"") | M32: =IFERROR(1-'Inputs'!$M$49/'Inputs'!$M$21,"") | N32: =IFERROR(1-'Inputs'!$N$49/'Inputs'!$N$21,"") | O32: =IFERROR(1-'Inputs'!$O$49/'Inputs'!$O$21,"") | P32: =IFERROR(1-'Inputs'!$P$49/'Inputs'!$P$21,"") | Q32: =IF(AND(ISNUMBER($K$32),ISNUMBER($J$32)),CHOOSE(2+($K$32>$J$32)-($K$32<$J$32),"▼","►","▲"),"") | R32: =IF(AND(ISNUMBER($K$32),ISNUMBER(AVERAGE($B$32:$K$32))),CHOOSE(2+($K$32>AVERAGE($B$32:$K$32)*(1+0.05))-($K$32<AVERAGE($B$32:$K$32)*(1-0.05)),"Falling","Stable","Rising"),"")
A34: Automated Observations
A35: =IFERROR("» Operating margin "&CHOOSE(2+('Profitability'!$K$12>'Profitability'!$B$12)-('Profitability'!$K$12<'Profitability'!$B$12),"contracted","was broadly flat","expanded")&" by "&TEXT(ABS(('Profitability'!$K$12-'Profitability'!$B$12)*10000),"#,##0")&" bps over the historical period, to "&TEXT('Profitability'!$K$12,"0.0%")&".","(insufficient data — populate inputs)")
A36: =IFERROR("» ROIC of "&TEXT('Profitability'!$K$20,"0.0%")&" is "&IF('Profitability'!$K$20>'Inputs'!$B$82,"above","below")&" the WACC of "&TEXT('Inputs'!$B$82,"0.0%")&" — "&IF('Profitability'!$K$20>'Inputs'!$B$82,"the business is creating economic value.","the business is not covering its cost of capital."),"(insufficient data — populate inputs)")
A37: =IFERROR("» Net margin is currently "&TEXT('Profitability'!$K$14,"0.0%")&" — assessed "&'Profitability'!$R$14&".","(insufficient data — populate inputs)")

Sheet Liquidity
A1: LIQUIDITY RATIOS
A2: Short-term solvency and working-capital strength
A3: Institutional Financial Ratio Analysis · v1.0
A5: Dashboard | B5: Inputs | C5: Common Size | D5: Profitability | E5: Liquidity | F5: Solvency | G5: Efficiency | H5: Growth
A6: Valuation | B6: Capital Allocation | C6: Quality | D6: Benchmarking | E6: Guide | F6: Quality Control
A7: All figures in USD millions unless stated; (F) = forecast year.
A8: Liquidity ratio | B8: FY2015 | C8: FY2016 | D8: FY2017 | E8: FY2018 | F8: FY2019 | G8: FY2020 | H8: FY2021 | I8: FY2022 | J8: FY2023 | K8: FY2024 | L8: FY2025 (F) | M8: FY2026 (F) | N8: FY2027 (F) | O8: FY2028 (F) | P8: FY2029 (F) | Q8: Trend | R8: Assessment
A9: Coverage of Current Liabilities
A10: Current ratio | B10: =IFERROR('Inputs'!$B$27/'Inputs'!$B$37,"") | C10: =IFERROR('Inputs'!$C$27/'Inputs'!$C$37,"") | D10: =IFERROR('Inputs'!$D$27/'Inputs'!$D$37,"") | E10: =IFERROR('Inputs'!$E$27/'Inputs'!$E$37,"") | F10: =IFERROR('Inputs'!$F$27/'Inputs'!$F$37,"") | G10: =IFERROR('Inputs'!$G$27/'Inputs'!$G$37,"") | H10: =IFERROR('Inputs'!$H$27/'Inputs'!$H$37,"") | I10: =IFERROR('Inputs'!$I$27/'Inputs'!$I$37,"") | J10: =IFERROR('Inputs'!$J$27/'Inputs'!$J$37,"") | K10: =IFERROR('Inputs'!$K$27/'Inputs'!$K$37,"") | L10: =IFERROR('Inputs'!$L$27/'Inputs'!$L$37,"") | M10: =IFERROR('Inputs'!$M$27/'Inputs'!$M$37,"") | N10: =IFERROR('Inputs'!$N$27/'Inputs'!$N$37,"") | O10: =IFERROR('Inputs'!$O$27/'Inputs'!$O$37,"") | P10: =IFERROR('Inputs'!$P$27/'Inputs'!$P$37,"") | Q10: =IF(AND(ISNUMBER($K$10),ISNUMBER($J$10)),CHOOSE(2+($K$10>$J$10)-($K$10<$J$10),"▼","►","▲"),"") | R10: =IF(ISNUMBER($K$10),CHOOSE(1+($K$10>=1.0)+($K$10>=2.0),"Weak","Adequate","Strong"),"")
A11: Quick ratio (ex-inventory) | B11: =IFERROR(('Inputs'!$B$27-'Inputs'!$B$25)/'Inputs'!$B$37,"") | C11: =IFERROR(('Inputs'!$C$27-'Inputs'!$C$25)/'Inputs'!$C$37,"") | D11: =IFERROR(('Inputs'!$D$27-'Inputs'!$D$25)/'Inputs'!$D$37,"") | E11: =IFERROR(('Inputs'!$E$27-'Inputs'!$E$25)/'Inputs'!$E$37,"") | F11: =IFERROR(('Inputs'!$F$27-'Inputs'!$F$25)/'Inputs'!$F$37,"") | G11: =IFERROR(('Inputs'!$G$27-'Inputs'!$G$25)/'Inputs'!$G$37,"") | H11: =IFERROR(('Inputs'!$H$27-'Inputs'!$H$25)/'Inputs'!$H$37,"") | I11: =IFERROR(('Inputs'!$I$27-'Inputs'!$I$25)/'Inputs'!$I$37,"") | J11: =IFERROR(('Inputs'!$J$27-'Inputs'!$J$25)/'Inputs'!$J$37,"") | K11: =IFERROR(('Inputs'!$K$27-'Inputs'!$K$25)/'Inputs'!$K$37,"") | L11: =IFERROR(('Inputs'!$L$27-'Inputs'!$L$25)/'Inputs'!$L$37,"") | M11: =IFERROR(('Inputs'!$M$27-'Inputs'!$M$25)/'Inputs'!$M$37,"") | N11: =IFERROR(('Inputs'!$N$27-'Inputs'!$N$25)/'Inputs'!$N$37,"") | O11: =IFERROR(('Inputs'!$O$27-'Inputs'!$O$25)/'Inputs'!$O$37,"") | P11: =IFERROR(('Inputs'!$P$27-'Inputs'!$P$25)/'Inputs'!$P$37,"") | Q11: =IF(AND(ISNUMBER($K$11),ISNUMBER($J$11)),CHOOSE(2+($K$11>$J$11)-($K$11<$J$11),"▼","►","▲"),"") | R11: =IF(ISNUMBER($K$11),CHOOSE(1+($K$11>=0.8)+($K$11>=1.2),"Weak","Adequate","Strong"),"")
A12: Cash ratio | B12: =IFERROR('Inputs'!$B$23/'Inputs'!$B$37,"") | C12: =IFERROR('Inputs'!$C$23/'Inputs'!$C$37,"") | D12: =IFERROR('Inputs'!$D$23/'Inputs'!$D$37,"") | E12: =IFERROR('Inputs'!$E$23/'Inputs'!$E$37,"") | F12: =IFERROR('Inputs'!$F$23/'Inputs'!$F$37,"") | G12: =IFERROR('Inputs'!$G$23/'Inputs'!$G$37,"") | H12: =IFERROR('Inputs'!$H$23/'Inputs'!$H$37,"") | I12: =IFERROR('Inputs'!$I$23/'Inputs'!$I$37,"") | J12: =IFERROR('Inputs'!$J$23/'Inputs'!$J$37,"") | K12: =IFERROR('Inputs'!$K$23/'Inputs'!$K$37,"") | L12: =IFERROR('Inputs'!$L$23/'Inputs'!$L$37,"") | M12: =IFERROR('Inputs'!$M$23/'Inputs'!$M$37,"") | N12: =IFERROR('Inputs'!$N$23/'Inputs'!$N$37,"") | O12: =IFERROR('Inputs'!$O$23/'Inputs'!$O$37,"") | P12: =IFERROR('Inputs'!$P$23/'Inputs'!$P$37,"") | Q12: =IF(AND(ISNUMBER($K$12),ISNUMBER($J$12)),CHOOSE(2+($K$12>$J$12)-($K$12<$J$12),"▼","►","▲"),"") | R12: =IF(ISNUMBER($K$12),CHOOSE(1+($K$12>=0.2)+($K$12>=0.5),"Weak","Adequate","Strong"),"")
A14: Working Capital
A15: Working capital | B15: ='Inputs'!$B$68 | C15: ='Inputs'!$C$68 | D15: ='Inputs'!$D$68 | E15: ='Inputs'!$E$68 | F15: ='Inputs'!$F$68 | G15: ='Inputs'!$G$68 | H15: ='Inputs'!$H$68 | I15: ='Inputs'!$I$68 | J15: ='Inputs'!$J$68 | K15: ='Inputs'!$K$68 | L15: ='Inputs'!$L$68 | M15: ='Inputs'!$M$68 | N15: ='Inputs'!$N$68 | O15: ='Inputs'!$O$68 | P15: ='Inputs'!$P$68 | Q15: =IF(AND(ISNUMBER($K$15),ISNUMBER($J$15)),CHOOSE(2+($K$15>$J$15)-($K$15<$J$15),"▼","►","▲"),"") | R15: =IF(AND(ISNUMBER($K$15),ISNUMBER(AVERAGE($B$15:$K$15))),CHOOSE(2+($K$15>AVERAGE($B$15:$K$15)*(1+0.05))-($K$15<AVERAGE($B$15:$K$15)*(1-0.05)),"Falling","Stable","Rising"),"")
